# StairwayToHeck
# Created for 1.7.10 -- 15 Oct 2014
# Updated for MC 1.8: 22 Jul 2015
# Created by Ruins mod version 13.8 Ingame Parser
# authoring Player: Jordan_Greywolf
# Last Updated: 27 Apr 2015

biomesToSpawnIn=badlands,boneyard,corrupted sands,deadlands,eerie,hell,phantasmagoric inferno,spectral garden,tainted land,undergarden,visceral heap

weight=1
embed_into_distance=0
# Note: Top level sometimes spawns at "Limbo" bedrock layer.

acceptable_target_blocks=

unacceptable_target_blocks=flowing_water,water,cloud,Natura:Cloud

dimensions=64,7,7
allowable_overhang=500
max_leveling=12
leveling_buffer=-1
preserve_water=0
preserve_lava=0

rule1=0,100,minecraft:nether_brick_fence-0
rule2=0,100,minecraft:nether_brick_stairs-0
rule3=0,100,minecraft:nether_brick_stairs-2
rule4=0,100,minecraft:nether_brick-0
rule5=0,100,minecraft:nether_brick_stairs-3
rule6=0,100,minecraft:stone_slab-6
rule7=0,100,minecraft:double_stone_slab-6
rule8=0,100,minecraft:stone_slab-14
rule9=0,100,minecraft:nether_brick_stairs-1
rule10=0,100,minecraft:nether_brick_stairs-4
rule11=0,100,minecraft:nether_brick_stairs-6
rule12=0,100,minecraft:netherrack-0
rule13=0,100,minecraft:nether_brick_stairs-7
rule14=0,100,minecraft:nether_brick_stairs-5
rule15=0,100,minecraft:fire-15
rule16=0,100,preserveBlock

# A
layer
1,2,16,16,16,2,1
5,4,1,1,1,4,3
16,1,6,0,0,1,16
16,1,7,4,0,1,16
16,1,8,0,0,1,16
5,4,1,1,1,4,3
1,9,16,16,16,9,1
endlayer

# B
layer
16,16,16,16,16,16,16
16,4,1,1,1,4,16
16,1,0,0,0,1,16
16,1,0,4,0,1,16
16,1,6,7,8,1,16
16,4,1,1,1,4,16
16,16,16,16,16,16,16
endlayer

# C
layer
1,10,16,16,16,10,1
13,12,11,1,13,12,11
16,14,0,0,8,14,16
16,1,0,4,7,1,16
16,10,0,0,6,10,16
13,12,11,1,13,12,11
1,14,16,16,16,14,1
endlayer

# D
layer
1,1,1,16,1,1,1
1,15,4,4,4,15,1
1,4,0,7,6,4,1
16,4,0,4,0,4,16
1,4,0,0,0,4,1
1,15,4,4,4,15,1
1,1,1,16,1,1,1
endlayer


# A
layer
1,2,16,16,16,2,1
5,4,1,1,1,4,3
16,1,6,0,0,1,16
16,1,7,4,0,1,16
16,1,8,0,0,1,16
5,4,1,1,1,4,3
1,9,16,16,16,9,1
endlayer

# B
layer
16,16,16,16,16,16,16
16,4,1,1,1,4,16
16,1,0,0,0,1,16
16,1,0,4,0,1,16
16,1,6,7,8,1,16
16,4,1,1,1,4,16
16,16,16,16,16,16,16
endlayer

# C
layer
1,10,16,16,16,10,1
13,12,11,1,13,12,11
16,14,0,0,8,14,16
16,1,0,4,7,1,16
16,10,0,0,6,10,16
13,12,11,1,13,12,11
1,14,16,16,16,14,1
endlayer

# D
layer
1,1,1,16,1,1,1
1,15,4,4,4,15,1
1,4,0,7,6,4,1
16,4,0,4,0,4,16
1,4,0,0,0,4,1
1,15,4,4,4,15,1
1,1,1,16,1,1,1
endlayer



# A
layer
1,2,16,16,16,2,1
5,4,1,1,1,4,3
16,1,6,0,0,1,16
16,1,7,4,0,1,16
16,1,8,0,0,1,16
5,4,1,1,1,4,3
1,9,16,16,16,9,1
endlayer

# B
layer
16,16,16,16,16,16,16
16,4,1,1,1,4,16
16,1,0,0,0,1,16
16,1,0,4,0,1,16
16,1,6,7,8,1,16
16,4,1,1,1,4,16
16,16,16,16,16,16,16
endlayer

# C
layer
1,10,16,16,16,10,1
13,12,11,1,13,12,11
16,14,0,0,8,14,16
16,1,0,4,7,1,16
16,10,0,0,6,10,16
13,12,11,1,13,12,11
1,14,16,16,16,14,1
endlayer

# D
layer
1,1,1,16,1,1,1
1,15,4,4,4,15,1
1,4,0,7,6,4,1
16,4,0,4,0,4,16
1,4,0,0,0,4,1
1,15,4,4,4,15,1
1,1,1,16,1,1,1
endlayer



# A
layer
1,2,16,16,16,2,1
5,4,1,1,1,4,3
16,1,6,0,0,1,16
16,1,7,4,0,1,16
16,1,8,0,0,1,16
5,4,1,1,1,4,3
1,9,16,16,16,9,1
endlayer

# B
layer
16,16,16,16,16,16,16
16,4,1,1,1,4,16
16,1,0,0,0,1,16
16,1,0,4,0,1,16
16,1,6,7,8,1,16
16,4,1,1,1,4,16
16,16,16,16,16,16,16
endlayer

# C
layer
1,10,16,16,16,10,1
13,12,11,1,13,12,11
16,14,0,0,8,14,16
16,1,0,4,7,1,16
16,10,0,0,6,10,16
13,12,11,1,13,12,11
1,14,16,16,16,14,1
endlayer

# D
layer
1,1,1,16,1,1,1
1,15,4,4,4,15,1
1,4,0,7,6,4,1
16,4,0,4,0,4,16
1,4,0,0,0,4,1
1,15,4,4,4,15,1
1,1,1,16,1,1,1
endlayer



# A
layer
1,2,16,16,16,2,1
5,4,1,1,1,4,3
16,1,6,0,0,1,16
16,1,7,4,0,1,16
16,1,8,0,0,1,16
5,4,1,1,1,4,3
1,9,16,16,16,9,1
endlayer

# B
layer
16,16,16,16,16,16,16
16,4,1,1,1,4,16
16,1,0,0,0,1,16
16,1,0,4,0,1,16
16,1,6,7,8,1,16
16,4,1,1,1,4,16
16,16,16,16,16,16,16
endlayer

# C
layer
1,10,16,16,16,10,1
13,12,11,1,13,12,11
16,14,0,0,8,14,16
16,1,0,4,7,1,16
16,10,0,0,6,10,16
13,12,11,1,13,12,11
1,14,16,16,16,14,1
endlayer

# D
layer
1,1,1,16,1,1,1
1,15,4,4,4,15,1
1,4,0,7,6,4,1
16,4,0,4,0,4,16
1,4,0,0,0,4,1
1,15,4,4,4,15,1
1,1,1,16,1,1,1
endlayer



# A
layer
1,2,16,16,16,2,1
5,4,1,1,1,4,3
16,1,6,0,0,1,16
16,1,7,4,0,1,16
16,1,8,0,0,1,16
5,4,1,1,1,4,3
1,9,16,16,16,9,1
endlayer

# B
layer
16,16,16,16,16,16,16
16,4,1,1,1,4,16
16,1,0,0,0,1,16
16,1,0,4,0,1,16
16,1,6,7,8,1,16
16,4,1,1,1,4,16
16,16,16,16,16,16,16
endlayer

# C
layer
1,10,16,16,16,10,1
13,12,11,1,13,12,11
16,14,0,0,8,14,16
16,1,0,4,7,1,16
16,10,0,0,6,10,16
13,12,11,1,13,12,11
1,14,16,16,16,14,1
endlayer

# D
layer
1,1,1,16,1,1,1
1,15,4,4,4,15,1
1,4,0,7,6,4,1
16,4,0,4,0,4,16
1,4,0,0,0,4,1
1,15,4,4,4,15,1
1,1,1,16,1,1,1
endlayer



# A
layer
1,2,16,16,16,2,1
5,4,1,1,1,4,3
16,1,6,0,0,1,16
16,1,7,4,0,1,16
16,1,8,0,0,1,16
5,4,1,1,1,4,3
1,9,16,16,16,9,1
endlayer

# B
layer
16,16,16,16,16,16,16
16,4,1,1,1,4,16
16,1,0,0,0,1,16
16,1,0,4,0,1,16
16,1,6,7,8,1,16
16,4,1,1,1,4,16
16,16,16,16,16,16,16
endlayer

# C
layer
1,10,16,16,16,10,1
13,12,11,1,13,12,11
16,14,0,0,8,14,16
16,1,0,4,7,1,16
16,10,0,0,6,10,16
13,12,11,1,13,12,11
1,14,16,16,16,14,1
endlayer

# D
layer
1,1,1,16,1,1,1
1,15,4,4,4,15,1
1,4,0,7,6,4,1
16,4,0,4,0,4,16
1,4,0,0,0,4,1
1,15,4,4,4,15,1
1,1,1,16,1,1,1
endlayer



# A
layer
1,2,16,16,16,2,1
5,4,1,1,1,4,3
16,1,6,0,0,1,16
16,1,7,4,0,1,16
16,1,8,0,0,1,16
5,4,1,1,1,4,3
1,9,16,16,16,9,1
endlayer

# B
layer
16,16,16,16,16,16,16
16,4,1,1,1,4,16
16,1,0,0,0,1,16
16,1,0,4,0,1,16
16,1,6,7,8,1,16
16,4,1,1,1,4,16
16,16,16,16,16,16,16
endlayer

# C
layer
1,10,16,16,16,10,1
13,12,11,1,13,12,11
16,14,0,0,8,14,16
16,1,0,4,7,1,16
16,10,0,0,6,10,16
13,12,11,1,13,12,11
1,14,16,16,16,14,1
endlayer

# D
layer
1,1,1,16,1,1,1
1,15,4,4,4,15,1
1,4,0,7,6,4,1
16,4,0,4,0,4,16
1,4,0,0,0,4,1
1,15,4,4,4,15,1
1,1,1,16,1,1,1
endlayer



# A
layer
1,2,16,16,16,2,1
5,4,1,1,1,4,3
16,1,6,0,0,1,16
16,1,7,4,0,1,16
16,1,8,0,0,1,16
5,4,1,1,1,4,3
1,9,16,16,16,9,1
endlayer

# B
layer
16,16,16,16,16,16,16
16,4,1,1,1,4,16
16,1,0,0,0,1,16
16,1,0,4,0,1,16
16,1,6,7,8,1,16
16,4,1,1,1,4,16
16,16,16,16,16,16,16
endlayer

# C
layer
1,10,16,16,16,10,1
13,12,11,1,13,12,11
16,14,0,0,8,14,16
16,1,0,4,7,1,16
16,10,0,0,6,10,16
13,12,11,1,13,12,11
1,14,16,16,16,14,1
endlayer

# D
layer
1,1,1,16,1,1,1
1,15,4,4,4,15,1
1,4,0,7,6,4,1
16,4,0,4,0,4,16
1,4,0,0,0,4,1
1,15,4,4,4,15,1
1,1,1,16,1,1,1
endlayer



# A
layer
1,2,16,16,16,2,1
5,4,1,1,1,4,3
16,1,6,0,0,1,16
16,1,7,4,0,1,16
16,1,8,0,0,1,16
5,4,1,1,1,4,3
1,9,16,16,16,9,1
endlayer

# B
layer
16,16,16,16,16,16,16
16,4,1,1,1,4,16
16,1,0,0,0,1,16
16,1,0,4,0,1,16
16,1,6,7,8,1,16
16,4,1,1,1,4,16
16,16,16,16,16,16,16
endlayer

# C
layer
1,10,16,16,16,10,1
13,12,11,1,13,12,11
16,14,0,0,8,14,16
16,1,0,4,7,1,16
16,10,0,0,6,10,16
13,12,11,1,13,12,11
1,14,16,16,16,14,1
endlayer

# D
layer
1,1,1,16,1,1,1
1,15,4,4,4,15,1
1,4,0,7,6,4,1
16,4,0,4,0,4,16
1,4,0,0,0,4,1
1,15,4,4,4,15,1
1,1,1,16,1,1,1
endlayer



# A
layer
1,2,16,16,16,2,1
5,4,1,1,1,4,3
16,1,6,0,0,1,16
16,1,7,4,0,1,16
16,1,8,0,0,1,16
5,4,1,1,1,4,3
1,9,16,16,16,9,1
endlayer

# B
layer
16,16,16,16,16,16,16
16,4,1,1,1,4,16
16,1,0,0,0,1,16
16,1,0,4,0,1,16
16,1,6,7,8,1,16
16,4,1,1,1,4,16
16,16,16,16,16,16,16
endlayer

# C
layer
1,10,16,16,16,10,1
13,12,11,1,13,12,11
16,14,0,0,8,14,16
16,1,0,4,7,1,16
16,10,0,0,6,10,16
13,12,11,1,13,12,11
1,14,16,16,16,14,1
endlayer

# D
layer
1,1,1,16,1,1,1
1,15,4,4,4,15,1
1,4,0,7,6,4,1
16,4,0,4,0,4,16
1,4,0,0,0,4,1
1,15,4,4,4,15,1
1,1,1,16,1,1,1
endlayer



# A
layer
1,2,16,16,16,2,1
5,4,1,1,1,4,3
16,1,6,0,0,1,16
16,1,7,4,0,1,16
16,1,8,0,0,1,16
5,4,1,1,1,4,3
1,9,16,16,16,9,1
endlayer

# B
layer
16,16,16,16,16,16,16
16,4,1,1,1,4,16
16,1,0,0,0,1,16
16,1,0,4,0,1,16
16,1,6,7,8,1,16
16,4,1,1,1,4,16
16,16,16,16,16,16,16
endlayer

# C
layer
1,10,16,16,16,10,1
13,12,11,1,13,12,11
16,14,0,0,8,14,16
16,1,0,4,7,1,16
16,10,0,0,6,10,16
13,12,11,1,13,12,11
1,14,16,16,16,14,1
endlayer

# D
layer
1,1,1,16,1,1,1
1,15,4,4,4,15,1
1,4,0,7,6,4,1
16,4,0,4,0,4,16
1,4,0,0,0,4,1
1,15,4,4,4,15,1
1,1,1,16,1,1,1
endlayer



# A
layer
1,2,16,16,16,2,1
5,4,1,1,1,4,3
16,1,6,0,0,1,16
16,1,7,4,0,1,16
16,1,8,0,0,1,16
5,4,1,1,1,4,3
1,9,16,16,16,9,1
endlayer

# B
layer
16,16,16,16,16,16,16
16,4,1,1,1,4,16
16,1,0,0,0,1,16
16,1,0,4,0,1,16
16,1,6,7,8,1,16
16,4,1,1,1,4,16
16,16,16,16,16,16,16
endlayer

# C
layer
1,10,16,16,16,10,1
13,12,11,1,13,12,11
16,14,0,0,8,14,16
16,1,0,4,7,1,16
16,10,0,0,6,10,16
13,12,11,1,13,12,11
1,14,16,16,16,14,1
endlayer

# D
layer
1,1,1,16,1,1,1
1,15,4,4,4,15,1
1,4,0,7,6,4,1
16,4,0,4,0,4,16
1,4,0,0,0,4,1
1,15,4,4,4,15,1
1,1,1,16,1,1,1
endlayer



# A
layer
1,2,16,16,16,2,1
5,4,1,1,1,4,3
16,1,6,0,0,1,16
16,1,7,4,0,1,16
16,1,8,0,0,1,16
5,4,1,1,1,4,3
1,9,16,16,16,9,1
endlayer

# B
layer
16,16,16,16,16,16,16
16,4,1,1,1,4,16
16,1,0,0,0,1,16
16,1,0,4,0,1,16
16,1,6,7,8,1,16
16,4,1,1,1,4,16
16,16,16,16,16,16,16
endlayer

# C
layer
1,10,16,16,16,10,1
13,12,11,1,13,12,11
16,14,0,0,8,14,16
16,1,0,4,7,1,16
16,10,0,0,6,10,16
13,12,11,1,13,12,11
1,14,16,16,16,14,1
endlayer

# D
layer
1,1,1,16,1,1,1
1,15,4,4,4,15,1
1,4,0,7,6,4,1
16,4,0,4,0,4,16
1,4,0,0,0,4,1
1,15,4,4,4,15,1
1,1,1,16,1,1,1
endlayer



# A
layer
1,2,16,16,16,2,1
5,4,1,1,1,4,3
16,1,6,0,0,1,16
16,1,7,4,0,1,16
16,1,8,0,0,1,16
5,4,1,1,1,4,3
1,9,16,16,16,9,1
endlayer

# B
layer
16,16,16,16,16,16,16
16,4,1,1,1,4,16
16,1,0,0,0,1,16
16,1,0,4,0,1,16
16,1,6,7,8,1,16
16,4,1,1,1,4,16
16,16,16,16,16,16,16
endlayer

# C
layer
1,10,16,16,16,10,1
13,12,11,1,13,12,11
16,14,0,0,8,14,16
16,1,0,4,7,1,16
16,10,0,0,6,10,16
13,12,11,1,13,12,11
1,14,16,16,16,14,1
endlayer

# D
layer
1,1,1,16,1,1,1
1,15,4,4,4,15,1
1,4,0,7,6,4,1
16,4,0,4,0,4,16
1,4,0,0,0,4,1
1,15,4,4,4,15,1
1,1,1,16,1,1,1
endlayer



# A
layer
1,2,16,16,16,2,1
5,4,1,1,1,4,3
16,1,6,0,0,1,16
16,1,7,4,0,1,16
16,1,8,0,0,1,16
5,4,1,1,1,4,3
1,9,16,16,16,9,1
endlayer

# B
layer
16,16,16,16,16,16,16
16,4,1,1,1,4,16
16,1,0,0,0,1,16
16,1,0,4,0,1,16
16,1,6,7,8,1,16
16,4,1,1,1,4,16
16,16,16,16,16,16,16
endlayer

# C
layer
1,10,16,16,16,10,1
13,12,11,1,13,12,11
16,14,0,0,8,14,16
16,1,0,4,7,1,16
16,10,0,0,6,10,16
13,12,11,1,13,12,11
1,14,16,16,16,14,1
endlayer

# D
layer
1,1,1,16,1,1,1
1,15,4,4,4,15,1
1,4,0,7,6,4,1
16,4,0,4,0,4,16
1,4,0,0,0,4,1
1,15,4,4,4,15,1
1,1,1,16,1,1,1
endlayer



# A
layer
1,2,16,16,16,2,1
5,4,1,1,1,4,3
16,1,6,0,0,1,16
16,1,7,4,0,1,16
16,1,8,0,0,1,16
5,4,1,1,1,4,3
1,9,16,16,16,9,1
endlayer

# B
layer
16,16,16,16,16,16,16
16,4,1,1,1,4,16
16,1,0,0,0,1,16
16,1,0,4,0,1,16
16,1,6,7,8,1,16
16,4,1,1,1,4,16
16,16,16,16,16,16,16
endlayer

# C
layer
1,10,16,16,16,10,1
13,12,11,1,13,12,11
16,14,0,0,8,14,16
16,1,0,4,7,1,16
16,10,0,0,6,10,16
13,12,11,1,13,12,11
1,14,16,16,16,14,1
endlayer

# D
layer
1,1,1,16,1,1,1
1,15,4,4,4,15,1
1,4,0,7,6,4,1
16,4,0,4,0,4,16
1,4,0,0,0,4,1
1,15,4,4,4,15,1
1,1,1,16,1,1,1
endlayer


