# Kujaku's Lighthouse
# Created by Ruins mod version 14.3 Ingame Parser
# authoring Player: Kujaku10
# Last Updated 13 Jul 2017

biomesToSpawnIn=beach,forested island,mushroomislandshore,stone beach

weight=1
embed_into_distance=8

uniqueMinDistance=2000

acceptable_target_blocks=

unacceptable_target_blocks=flowing_lava,lava,cloud,Natura:Cloud,slime_congealed,slime_dirt,slime_grass,red_mushroom_block,brown_mushroom_block

dimensions=28,15,13
allowable_overhang=0
max_leveling=4
leveling_buffer=-1
preserve_water=0
preserve_lava=0
preserve_plants=1

rule1=0,100,preserveBlock
rule2=0,100,minecraft:grass-0
rule3=0,100,minecraft:red_flower-7
rule4=0,100,minecraft:leaves-6
rule5=0,100,minecraft:red_flower-0
rule6=0,100,minecraft:stonebrick-0
rule7=0,100,minecraft:planks-3
rule8=0,100,minecraft:planks-4
rule9=0,100,minecraft:leaves-14
rule10=0,100,minecraft:stone_slab-4
rule11=0,100,minecraft:quartz_block-0
rule12=0,100,minecraft:ladder-3
rule13=0,100,minecraft:acacia_stairs-7
rule14=0,100,minecraft:wooden_slab-12
rule15=0,100,minecraft:acacia_stairs-6
rule16=0,100,minecraft:jungle_stairs-6
rule17=0,100,minecraft:acacia_stairs-3
rule18=0,100,minecraft:acacia_stairs-1
rule19=0,100,minecraft:bed-10
rule20=0,100,minecraft:bed-2
rule21=0,100,minecraft:wooden_slab-4
rule22=0,100,minecraft:acacia_stairs-0
rule23=0,100,minecraft:lit_furnace-2
rule24=0,100,IInventory;minecraft:chest;minecraft:compass#1#0#0-3
rule25=0,100,minecraft:crafting_table-0
rule26=0,100,ChestGenHook:dungeonChest:5-3
rule27=0,100,minecraft:wooden_door-2
rule28=0,100,minecraft:glass_pane-0
rule29=0,100,minecraft:flower_pot-1,minecraft:flower_pot-2,minecraft:flower_pot-11,minecraft:flower_pot-12,minecraft:flower_pot-13,minecraft:flower_pot-6,minecraft:flower_pot-7,minecraft:flower_pot-4,minecraft:flower_pot-5
rule30=0,100,minecraft:fence-0
rule31=0,100,minecraft:wooden_door-8
rule32=0,100,minecraft:stone_stairs-0
rule33=0,100,minecraft:stone_stairs-1
rule34=1,100,minecraft:torch-5
rule35=0,100,minecraft:jungle_stairs-2
rule36=0,100,minecraft:jungle_stairs-3
rule37=0,100,minecraft:stone_stairs-2
rule38=0,100,minecraft:jungle_stairs-7
rule39=0,100,minecraft:wooden_slab-3
rule40=0,100,minecraft:wooden_slab-11
rule41=0,100,minecraft:acacia_stairs-5
rule42=0,100,minecraft:acacia_stairs-4
rule43=0,100,minecraft:jungle_stairs-1
rule44=0,100,minecraft:jungle_stairs-0
rule45=0,100,minecraft:stone_brick_stairs-0
rule46=0,100,minecraft:stone_brick_stairs-2
rule47=0,100,minecraft:stone_brick_stairs-3
rule48=0,100,minecraft:stone_brick_stairs-1
rule49=0,100,minecraft:glowstone
rule50=0,100,minecraft:stone_brick_stairs-7
rule51=0,100,minecraft:stone_brick_stairs-6
rule52=0,100,minecraft:stone_slab-5

rule53=0,100,CommandBlock:RUINSTRIGGER /summon Skeleton ~0 ~1 ~0 {CustomName:Pirate,Equipment:[{Count:1,id:268,tag:{display:{Name:Pirate Bludgeon},ench:[{id:21,lvl:5},{id:16,lvl:3},{id:19,lvl:3}]}},{Count:1,id:301},{Count:1,id:300},{Count:1,id:299},{Count:1,id:397,Damage:3}],Attributes:[{Name:generic.maxHealth,Base:15}],DropChances:[0.5F,0.5F,0.5F,0.5F,0.5F],PersistenceRequired:1}:@

layer
1,1,2,2,2,2,2,2,2,2,2,1,1
1,2,2,2,2,2,2,2,2,2,2,2,1
2,2,2,2,2,2,2,2,2,2,2,2,2
2,2,2,2,2,2,2,2,2,2,2,2,2
2,2,2,2,2,2,2,2,2,2,2,2,2
2,2,2,2,2,2,2,2,2,2,2,2,2
2,2,2,2,2,2,2,2,2,2,2,2,2
2,2,2,2,2,2,2,2,2,2,2,2,2
2,2,2,2,2,2,2,2,2,2,2,2,2
1,2,2,2,2,2,2,2,2,2,2,2,2
1,1,2,2,2,2,2,2,2,2,2,2,2
1,1,2,2,2,2,2,2,2,2,2,2,2
1,1,1,2,2,2,2,2,2,2,2,2,1
1,1,1,1,2,2,2,2,2,2,2,1,1
1,1,1,1,1,1,2,2,2,1,1,1,1
endlayer

layer
1,1,2,2,2,2,2,2,2,2,2,1,1
1,2,2,2,2,2,2,2,2,2,2,2,1
2,2,2,2,2,2,2,2,2,2,2,2,2
2,2,2,2,2,2,2,2,2,2,2,2,2
2,2,2,2,2,2,2,2,2,2,2,2,2
2,2,2,2,2,2,2,2,2,2,2,2,2
2,2,2,2,2,2,2,2,2,2,2,2,2
2,2,2,2,2,2,2,2,2,2,2,2,2
2,2,2,2,2,2,2,2,2,2,2,2,2
1,2,2,2,2,2,2,2,2,2,2,2,2
1,1,2,2,2,2,2,2,2,2,2,2,2
1,1,2,2,2,2,2,2,2,2,2,2,2
1,1,1,2,2,2,2,2,2,2,2,2,1
1,1,1,1,2,2,2,2,2,2,2,1,1
1,1,1,1,1,1,2,2,2,1,1,1,1
endlayer

layer
1,1,2,2,2,2,2,2,2,2,2,1,1
1,2,2,2,2,2,2,2,2,2,2,2,1
2,2,2,2,2,2,2,2,2,2,2,2,2
2,2,2,2,2,2,2,2,2,2,2,2,2
2,2,2,2,2,2,2,2,2,2,2,2,2
2,2,2,2,2,2,2,2,2,2,2,2,2
2,2,2,2,2,2,2,2,2,2,2,2,2
2,2,2,2,2,2,2,2,2,2,2,2,2
2,2,2,2,2,2,2,2,2,2,2,2,2
1,2,2,2,2,2,2,2,2,2,2,2,2
1,1,2,2,2,2,2,2,2,2,2,2,2
1,1,2,2,2,2,2,2,2,2,2,2,2
1,1,1,2,2,2,2,2,2,2,2,2,1
1,1,1,1,2,2,2,2,2,2,2,1,1
1,1,1,1,1,1,2,2,2,1,1,1,1
endlayer

layer
1,1,2,2,2,2,2,2,2,2,2,1,1
1,2,2,2,2,2,2,2,2,2,2,2,1
2,2,2,2,2,2,2,2,2,2,2,2,2
2,2,2,2,2,2,2,2,2,2,2,2,2
2,2,2,2,2,2,2,2,2,2,2,2,2
2,2,2,2,2,2,2,2,2,2,2,2,2
2,2,2,2,2,2,2,2,2,2,2,2,2
2,2,2,2,2,2,2,2,2,2,2,2,2
2,2,2,2,2,2,2,2,2,2,2,2,2
1,2,2,2,2,2,2,2,2,2,2,2,2
1,1,2,2,2,2,2,2,2,2,2,2,2
1,1,2,2,2,2,2,2,2,2,2,2,2
1,1,1,2,2,2,2,2,2,2,2,2,1
1,1,1,1,2,2,2,2,2,2,2,1,1
1,1,1,1,1,1,2,2,2,1,1,1,1
endlayer

layer
1,1,2,2,2,2,2,2,2,2,2,1,1
1,2,2,2,2,2,2,2,2,2,2,2,1
2,2,2,2,2,2,2,2,2,2,2,2,2
2,2,2,2,2,2,2,2,2,2,2,2,2
2,2,2,2,2,2,2,2,2,2,2,2,2
2,2,2,2,2,2,2,2,2,2,2,2,2
2,2,2,2,2,2,2,2,2,2,2,2,2
2,2,2,2,2,2,2,2,2,2,2,2,2
2,2,2,2,2,2,2,2,2,2,2,2,2
1,2,2,2,2,2,2,2,2,2,2,2,2
1,1,2,2,2,2,2,2,2,2,2,2,2
1,1,2,2,2,2,2,2,2,2,2,2,2
1,1,1,2,2,2,2,2,2,2,2,2,1
1,1,1,1,2,2,2,2,2,2,2,1,1
1,1,1,1,1,1,2,2,2,1,1,1,1
endlayer


layer
1,1,2,2,2,2,2,2,2,2,2,1,1
1,2,2,2,2,2,2,2,2,2,2,2,1
2,2,2,2,2,2,2,2,2,2,2,2,2
2,2,2,2,2,2,2,2,2,2,2,2,2
2,2,2,2,2,2,2,2,2,2,2,2,2
2,2,2,2,2,2,2,2,2,2,2,2,2
2,2,2,2,2,2,2,2,2,2,2,2,2
2,2,2,2,2,2,2,2,2,2,2,2,2
2,2,2,2,2,2,2,2,2,2,2,2,2
1,2,2,2,2,2,2,2,2,2,2,2,2
1,1,2,2,2,2,2,2,2,2,2,2,2
1,1,2,2,2,2,2,2,2,2,2,2,2
1,1,1,2,2,2,2,2,2,2,2,2,1
1,1,1,1,2,2,2,2,2,2,2,1,1
1,1,1,1,1,1,2,2,2,1,1,1,1
endlayer

layer
1,1,2,2,2,2,2,2,2,2,2,1,1
1,2,2,2,2,2,2,2,2,2,2,2,1
2,2,2,2,2,2,2,2,2,2,2,2,2
2,2,2,2,2,2,2,2,2,2,2,2,2
2,2,2,2,2,2,2,2,2,2,2,2,2
2,2,2,2,2,2,2,2,2,2,2,2,2
2,2,2,2,2,2,2,2,2,2,2,2,2
2,2,2,2,2,2,2,2,2,2,2,2,2
2,2,2,2,2,2,2,2,2,2,2,2,2
1,2,2,2,2,2,2,2,2,2,2,2,2
1,1,2,2,2,2,2,2,2,2,2,2,2
1,1,2,2,2,2,2,2,2,2,2,2,2
1,1,1,2,2,2,2,2,2,2,2,2,1
1,1,1,1,2,2,2,2,2,2,2,1,1
1,1,1,1,1,1,2,2,2,1,1,1,1
endlayer

layer
1,1,2,2,2,2,2,2,2,2,2,1,1
1,2,2,2,2,2,2,2,2,2,2,2,1
2,2,2,2,2,2,2,2,2,2,2,2,2
2,2,2,2,2,2,2,2,2,2,2,2,2
2,2,2,2,2,2,2,2,2,2,2,2,2
2,2,2,2,2,2,2,2,2,2,2,2,2
2,2,2,2,2,2,2,2,2,2,2,2,2
2,2,2,2,2,2,2,2,2,2,2,2,2
2,2,2,2,2,2,2,2,2,2,2,2,2
1,2,2,2,2,2,2,2,2,2,2,2,2
1,1,2,2,2,2,2,2,2,2,2,2,2
1,1,2,2,2,2,2,2,2,2,2,2,2
1,1,1,2,2,2,2,2,2,2,2,2,1
1,1,1,1,2,2,2,2,2,2,2,1,1
1,1,1,1,1,1,2,2,2,1,1,1,1
endlayer


layer
1,1,1,1,1,1,1,1,1,1,1,1,1
1,1,2,2,2,2,2,2,2,2,2,1,1
1,2,2,2,2,2,2,2,2,2,2,2,1
1,2,2,2,2,2,2,2,2,2,2,2,1
1,2,2,2,2,2,2,2,2,2,2,2,1
1,2,2,2,2,2,2,2,2,2,2,2,1
1,2,2,2,2,2,2,2,2,2,2,2,1
1,2,2,2,2,2,2,2,2,2,2,2,1
1,2,2,2,2,2,2,2,2,2,2,2,1
1,1,2,2,2,2,2,2,2,2,2,2,1
1,1,1,2,2,2,2,2,2,2,2,2,1
1,1,1,2,2,2,2,2,2,2,2,2,1
1,1,1,1,2,2,2,2,2,2,2,1,1
1,1,1,1,1,1,2,2,2,1,1,1,1
1,1,1,1,1,1,2,2,2,1,1,1,1
endlayer

layer
1,1,1,1,0,0,0,0,0,1,1,1,1
1,1,3,4,4,4,4,4,4,4,3,1,1
1,5,6,6,6,6,6,6,6,6,6,5,1
1,4,6,7,7,7,7,7,7,7,6,4,1
0,4,6,7,8,7,8,8,8,7,6,4,0
0,4,6,7,8,7,8,8,8,7,6,4,0
0,4,6,7,8,7,8,8,8,7,6,4,0
0,4,6,7,7,7,8,8,8,7,6,4,0
0,5,6,6,6,7,8,8,8,7,6,4,0
1,0,4,4,6,7,8,8,8,7,6,4,0
1,0,0,9,6,7,7,7,7,7,6,4,1
1,1,0,3,6,6,6,6,6,6,6,3,1
1,1,0,0,5,4,6,6,6,4,5,1,1
1,1,1,1,0,0,10,10,10,0,1,1,1
1,1,1,1,1,1,0,0,1,1,1,1,1
endlayer

layer
1,1,1,0,0,0,0,0,0,0,1,1,1
1,1,0,0,0,0,0,0,0,0,0,1,1
1,0,8,11,8,8,8,8,8,11,8,0,1
0,0,11,16,0,15,14,13,12,8,11,0,0
0,0,8,18,0,0,53,0,0,17,8,0,0
0,0,8,21,0,0,0,0,20,19,8,0,0
0,0,8,22,0,0,0,0,0,17,8,0,0
0,0,11,16,0,0,0,0,20,19,8,0,0
0,0,8,8,8,23,0,0,0,17,8,0,0
0,0,0,0,8,25,0,53,0,24,11,0,0
1,0,0,0,8,23,0,0,0,26,11,0,0
1,0,0,0,8,11,0,27,0,11,8,0,1
1,1,0,0,0,0,11,0,11,0,0,0,1
1,1,1,0,0,0,0,0,0,0,0,1,1
1,1,1,1,1,0,0,0,0,1,1,1,1
endlayer

layer
1,1,0,0,0,0,0,0,0,0,0,1,1
1,0,0,0,0,0,0,0,0,0,0,0,1
0,0,8,11,28,28,28,28,28,11,8,0,0
0,0,11,29,0,0,0,29,12,8,11,0,0
0,0,28,0,0,0,0,0,0,0,28,0,0
0,0,28,0,0,0,0,0,0,0,28,0,0
0,0,28,0,0,0,0,0,0,0,28,0,0
0,0,11,29,0,0,0,0,0,0,28,0,0
0,0,8,11,8,23,0,0,0,0,28,0,0
0,0,0,0,11,0,0,0,0,0,28,0,0
0,0,0,0,11,23,0,0,0,0,11,0,0
1,0,0,0,8,11,30,31,30,11,8,0,0
1,0,0,0,0,0,11,0,11,0,0,0,1
1,1,0,0,0,0,0,0,0,0,0,1,1
1,1,1,1,0,0,0,0,0,0,1,1,1
endlayer

layer
1,0,0,0,0,0,0,0,0,0,0,0,1
0,0,0,0,0,0,0,0,0,0,0,0,0
0,0,8,8,11,28,28,28,11,8,8,0,0
0,0,8,30,0,0,0,0,12,8,8,0,0
0,0,11,0,0,0,0,0,0,30,11,0,0
0,0,28,0,0,0,0,0,0,0,28,0,0
0,0,11,0,0,0,0,0,0,0,28,0,0
0,0,8,30,0,0,0,0,0,0,28,0,0
0,0,8,11,8,32,0,0,0,0,28,0,0
0,0,0,0,11,23,0,0,0,0,11,0,0
0,0,0,0,11,33,0,0,0,30,8,0,0
0,0,0,0,8,8,34,0,34,8,8,0,0
0,0,0,0,0,36,11,7,11,35,0,0,0
1,0,0,0,0,36,0,0,0,35,0,0,1
1,1,0,0,0,0,0,0,0,0,0,1,1
endlayer

layer
0,0,0,0,0,0,0,0,0,0,0,0,0
0,0,0,0,0,0,0,0,0,0,0,0,0
0,30,8,11,8,11,11,11,8,11,8,30,0
0,0,11,34,0,0,0,0,12,8,11,0,0
0,30,8,0,0,0,0,0,0,34,8,30,0
0,0,11,0,0,0,0,0,0,0,11,0,0
0,30,8,0,0,0,0,0,0,0,11,30,0
0,0,11,34,0,0,0,0,0,0,11,30,0
0,30,8,11,8,0,0,0,0,0,11,0,0
0,0,0,30,11,37,0,0,0,0,8,30,0
0,0,0,0,11,0,0,0,0,34,11,0,0
0,0,0,30,8,11,8,0,8,11,8,30,0
0,0,0,0,0,0,36,11,35,0,0,0,0
0,0,0,0,0,0,36,0,35,0,0,0,0
1,0,0,0,0,0,0,0,0,0,0,0,1
endlayer

layer
0,0,0,0,0,0,0,0,0,0,0,35,0
0,36,0,0,0,0,0,0,0,0,38,35,0
0,36,8,8,8,8,8,8,8,8,8,35,0
0,36,8,0,0,0,0,0,12,8,8,35,0
0,36,8,0,0,0,0,0,0,0,8,35,0
0,36,8,0,0,0,0,0,0,0,8,35,0
0,36,8,0,0,0,0,0,0,0,8,35,0
0,36,8,0,0,0,0,0,0,0,8,35,0
0,36,8,8,8,0,0,0,0,0,8,35,0
0,36,0,36,8,0,0,0,0,0,8,35,0
0,0,0,36,8,0,0,0,0,0,8,35,0
0,0,0,36,8,8,8,8,8,8,8,35,0
0,0,0,36,16,0,0,39,0,0,38,35,0
0,0,0,36,0,0,0,39,0,0,0,35,0
0,0,0,0,0,0,0,0,0,0,0,0,0
endlayer

layer
0,0,0,0,0,0,0,0,0,0,35,0,0
0,0,36,0,0,0,0,0,0,38,35,0,0
0,0,36,8,11,8,11,28,11,8,35,0,0
0,0,36,8,0,8,15,0,12,8,35,0,0
0,0,36,8,0,8,0,0,0,8,8,0,0
0,0,36,8,0,8,0,0,0,8,8,0,0
0,0,36,8,0,8,15,0,13,8,35,0,0
0,0,36,8,0,8,0,0,0,8,35,0,0
0,0,36,8,11,8,0,0,0,8,35,0,0
0,0,36,0,36,8,0,0,0,8,35,0,0
0,0,0,0,36,8,0,0,0,8,35,0,0
0,0,0,0,36,8,11,28,11,8,35,0,0
0,0,0,0,36,16,0,0,0,38,35,0,0
0,0,0,0,36,0,0,0,0,0,35,0,0
0,0,0,0,0,0,0,0,0,0,0,0,0
endlayer

layer
0,0,0,0,0,36,0,0,0,35,0,0,0
0,0,0,36,40,7,16,0,38,35,0,0,0
0,0,0,36,8,7,8,11,8,35,0,0,0
0,0,0,36,8,7,8,0,12,8,0,0,0
0,0,0,36,8,8,0,0,0,18,8,0,0
0,0,0,36,8,8,0,0,0,22,8,0,0
0,0,0,36,8,7,8,22,8,8,0,0,0
0,0,0,36,8,7,8,8,8,35,0,0,0
0,0,0,36,8,7,8,41,8,35,0,0,0
0,0,0,36,0,7,8,0,8,35,0,0,0
0,0,0,0,0,36,8,42,8,35,0,0,0
0,0,0,0,0,36,8,11,8,35,0,0,0
0,0,0,0,0,36,16,0,38,35,0,0,0
0,0,0,0,0,36,0,0,0,35,0,0,0
0,0,0,0,0,0,0,0,0,0,0,0,0
endlayer

layer
0,0,0,0,0,0,7,0,7,0,0,0,0
0,0,0,0,39,39,36,40,35,0,0,0,0
0,0,0,0,39,39,36,8,8,0,0,0,0
0,0,0,0,39,39,8,0,12,8,0,0,0
0,0,0,0,36,11,0,0,0,0,11,0,0
0,0,0,0,36,11,0,0,0,0,11,0,0
0,0,0,0,39,39,8,0,8,8,0,0,0
0,0,0,0,39,39,36,8,8,0,0,0,0
0,0,0,0,39,39,36,8,35,0,0,0,0
0,0,0,0,39,39,36,8,35,0,0,0,0
0,0,0,0,0,0,36,8,35,0,0,0,0
0,0,0,0,0,0,36,8,35,0,0,0,0
0,0,0,0,0,0,36,40,35,0,0,0,0
0,0,0,0,0,0,7,0,7,0,0,0,0
0,0,0,0,0,0,0,0,0,0,0,0,0
endlayer

layer
0,0,0,0,0,0,36,7,35,0,0,0,0
0,0,0,0,0,0,0,43,0,0,0,0,0
0,0,0,0,0,0,0,11,11,0,0,0,0
0,0,0,0,0,0,8,0,12,8,0,0,0
0,0,0,0,0,11,0,0,0,0,11,0,0
0,0,0,0,0,11,0,0,0,0,11,0,0
0,0,0,0,0,0,8,0,8,8,0,0,0
0,0,0,0,0,0,0,11,11,0,0,0,0
0,0,0,0,0,0,0,39,0,0,0,0,0
0,0,0,0,0,0,0,39,0,0,0,0,0
0,0,0,0,0,0,0,39,0,0,0,0,0
0,0,0,0,0,0,0,39,0,0,0,0,0
0,0,0,0,0,0,0,44,0,0,0,0,0
0,0,0,0,0,0,36,7,35,0,0,0,0
0,0,0,0,0,0,0,0,0,0,0,0,0
endlayer

layer
0,0,0,0,0,0,0,43,0,0,0,0,0
0,0,0,0,0,0,0,0,0,0,0,0,0
0,0,0,0,0,0,0,8,8,0,0,0,0
0,0,0,0,0,0,8,0,12,8,0,0,0
0,0,0,0,0,8,0,0,0,0,8,0,0
0,0,0,0,0,8,0,0,0,0,8,0,0
0,0,0,0,0,0,8,0,8,8,0,0,0
0,0,0,0,0,0,0,8,8,0,0,0,0
0,0,0,0,0,0,0,0,0,0,0,0,0
0,0,0,0,0,0,0,0,0,0,0,0,0
0,0,0,0,0,0,0,0,0,0,0,0,0
0,0,0,0,0,0,0,0,0,0,0,0,0
0,0,0,0,0,0,0,0,0,0,0,0,0
0,0,0,0,0,0,0,44,0,0,0,0,0
0,0,0,0,0,0,0,0,0,0,0,0,0
endlayer

layer
0,0,0,0,0,0,0,0,0,0,0,0,0
0,0,0,0,0,0,0,0,0,0,0,0,0
0,0,0,0,0,0,0,11,11,0,0,0,0
0,0,0,0,0,0,8,0,12,8,0,0,0
0,0,0,0,0,11,0,0,0,0,11,0,0
0,0,0,0,0,11,0,0,0,0,11,0,0
0,0,0,0,0,0,8,0,8,8,0,0,0
0,0,0,0,0,0,0,11,11,0,0,0,0
0,0,0,0,0,0,0,0,0,0,0,0,0
0,0,0,0,0,0,0,0,0,0,0,0,0
0,0,0,0,0,0,0,0,0,0,0,0,0
0,0,0,0,0,0,0,0,0,0,0,0,0
0,0,0,0,0,0,0,0,0,0,0,0,0
0,0,0,0,0,0,0,0,0,0,0,0,0
0,0,0,0,0,0,0,0,0,0,0,0,0
endlayer

layer
0,0,0,0,0,0,0,0,0,0,0,0,0
0,0,0,0,0,0,0,0,0,0,0,0,0
0,0,0,0,0,0,0,8,8,30,0,0,0
0,0,0,0,0,0,8,41,12,8,30,0,0
0,0,0,0,0,8,15,0,0,13,8,0,0
0,0,0,0,0,8,15,0,0,13,8,0,0
0,0,0,0,0,30,8,42,8,8,30,0,0
0,0,0,0,0,0,30,8,8,30,0,0,0
0,0,0,0,0,0,0,0,0,0,0,0,0
0,0,0,0,0,0,0,0,0,0,0,0,0
0,0,0,0,0,0,0,0,0,0,0,0,0
0,0,0,0,0,0,0,0,0,0,0,0,0
0,0,0,0,0,0,0,0,0,0,0,0,0
0,0,0,0,0,0,0,0,0,0,0,0,0
0,0,0,0,0,0,0,0,0,0,0,0,0
endlayer

layer
0,0,0,0,0,0,0,0,0,0,0,0,0
0,0,0,0,0,0,45,6,6,45,0,0,0
0,0,0,0,0,45,6,6,6,6,45,0,0
0,0,0,0,47,6,6,7,12,6,6,46,0
0,0,0,0,6,6,7,7,7,7,6,6,0
0,0,0,0,6,6,7,7,7,7,6,6,0
0,0,0,0,47,6,6,7,7,6,6,46,0
0,0,0,0,0,48,6,6,6,6,48,0,0
0,0,0,0,0,0,48,6,6,48,0,0,0
0,0,0,0,0,0,0,0,0,0,0,0,0
0,0,0,0,0,0,0,0,0,0,0,0,0
0,0,0,0,0,0,0,0,0,0,0,0,0
0,0,0,0,0,0,0,0,0,0,0,0,0
0,0,0,0,0,0,0,0,0,0,0,0,0
0,0,0,0,0,0,0,0,0,0,0,0,0
endlayer

layer
0,0,0,0,0,0,0,0,0,0,0,0,0
0,0,0,0,0,0,0,0,0,0,0,0,0
0,0,0,0,0,0,45,46,47,45,0,0,0
0,0,0,0,0,47,6,0,12,6,46,0,0
0,0,0,0,0,6,0,0,0,0,6,46,0
0,0,0,0,0,6,0,49,0,0,6,46,0
0,0,0,0,0,47,6,0,0,6,46,0,0
0,0,0,0,0,0,48,46,47,48,0,0,0
0,0,0,0,0,0,0,0,0,0,0,0,0
0,0,0,0,0,0,0,0,0,0,0,0,0
0,0,0,0,0,0,0,0,0,0,0,0,0
0,0,0,0,0,0,0,0,0,0,0,0,0
0,0,0,0,0,0,0,0,0,0,0,0,0
0,0,0,0,0,0,0,0,0,0,0,0,0
0,0,0,0,0,0,0,0,0,0,0,0,0
endlayer

layer
0,0,0,0,0,0,0,0,0,0,0,0,0
0,0,0,0,0,0,0,0,0,0,0,0,0
0,0,0,0,0,0,0,0,0,0,0,0,0
0,0,0,0,0,0,6,0,0,6,0,0,0
0,0,0,0,0,6,0,0,0,0,6,0,0
0,0,0,0,0,6,0,49,0,0,6,0,0
0,0,0,0,0,0,6,0,0,6,0,0,0
0,0,0,0,0,0,0,0,0,0,0,0,0
0,0,0,0,0,0,0,0,0,0,0,0,0
0,0,0,0,0,0,0,0,0,0,0,0,0
0,0,0,0,0,0,0,0,0,0,0,0,0
0,0,0,0,0,0,0,0,0,0,0,0,0
0,0,0,0,0,0,0,0,0,0,0,0,0
0,0,0,0,0,0,0,0,0,0,0,0,0
0,0,0,0,0,0,0,0,0,0,0,0,0
endlayer

layer
0,0,0,0,0,0,0,0,0,0,0,0,0
0,0,0,0,0,0,0,0,0,0,0,0,0
0,0,0,0,0,0,0,0,0,0,0,0,0
0,0,0,0,0,0,47,51,50,46,0,0,0
0,0,0,0,0,47,6,0,0,6,46,0,0
0,0,0,0,0,47,6,49,0,6,46,0,0
0,0,0,0,0,0,47,51,50,46,0,0,0
0,0,0,0,0,0,0,0,0,0,0,0,0
0,0,0,0,0,0,0,0,0,0,0,0,0
0,0,0,0,0,0,0,0,0,0,0,0,0
0,0,0,0,0,0,0,0,0,0,0,0,0
0,0,0,0,0,0,0,0,0,0,0,0,0
0,0,0,0,0,0,0,0,0,0,0,0,0
0,0,0,0,0,0,0,0,0,0,0,0,0
0,0,0,0,0,0,0,0,0,0,0,0,0
endlayer

layer
0,0,0,0,0,0,0,0,0,0,0,0,0
0,0,0,0,0,0,0,0,0,0,0,0,0
0,0,0,0,0,0,0,0,0,0,0,0,0
0,0,0,0,0,0,0,45,45,0,0,0,0
0,0,0,0,0,0,47,6,6,46,0,0,0
0,0,0,0,0,0,47,6,6,46,0,0,0
0,0,0,0,0,0,0,48,48,0,0,0,0
0,0,0,0,0,0,0,0,0,0,0,0,0
0,0,0,0,0,0,0,0,0,0,0,0,0
0,0,0,0,0,0,0,0,0,0,0,0,0
0,0,0,0,0,0,0,0,0,0,0,0,0
0,0,0,0,0,0,0,0,0,0,0,0,0
0,0,0,0,0,0,0,0,0,0,0,0,0
0,0,0,0,0,0,0,0,0,0,0,0,0
0,0,0,0,0,0,0,0,0,0,0,0,0
endlayer

layer
0,0,0,0,0,0,0,0,0,0,0,0,0
0,0,0,0,0,0,0,0,0,0,0,0,0
0,0,0,0,0,0,0,0,0,0,0,0,0
0,0,0,0,0,0,0,0,0,0,0,0,0
0,0,0,0,0,0,0,52,52,0,0,0,0
0,0,0,0,0,0,0,52,52,0,0,0,0
0,0,0,0,0,0,0,0,0,0,0,0,0
0,0,0,0,0,0,0,0,0,0,0,0,0
0,0,0,0,0,0,0,0,0,0,0,0,0
0,0,0,0,0,0,0,0,0,0,0,0,0
0,0,0,0,0,0,0,0,0,0,0,0,0
0,0,0,0,0,0,0,0,0,0,0,0,0
0,0,0,0,0,0,0,0,0,0,0,0,0
0,0,0,0,0,0,0,0,0,0,0,0,0
0,0,0,0,0,0,0,0,0,0,0,0,0
endlayer

