# Chapel 10/21/2014
# Created by Ruins mod version 13.8 Ingame Parser
# authoring Player: Kujaku10
# Last Updated 7 Feb 2016

preventRotation=1

weight=1
embed_into_distance=5
acceptable_target_blocks=

unacceptable_target_blocks=flowing_water,water,flowing_lava,lava,cloud,Natura:Cloud,slime_congealed,slime_dirt,slime_grass

dimensions=24,15,14
allowable_overhang=0
max_leveling=2
leveling_buffer=-1
preserve_water=0
preserve_lava=0
preserve_plants=1

rule1=0,100,preserveBlock
rule2=0,100,minecraft:cobblestone-0,minecraft:mossy_cobblestone-0
rule3=0,100,minecraft:stone_brick_stairs-2
rule4=0,100,minecraft:stone_brick_stairs-0
rule5=0,100,minecraft:stone_brick_stairs-3
rule6=1,100,minecraft:leaves-6
rule7=0,100,minecraft:cobblestone-0
rule8=1,100,minecraft:leaves-14
rule9=0,100,minecraft:double_stone_slab-0
rule10=0,100,minecraft:stone_brick_stairs-1
rule11=0,100,minecraft:stonebrick-3
rule12=0,100,minecraft:stonebrick-0
rule13=0,100,minecraft:log-1
rule14=0,100,minecraft:spruce_stairs-0
rule15=1,100,minecraft:wooden_door-2
rule16=0,100,minecraft:spruce_stairs-1
rule17=0,100,minecraft:cobblestone_wall-0
rule18=0,100,minecraft:stained_glass_pane-5
rule19=0,100,minecraft:stained_glass_pane-11
rule20=0,100,minecraft:stained_glass_pane-13
rule21=0,100,minecraft:stained_glass_pane-3
rule22=0,100,minecraft:stained_glass_pane-9
rule23=1,100,minecraft:wooden_door-9
rule24=1,100,minecraft:wooden_door-8
rule25=0,100,minecraft:stained_glass_pane-8
rule26=0,100,minecraft:fence-0
rule27=0,100,minecraft:stone_brick_stairs-5
rule28=1,100,minecraft:torch-5
rule29=0,100,minecraft:spruce_stairs-2
rule30=0,100,minecraft:spruce_stairs-3
rule31=0,100,minecraft:stained_glass_pane-0
rule32=0,100,minecraft:stone_brick_stairs-7
rule33=0,100,minecraft:stone_brick_stairs-6
rule34=0,100,minecraft:planks-1
rule35=0,100,minecraft:stone_brick_stairs-4

rule36=0,100,minecraft:fence_gate-1
rule37=0,100,minecraft:stone_slab-2

rule38=0,100,CommandBlock:RUINSTRIGGER /summon Villager ~0 ~0 ~0 {Profession:2,CustomName:Village Priest,Offers:{Recipes:[{uses:-25,maxUses:25,buy:{id:352,Count:32},sell:{id:388,Count:1}},{uses:-25,maxUses:25,buy:{id:367,Count:32},sell:{id:388,Count:1}},{uses:-25,maxUses:25,buy:{id:397,Count:32},sell:{id:388,Count:1}}]}}:@

layer
1,1,1,1,1,1,1,1,1,1,1,1,1,1
1,1,2,2,2,2,2,2,2,2,2,2,1,1
1,1,2,2,2,2,2,2,2,2,2,2,1,1
1,1,2,2,2,2,2,2,2,2,2,2,1,1
1,1,2,2,2,2,2,2,2,2,2,2,1,1
1,1,2,2,2,2,2,2,2,2,2,2,1,1
1,1,2,2,2,2,2,2,2,2,2,2,1,1
1,1,2,2,2,2,2,2,2,2,2,2,1,1
1,1,2,2,2,2,2,2,2,2,2,2,1,1
1,1,2,2,2,2,2,2,2,2,2,2,1,1
1,1,2,2,2,2,2,2,2,2,2,2,1,1
1,1,2,2,2,2,2,2,2,2,2,2,1,1
1,1,2,2,2,2,2,2,2,2,2,2,1,1
1,1,2,2,2,2,2,2,2,2,2,2,1,1
1,1,1,1,1,1,2,2,1,1,1,1,1,1
endlayer

layer
1,1,1,1,1,1,1,1,1,1,1,1,1,1
1,1,2,2,2,2,2,2,2,2,2,2,1,1
1,1,2,2,2,2,2,2,2,2,2,2,1,1
1,1,2,2,2,2,2,2,2,2,2,2,1,1
1,1,2,2,2,2,2,2,2,2,2,2,1,1
1,1,2,2,2,2,2,2,2,2,2,2,1,1
1,1,2,2,2,2,2,2,2,2,2,2,1,1
1,1,2,2,2,2,2,2,2,2,2,2,1,1
1,1,2,2,2,2,2,2,2,2,2,2,1,1
1,1,2,2,2,2,2,2,2,2,2,2,1,1
1,1,2,2,2,2,2,2,2,2,2,2,1,1
1,1,2,2,2,2,2,2,2,2,2,2,1,1
1,1,2,2,2,2,2,2,2,2,2,2,1,1
1,1,2,2,2,2,2,2,2,2,2,2,1,1
1,1,1,1,1,1,2,2,1,1,1,1,1,1
endlayer

layer
1,1,1,1,1,1,1,1,1,1,1,1,1,1
1,1,2,2,2,2,2,2,2,2,2,2,1,1
1,1,2,2,2,2,2,2,2,2,2,2,1,1
1,1,2,2,2,2,2,2,2,2,2,2,1,1
1,1,2,2,2,2,2,2,2,2,2,2,1,1
1,1,2,2,2,2,2,2,2,2,2,2,1,1
1,1,2,2,2,2,2,2,2,2,2,2,1,1
1,1,2,2,2,2,2,2,2,2,2,2,1,1
1,1,2,2,2,2,2,2,2,2,2,2,1,1
1,1,2,2,2,2,2,2,2,2,2,2,1,1
1,1,2,2,2,2,2,2,2,2,2,2,1,1
1,1,2,2,2,2,2,2,2,2,2,2,1,1
1,1,2,2,2,2,2,2,2,2,2,2,1,1
1,1,2,2,2,2,2,2,2,2,2,2,1,1
1,1,1,1,1,1,2,2,1,1,1,1,1,1
endlayer

layer
1,1,1,1,1,1,1,1,1,1,1,1,1,1
1,1,2,2,2,2,2,2,2,2,2,2,1,1
1,1,2,2,2,2,2,2,2,2,2,2,1,1
1,1,2,2,2,2,2,2,2,2,2,2,1,1
1,1,2,2,2,2,2,2,2,2,2,2,1,1
1,1,2,2,2,2,2,2,2,2,2,2,1,1
1,1,2,2,2,2,2,2,2,2,2,2,1,1
1,1,2,2,2,2,2,2,2,2,2,2,1,1
1,1,2,2,2,2,2,2,2,2,2,2,1,1
1,1,2,2,2,2,2,2,2,2,2,2,1,1
1,1,2,2,2,2,2,2,2,2,2,2,1,1
1,1,2,2,2,2,2,2,2,2,2,2,1,1
1,1,2,2,2,2,2,2,2,2,2,2,1,1
1,1,2,2,2,2,2,2,2,2,2,2,1,1
1,1,1,1,1,1,2,2,1,1,1,1,1,1
endlayer

layer
1,1,1,1,1,1,1,1,1,1,1,1,1,1
1,1,2,2,2,2,2,2,2,2,2,2,1,1
1,1,2,2,2,2,2,2,2,2,2,2,1,1
1,1,2,2,2,2,2,2,2,2,2,2,1,1
1,1,2,2,2,2,2,2,2,2,2,2,1,1
1,1,2,2,2,2,2,2,2,2,2,2,1,1
1,1,2,2,2,2,2,2,2,2,2,2,1,1
1,1,2,2,2,2,2,2,2,2,2,2,1,1
1,1,2,2,2,2,2,2,2,2,2,2,1,1
1,1,2,2,2,2,2,2,2,2,2,2,1,1
1,1,2,2,2,2,2,2,2,2,2,2,1,1
1,1,2,2,2,2,2,2,2,2,2,2,1,1
1,1,2,2,2,2,2,2,2,2,2,2,1,1
1,1,2,2,2,2,2,2,2,2,2,2,1,1
1,1,1,1,1,1,2,2,1,1,1,1,1,1
endlayer


layer
1,1,1,1,0,0,0,0,0,0,1,1,1,1
1,1,5,4,4,4,4,4,4,4,4,3,1,1
1,8,5,7,7,7,7,7,7,7,7,3,6,1
1,6,5,7,7,7,7,7,7,7,7,3,6,1
0,6,5,7,7,7,7,7,7,7,7,3,6,0
0,6,5,7,9,9,9,9,9,9,7,3,6,0
0,6,5,7,9,9,9,9,9,9,7,3,6,0
0,6,5,7,9,9,9,9,9,9,7,3,6,0
0,6,5,7,9,9,9,9,9,9,7,3,6,0
0,6,5,7,9,9,9,9,9,9,7,3,6,0
0,6,5,7,9,9,9,9,9,9,7,3,6,0
1,6,5,7,9,9,9,9,9,9,7,3,6,1
1,6,5,7,7,7,7,7,7,7,7,3,6,1
1,1,10,10,10,10,10,10,10,10,10,3,1,1
1,1,1,1,0,0,0,0,0,0,1,1,1,1
endlayer

layer
0,0,0,0,0,0,0,0,0,0,0,0,0,0
0,0,0,0,0,0,0,0,0,0,0,0,0,0
0,0,0,11,12,11,12,12,11,12,11,0,0,0
0,0,0,12,9,9,9,9,9,9,12,0,0,0
0,0,0,12,9,9,9,9,9,9,12,0,0,0
0,0,0,12,9,10,13,13,10,9,12,0,0,0
0,0,0,12,0,0,0,0,0,0,12,0,0,0
0,0,0,12,14,14,0,0,14,14,12,0,0,0
0,0,0,12,0,0,0,0,0,0,12,0,0,0
0,0,0,12,14,14,0,0,14,14,12,0,0,0
0,0,0,12,0,0,0,0,0,0,12,0,0,0
0,0,0,12,14,14,0,0,14,14,12,0,0,0
0,0,0,11,12,11,15,15,11,12,11,0,0,0
0,0,0,0,0,0,0,0,0,0,0,0,0,0
0,0,0,0,0,0,0,0,0,0,0,0,0,0
endlayer

layer
0,0,0,0,0,0,0,0,0,0,0,0,0,0
0,0,0,0,0,0,0,0,0,0,0,0,0,0
0,0,0,9,12,9,9,9,9,12,9,0,0,0
0,0,0,12,16,16,0,0,16,16,12,0,0,0
0,0,0,12,0,0,0,38,0,0,12,0,0,0
0,0,0,12,17,36,11,11,36,17,12,0,0,0
0,0,0,12,0,0,0,0,0,0,12,0,0,0
0,0,0,19,0,0,0,0,0,0,18,0,0,0
0,0,0,12,0,0,0,0,0,0,12,0,0,0
0,0,0,18,0,0,0,0,0,0,20,0,0,0
0,0,0,12,0,0,0,0,0,0,12,0,0,0
0,0,0,21,0,0,0,0,0,0,19,0,0,0
0,0,0,9,18,9,24,23,9,22,9,0,0,0
0,0,0,0,0,26,0,0,26,0,0,0,0,0
0,0,0,0,0,0,0,0,0,0,0,0,0,0
endlayer

layer
0,0,0,0,0,0,0,0,0,0,0,0,0,0
0,0,0,0,0,0,0,0,0,0,0,0,0,0
0,0,0,9,12,9,25,18,9,12,9,0,0,0
0,0,0,12,0,0,0,0,0,0,12,0,0,0
0,0,0,12,0,0,0,0,0,0,12,0,0,0
0,0,0,12,17,0,37,37,0,17,12,0,0,0
0,0,0,12,0,0,0,0,0,0,12,0,0,0
0,0,0,20,0,0,0,0,0,0,19,0,0,0
0,0,0,12,26,0,0,0,0,26,12,0,0,0
0,0,0,19,0,0,0,0,0,0,22,0,0,0
0,0,0,12,26,0,0,0,0,26,12,0,0,0
0,0,0,20,0,0,0,0,0,0,18,0,0,0
0,0,0,9,19,9,27,27,9,20,9,0,0,0
0,0,0,0,0,28,0,0,28,0,0,0,0,0
0,0,0,0,0,0,0,0,0,0,0,0,0,0
endlayer

layer
0,0,0,0,0,0,0,0,0,0,0,0,0,0
0,0,0,0,0,0,0,0,0,0,0,0,0,0
0,0,0,9,12,9,21,20,9,12,9,0,0,0
0,0,0,12,0,0,0,0,0,0,12,0,0,0
0,0,0,12,0,0,0,0,0,0,12,0,0,0
0,0,0,12,28,0,0,0,0,28,12,0,0,0
0,0,0,12,0,0,0,0,0,0,12,0,0,0
0,0,0,22,0,0,0,0,0,0,21,0,0,0
0,0,0,12,28,0,0,0,0,28,12,0,0,0
0,0,0,20,0,0,0,0,0,0,18,0,0,0
0,0,0,12,28,0,0,0,0,28,12,0,0,0
0,0,0,22,0,0,0,0,0,0,21,0,0,0
0,0,0,9,22,9,12,12,9,19,9,0,0,0
0,0,0,0,0,0,0,0,0,0,0,0,0,0
0,0,0,0,0,0,0,0,0,0,0,0,0,0
endlayer

layer
0,0,0,0,0,0,0,0,0,0,0,0,0,0
0,0,30,0,0,0,0,0,0,0,0,29,0,0
0,0,30,11,12,9,19,31,9,12,11,29,0,0
0,0,30,12,0,0,0,0,0,0,12,29,0,0
0,0,30,12,0,0,0,0,0,0,12,29,0,0
0,0,30,12,12,33,0,0,32,12,12,29,0,0
0,0,30,12,0,0,0,0,0,0,12,29,0,0
0,0,30,12,0,0,0,0,0,0,12,29,0,0
0,0,30,12,0,0,0,0,0,0,12,29,0,0
0,0,30,12,33,0,0,0,0,32,12,29,0,0
0,0,30,12,0,0,0,0,0,0,12,29,0,0
0,0,30,12,0,0,0,0,0,0,12,29,0,0
0,0,30,11,12,9,25,31,9,12,11,29,0,0
0,0,30,0,0,0,0,0,0,0,0,29,0,0
0,0,0,0,0,0,0,0,0,0,0,0,0,0
endlayer

layer
0,0,0,0,0,0,0,0,0,0,0,0,0,0
0,0,0,30,0,0,0,0,0,0,29,0,0,0
0,0,0,30,12,9,18,22,9,12,29,0,0,0
0,0,0,30,34,0,0,0,0,34,29,0,0,0
0,0,0,30,34,0,0,0,0,34,29,0,0,0
0,0,0,30,34,11,12,12,11,34,29,0,0,0
0,0,0,30,34,0,0,0,0,34,29,0,0,0
0,0,0,30,34,0,0,0,0,34,29,0,0,0
0,0,0,30,34,0,0,0,0,34,29,0,0,0
0,0,0,30,34,12,12,12,12,34,29,0,0,0
0,0,0,30,34,0,0,0,0,34,29,0,0,0
0,0,0,30,34,0,0,0,0,34,29,0,0,0
0,0,0,30,12,9,31,25,9,12,29,0,0,0
0,0,0,30,0,0,0,0,0,0,29,0,0,0
0,0,0,0,0,0,0,0,0,0,0,0,0,0
endlayer

layer
0,0,0,0,0,0,0,0,0,0,0,0,0,0
0,0,0,0,30,0,0,0,0,29,0,0,0,0
0,0,0,0,30,11,9,9,11,29,0,0,0,0
0,0,0,0,30,34,0,0,34,29,0,0,0,0
0,0,0,0,30,34,0,0,34,29,0,0,0,0
0,0,0,0,30,34,12,12,34,29,0,0,0,0
0,0,0,0,30,34,0,0,34,29,0,0,0,0
0,0,0,0,30,34,0,0,34,29,0,0,0,0
0,0,0,0,30,34,0,0,34,29,0,0,0,0
0,0,0,0,30,34,12,12,34,29,0,0,0,0
0,0,0,0,30,34,0,0,34,29,0,0,0,0
0,0,0,0,30,34,0,0,34,29,0,0,0,0
0,0,0,0,30,11,12,12,11,29,0,0,0,0
0,0,0,0,30,0,0,0,0,29,0,0,0,0
0,0,0,0,0,0,0,0,0,0,0,0,0,0
endlayer

layer
0,0,0,0,0,0,0,0,0,0,0,0,0,0
0,0,0,0,0,30,0,0,29,0,0,0,0,0
0,0,0,0,0,30,12,12,29,0,0,0,0,0
0,0,0,0,0,30,34,34,29,0,0,0,0,0
0,0,0,0,0,30,34,34,29,0,0,0,0,0
0,0,0,0,0,30,34,34,29,0,0,0,0,0
0,0,0,0,0,30,34,34,29,0,0,0,0,0
0,0,0,0,0,30,34,34,29,0,0,0,0,0
0,0,0,0,0,30,34,34,29,0,0,0,0,0
0,0,0,0,0,9,12,12,9,0,0,0,0,0
0,0,0,0,0,12,0,0,12,0,0,0,0,0
0,0,0,0,0,12,0,0,12,0,0,0,0,0
0,0,0,0,0,9,12,12,9,0,0,0,0,0
0,0,0,0,0,30,0,0,29,0,0,0,0,0
0,0,0,0,0,0,0,0,0,0,0,0,0,0
endlayer

layer
0,0,0,0,0,0,0,0,0,0,0,0,0,0
0,0,0,0,0,0,30,29,0,0,0,0,0,0
0,0,0,0,0,0,30,29,0,0,0,0,0,0
0,0,0,0,0,0,30,29,0,0,0,0,0,0
0,0,0,0,0,0,30,29,0,0,0,0,0,0
0,0,0,0,0,0,30,29,0,0,0,0,0,0
0,0,0,0,0,0,30,29,0,0,0,0,0,0
0,0,0,0,0,0,30,29,0,0,0,0,0,0
0,0,0,0,0,0,30,29,0,0,0,0,0,0
0,0,0,0,0,9,12,12,9,0,0,0,0,0
0,0,0,0,0,12,0,0,12,0,0,0,0,0
0,0,0,0,0,12,0,0,12,0,0,0,0,0
0,0,0,0,0,9,12,12,9,0,0,0,0,0
0,0,0,0,0,0,30,29,0,0,0,0,0,0
0,0,0,0,0,0,0,0,0,0,0,0,0,0
endlayer

layer
0,0,0,0,0,0,0,0,0,0,0,0,0,0
0,0,0,0,0,0,0,0,0,0,0,0,0,0
0,0,0,0,0,0,0,0,0,0,0,0,0,0
0,0,0,0,0,0,0,0,0,0,0,0,0,0
0,0,0,0,0,0,0,0,0,0,0,0,0,0
0,0,0,0,0,0,0,0,0,0,0,0,0,0
0,0,0,0,0,0,0,0,0,0,0,0,0,0
0,0,0,0,0,0,0,0,0,0,0,0,0,0
0,0,0,0,0,0,0,0,0,0,0,0,0,0
0,0,0,0,0,9,12,12,9,0,0,0,0,0
0,0,0,0,0,12,0,0,12,0,0,0,0,0
0,0,0,0,0,12,0,0,12,0,0,0,0,0
0,0,0,0,0,9,12,12,9,0,0,0,0,0
0,0,0,0,0,0,0,0,0,0,0,0,0,0
0,0,0,0,0,0,0,0,0,0,0,0,0,0
endlayer

layer
0,0,0,0,0,0,0,0,0,0,0,0,0,0
0,0,0,0,0,0,0,0,0,0,0,0,0,0
0,0,0,0,0,0,0,0,0,0,0,0,0,0
0,0,0,0,0,0,0,0,0,0,0,0,0,0
0,0,0,0,0,0,0,0,0,0,0,0,0,0
0,0,0,0,0,0,0,0,0,0,0,0,0,0
0,0,0,0,0,0,0,0,0,0,0,0,0,0
0,0,0,0,0,0,0,0,0,0,0,0,0,0
0,0,0,0,0,0,0,0,0,0,0,0,0,0
0,0,0,0,0,9,0,0,9,0,0,0,0,0
0,0,0,0,0,0,0,0,0,0,0,0,0,0
0,0,0,0,0,0,0,0,0,0,0,0,0,0
0,0,0,0,0,9,0,0,9,0,0,0,0,0
0,0,0,0,0,0,0,0,0,0,0,0,0,0
0,0,0,0,0,0,0,0,0,0,0,0,0,0
endlayer

layer
0,0,0,0,0,0,0,0,0,0,0,0,0,0
0,0,0,0,0,0,0,0,0,0,0,0,0,0
0,0,0,0,0,0,0,0,0,0,0,0,0,0
0,0,0,0,0,0,0,0,0,0,0,0,0,0
0,0,0,0,0,0,0,0,0,0,0,0,0,0
0,0,0,0,0,0,0,0,0,0,0,0,0,0
0,0,0,0,0,0,0,0,0,0,0,0,0,0
0,0,0,0,0,0,0,0,0,0,0,0,0,0
0,0,0,0,0,0,0,0,0,0,0,0,0,0
0,0,0,0,0,9,33,32,9,0,0,0,0,0
0,0,0,0,0,27,0,0,27,0,0,0,0,0
0,0,0,0,0,35,0,0,35,0,0,0,0,0
0,0,0,0,0,9,33,32,9,0,0,0,0,0
0,0,0,0,0,0,0,0,0,0,0,0,0,0
0,0,0,0,0,0,0,0,0,0,0,0,0,0
endlayer

layer
0,0,0,0,0,0,0,0,0,0,0,0,0,0
0,0,0,0,0,0,0,0,0,0,0,0,0,0
0,0,0,0,0,0,0,0,0,0,0,0,0,0
0,0,0,0,0,0,0,0,0,0,0,0,0,0
0,0,0,0,0,0,0,0,0,0,0,0,0,0
0,0,0,0,0,0,0,0,0,0,0,0,0,0
0,0,0,0,0,0,0,0,0,0,0,0,0,0
0,0,0,0,0,0,0,0,0,0,0,0,0,0
0,0,0,0,0,0,0,0,0,0,0,0,0,0
0,0,0,0,0,11,12,12,11,0,0,0,0,0
0,0,0,0,0,12,0,0,12,0,0,0,0,0
0,0,0,0,0,12,0,0,12,0,0,0,0,0
0,0,0,0,0,11,12,12,11,0,0,0,0,0
0,0,0,0,0,0,0,0,0,0,0,0,0,0
0,0,0,0,0,0,0,0,0,0,0,0,0,0
endlayer

layer
0,0,0,0,0,0,0,0,0,0,0,0,0,0
0,0,0,0,0,0,0,0,0,0,0,0,0,0
0,0,0,0,0,0,0,0,0,0,0,0,0,0
0,0,0,0,0,0,0,0,0,0,0,0,0,0
0,0,0,0,0,0,0,0,0,0,0,0,0,0
0,0,0,0,0,0,0,0,0,0,0,0,0,0
0,0,0,0,0,0,0,0,0,0,0,0,0,0
0,0,0,0,0,0,0,0,0,0,0,0,0,0
0,0,0,0,14,14,14,14,14,14,0,0,0,0
0,0,0,0,30,34,34,34,34,29,0,0,0,0
0,0,0,0,30,34,0,0,34,29,0,0,0,0
0,0,0,0,30,34,0,0,34,29,0,0,0,0
0,0,0,0,30,34,34,34,34,29,0,0,0,0
0,0,0,0,16,16,16,16,16,16,0,0,0,0
0,0,0,0,0,0,0,0,0,0,0,0,0,0
endlayer

layer
0,0,0,0,0,0,0,0,0,0,0,0,0,0
0,0,0,0,0,0,0,0,0,0,0,0,0,0
0,0,0,0,0,0,0,0,0,0,0,0,0,0
0,0,0,0,0,0,0,0,0,0,0,0,0,0
0,0,0,0,0,0,0,0,0,0,0,0,0,0
0,0,0,0,0,0,0,0,0,0,0,0,0,0
0,0,0,0,0,0,0,0,0,0,0,0,0,0
0,0,0,0,0,0,0,0,0,0,0,0,0,0
0,0,0,0,0,0,0,0,0,0,0,0,0,0
0,0,0,0,0,34,34,34,34,0,0,0,0,0
0,0,0,0,0,34,0,0,34,0,0,0,0,0
0,0,0,0,0,34,0,0,34,0,0,0,0,0
0,0,0,0,0,34,34,34,34,0,0,0,0,0
0,0,0,0,0,0,0,0,0,0,0,0,0,0
0,0,0,0,0,0,0,0,0,0,0,0,0,0
endlayer

layer
0,0,0,0,0,0,0,0,0,0,0,0,0,0
0,0,0,0,0,0,0,0,0,0,0,0,0,0
0,0,0,0,0,0,0,0,0,0,0,0,0,0
0,0,0,0,0,0,0,0,0,0,0,0,0,0
0,0,0,0,0,0,0,0,0,0,0,0,0,0
0,0,0,0,0,0,0,0,0,0,0,0,0,0
0,0,0,0,0,0,0,0,0,0,0,0,0,0
0,0,0,0,0,0,0,0,0,0,0,0,0,0
0,0,0,0,0,0,0,0,0,0,0,0,0,0
0,0,0,0,0,30,14,14,29,0,0,0,0,0
0,0,0,0,0,30,34,34,29,0,0,0,0,0
0,0,0,0,0,30,34,34,29,0,0,0,0,0
0,0,0,0,0,30,16,16,16,0,0,0,0,0
0,0,0,0,0,0,0,0,0,0,0,0,0,0
0,0,0,0,0,0,0,0,0,0,0,0,0,0
endlayer

layer
0,0,0,0,0,0,0,0,0,0,0,0,0,0
0,0,0,0,0,0,0,0,0,0,0,0,0,0
0,0,0,0,0,0,0,0,0,0,0,0,0,0
0,0,0,0,0,0,0,0,0,0,0,0,0,0
0,0,0,0,0,0,0,0,0,0,0,0,0,0
0,0,0,0,0,0,0,0,0,0,0,0,0,0
0,0,0,0,0,0,0,0,0,0,0,0,0,0
0,0,0,0,0,0,0,0,0,0,0,0,0,0
0,0,0,0,0,0,0,0,0,0,0,0,0,0
0,0,0,0,0,0,0,0,0,0,0,0,0,0
0,0,0,0,0,0,34,34,0,0,0,0,0,0
0,0,0,0,0,0,34,34,0,0,0,0,0,0
0,0,0,0,0,0,0,0,0,0,0,0,0,0
0,0,0,0,0,0,0,0,0,0,0,0,0,0
0,0,0,0,0,0,0,0,0,0,0,0,0,0
endlayer

layer
0,0,0,0,0,0,0,0,0,0,0,0,0,0
0,0,0,0,0,0,0,0,0,0,0,0,0,0
0,0,0,0,0,0,0,0,0,0,0,0,0,0
0,0,0,0,0,0,0,0,0,0,0,0,0,0
0,0,0,0,0,0,0,0,0,0,0,0,0,0
0,0,0,0,0,0,0,0,0,0,0,0,0,0
0,0,0,0,0,0,0,0,0,0,0,0,0,0
0,0,0,0,0,0,0,0,0,0,0,0,0,0
0,0,0,0,0,0,0,0,0,0,0,0,0,0
0,0,0,0,0,0,0,0,0,0,0,0,0,0
0,0,0,0,0,0,30,14,0,0,0,0,0,0
0,0,0,0,0,0,16,29,0,0,0,0,0,0
0,0,0,0,0,0,0,0,0,0,0,0,0,0
0,0,0,0,0,0,0,0,0,0,0,0,0,0
0,0,0,0,0,0,0,0,0,0,0,0,0,0
endlayer

