# Barn Roof Cottage -- 10/21/2014
# Created by Ruins mod version 13.8 Ingame Parser
# authoring Player: Kujaku10
# Last Updated 1 Feb 2016

weight=1
embed_into_distance=5
acceptable_target_blocks=

unacceptable_target_blocks=flowing_water,water,flowing_lava,lava,cloud,Natura:Cloud,slime_congealed,slime_dirt,slime_grass

dimensions=19,15,15
allowable_overhang=0
max_leveling=3
leveling_buffer=-1
preserve_water=0
preserve_lava=0
preserve_plants=1

rule1=0,100,preserveBlock
rule2=0,100,minecraft:grass-0
rule3=0,100,minecraft:red_flower-8
rule4=0,100,minecraft:red_flower-4
rule5=0,100,minecraft:leaves-14
rule6=0,100,minecraft:fence-0
rule7=0,100,minecraft:cobblestone-0
rule8=0,100,minecraft:log-0
rule9=0,100,minecraft:log-5
rule10=0,100,minecraft:stone_brick_stairs-0
rule11=0,100,minecraft:fence_gate-0
rule12=0,100,minecraft:stone_brick_stairs-2
rule13=0,100,minecraft:stone_brick_stairs-1
rule14=1,100,minecraft:torch-5
rule15=0,100,minecraft:planks-1
rule16=0,100,minecraft:planks-4
rule17=0,100,minecraft:wooden_door-1
rule18=2,100,minecraft:ladder-2
rule19=0,100,minecraft:wooden_door-8
rule20=0,100,minecraft:oak_stairs-2
rule21=0,100,minecraft:oak_stairs-7
rule22=0,100,minecraft:oak_stairs-6
rule23=0,100,minecraft:oak_stairs-3
rule24=0,100,minecraft:planks-0
rule25=0,100,minecraft:oak_stairs-0
rule26=0,100,minecraft:oak_stairs-5
rule27=0,100,minecraft:oak_stairs-4
rule28=0,100,minecraft:oak_stairs-1
rule29=0,100,minecraft:wooden_slab-0

rule30=0,100,CommandBlock:RUINSTRIGGER /summon Skeleton ~0 ~1 ~0 {CustomName:Bandit,Equipment:[{Count:1,id:261,tag:{display:{Name:Bandit Bow},ench:[{id:21,lvl:5},{id:48,lvl:2},{id:49,lvl:3}]}},{Count:1,id:301},{Count:1,id:300},{Count:1,id:299},{Count:1,id:397,Damage:3}],Attributes:[{Name:generic.maxHealth,Base:15}],DropChances:[1.0F,0.5F,0.5F,0.5F,0.5F],PersistenceRequired:1}:@

rule31=0,100,CommandBlock:RUINSTRIGGER /summon Sheep ~0 ~0 ~0:@

rule32=0,100,minecraft:crafting_table-0

rule33=0,100,CommandBlock:RUINSTRIGGER /summon Villager ~0 ~0 ~0 {Profession:0,CustomName:Livestock Trader,Offers:{Recipes:[{maxUses:8,buy:{id:388,Count:4},sell:{id:383,Damage:90,Count:1}},{maxUses:8,buy:{id:388,Count:4},sell:{id:383,Damage:91,Count:1}},{maxUses:8,buy:{id:388,Count:8},sell:{id:383,Damage:92,Count:1}},{maxUses:8,buy:{id:388,Count:2},sell:{id:383,Damage:93,Count:1}},{maxUses:8,buy:{id:388,Count:24},sell:{id:383,Damage:100,Count:1}},{maxUses:8,buy:{id:388,Count:32},sell:{id:383,Damage:96,Count:1}},{maxUses:8,buy:{id:295,Count:32},sell:{id:296,Count:4}}]}}:@



layer
1,1,1,1,1,1,1,1,1,1,1,1,1,1,1
1,1,1,1,1,1,1,1,1,1,1,1,1,1,1
1,1,1,1,1,1,1,1,1,1,1,1,1,1,1
1,1,2,2,2,2,2,2,2,2,2,2,2,2,1
1,1,2,2,2,2,2,2,2,2,2,2,2,2,1
1,1,2,2,2,2,2,2,2,2,2,2,2,2,1
1,1,2,2,2,2,2,2,2,2,2,2,2,2,1
1,1,2,2,2,2,2,2,2,2,2,2,2,2,1
1,1,2,2,2,2,2,2,2,2,2,2,2,2,1
1,1,2,2,2,2,2,2,2,2,2,2,2,2,1
1,1,2,2,2,2,2,2,2,2,2,2,2,2,1
1,1,2,2,2,2,2,2,2,2,2,2,2,2,1
1,1,1,1,1,1,1,1,1,1,1,1,1,1,1
1,1,1,1,1,1,1,1,1,1,1,1,1,1,1
1,1,1,1,1,1,1,1,1,1,1,1,1,1,1
endlayer

layer
1,1,1,1,1,1,1,1,1,1,1,1,1,1,1
1,1,1,1,1,1,1,1,1,1,1,1,1,1,1
1,1,1,1,1,1,1,1,1,1,1,1,1,1,1
1,1,2,2,2,2,2,2,2,2,2,2,2,2,1
1,1,2,2,2,2,2,2,2,2,2,2,2,2,1
1,1,2,2,2,2,2,2,2,2,2,2,2,2,1
1,1,2,2,2,2,2,2,2,2,2,2,2,2,1
1,1,2,2,2,2,2,2,2,2,2,2,2,2,1
1,1,2,2,2,2,2,2,2,2,2,2,2,2,1
1,1,2,2,2,2,2,2,2,2,2,2,2,2,1
1,1,2,2,2,2,2,2,2,2,2,2,2,2,1
1,1,2,2,2,2,2,2,2,2,2,2,2,2,1
1,1,1,1,1,1,1,1,1,1,1,1,1,1,1
1,1,1,1,1,1,1,1,1,1,1,1,1,1,1
1,1,1,1,1,1,1,1,1,1,1,1,1,1,1
endlayer

layer
1,1,1,1,1,1,1,1,1,1,1,1,1,1,1
1,1,1,1,1,1,1,1,1,1,1,1,1,1,1
1,1,1,1,1,1,1,1,1,1,1,1,1,1,1
1,1,2,2,2,2,2,2,2,2,2,2,2,2,1
1,1,2,2,2,2,2,2,2,2,2,2,2,2,1
1,1,2,2,2,2,2,2,2,2,2,2,2,2,1
1,1,2,2,2,2,2,2,2,2,2,2,2,2,1
1,1,2,2,2,2,2,2,2,2,2,2,2,2,1
1,1,2,2,2,2,2,2,2,2,2,2,2,2,1
1,1,2,2,2,2,2,2,2,2,2,2,2,2,1
1,1,2,2,2,2,2,2,2,2,2,2,2,2,1
1,1,2,2,2,2,2,2,2,2,2,2,2,2,1
1,1,1,1,1,1,1,1,1,1,1,1,1,1,1
1,1,1,1,1,1,1,1,1,1,1,1,1,1,1
1,1,1,1,1,1,1,1,1,1,1,1,1,1,1
endlayer


layer
1,1,1,1,1,1,1,1,1,1,1,1,1,1,1
1,1,1,1,1,1,1,1,1,1,1,1,1,1,1
1,1,1,1,1,1,1,1,1,1,1,1,1,1,1
1,1,2,2,2,2,2,2,2,2,2,2,2,2,1
1,1,2,2,2,2,2,2,2,2,2,2,2,2,1
1,1,2,2,2,2,2,2,2,2,2,2,2,2,1
1,1,2,2,2,2,2,2,2,2,2,2,2,2,1
1,1,2,2,2,2,2,2,2,2,2,2,2,2,1
1,1,2,2,2,2,2,2,2,2,2,2,2,2,1
1,1,2,2,2,2,2,2,2,2,2,2,2,2,1
1,1,2,2,2,2,2,2,2,2,2,2,2,2,1
1,1,2,2,2,2,2,2,2,2,2,2,2,2,1
1,1,1,1,1,1,1,1,1,1,1,1,1,1,1
1,1,1,1,1,1,1,1,1,1,1,1,1,1,1
1,1,1,1,1,1,1,1,1,1,1,1,1,1,1
endlayer

layer
1,1,1,1,1,1,1,1,1,1,1,1,1,1,1
1,1,1,1,1,1,1,1,1,1,1,1,1,1,1
1,1,1,1,1,1,1,1,1,1,1,1,1,1,1
1,1,2,2,2,2,2,2,2,2,2,2,2,2,1
1,1,2,2,2,2,2,2,2,2,2,2,2,2,1
1,1,2,2,2,2,2,2,2,2,2,2,2,2,1
1,1,2,2,2,2,2,2,2,2,2,2,2,2,1
1,1,2,2,2,2,2,2,2,2,2,2,2,2,1
1,1,2,2,2,2,2,2,2,2,2,2,2,2,1
1,1,2,2,2,2,2,2,2,2,2,2,2,2,1
1,1,2,2,2,2,2,2,2,2,2,2,2,2,1
1,1,2,2,2,2,2,2,2,2,2,2,2,2,1
1,1,1,1,1,1,1,1,1,1,1,1,1,1,1
1,1,1,1,1,1,1,1,1,1,1,1,1,1,1
1,1,1,1,1,1,1,1,1,1,1,1,1,1,1
endlayer


layer
1,1,1,1,1,1,1,1,1,1,1,1,1,1,1
1,1,1,0,0,0,0,0,3,0,0,0,1,1,1
1,1,0,0,5,5,5,0,3,4,0,0,0,0,0
1,0,7,7,7,7,7,7,7,6,6,6,6,6,0
1,0,7,8,9,8,9,8,7,0,0,31,0,6,0
1,5,7,9,8,9,8,9,7,4,0,0,0,6,0
1,5,7,8,9,8,9,8,7,10,0,0,0,6,0
1,5,7,9,8,9,8,9,7,12,0,0,0,11,0
1,5,7,8,9,8,9,8,7,13,0,0,0,6,0
1,5,7,9,8,9,8,9,7,4,0,0,0,6,0
1,0,7,8,9,8,9,8,7,0,0,31,0,6,0
1,0,7,7,7,7,7,7,7,6,6,6,6,6,0
1,1,0,0,5,5,5,0,3,4,0,0,0,0,0
1,1,1,0,0,0,0,0,3,0,0,0,1,1,1
1,1,1,1,1,1,1,1,1,1,1,1,1,1,1
endlayer

layer
1,1,1,1,1,1,1,1,1,1,1,1,1,1,1
1,1,0,0,0,0,0,0,0,0,0,0,0,0,0
1,0,0,0,0,0,0,0,0,0,0,0,0,0,0
1,0,15,16,16,15,16,16,15,0,0,0,0,14,0
1,0,16,33,6,0,0,0,16,0,0,0,0,0,0
1,0,16,0,6,30,0,0,16,0,0,0,0,0,0
1,0,16,32,6,0,0,0,16,0,0,0,0,0,0
1,0,15,18,0,0,0,17,0,0,0,0,0,0,0
1,0,16,0,0,0,0,0,16,0,0,0,0,0,0
1,0,16,0,0,0,0,0,16,0,0,0,0,0,0
1,0,16,0,0,0,0,0,16,0,0,0,0,0,0
1,0,15,16,16,15,16,16,15,0,0,0,0,14,0
1,0,0,0,0,0,0,0,0,0,0,0,0,0,0
1,1,0,0,0,0,0,0,0,0,0,0,0,0,0
1,1,1,1,1,1,1,1,1,1,1,1,1,1,1
endlayer

layer
1,1,0,0,0,0,0,0,0,0,0,0,0,0,0
1,0,0,0,0,0,0,0,0,0,0,0,0,0,0
1,0,0,0,0,0,0,0,0,0,0,0,0,0,0
1,0,15,16,6,15,6,16,15,0,0,0,0,0,0
1,0,16,0,0,6,0,0,16,0,0,0,0,0,0
1,0,6,0,0,0,0,0,6,0,0,0,0,0,0
1,0,16,0,14,0,0,0,16,6,0,0,0,0,0
1,0,15,18,0,0,0,19,0,0,0,0,0,0,0
1,0,16,0,0,0,0,0,16,6,0,0,0,0,0
1,0,6,0,0,0,0,0,6,0,0,0,0,0,0
1,0,16,0,0,6,0,0,16,0,0,0,0,0,0
1,0,15,16,6,15,6,16,15,0,0,0,0,0,0
1,0,0,0,0,0,0,0,0,0,0,0,0,0,0
1,0,0,0,0,0,0,0,0,0,0,0,0,0,0
1,1,0,0,0,0,0,0,0,0,0,0,0,0,0
endlayer

layer
1,0,0,0,0,0,0,0,0,0,0,0,0,0,0
1,0,0,0,0,0,0,0,0,0,0,0,0,0,0
1,0,0,0,0,0,0,0,0,0,0,0,0,0,0
1,0,15,16,16,15,16,16,15,0,0,0,0,0,0
1,0,16,0,6,14,0,0,16,0,0,0,0,0,0
1,0,16,0,6,0,0,0,16,0,0,0,0,0,0
1,0,16,6,6,0,0,0,16,14,0,0,0,0,0
1,0,15,18,0,0,0,0,15,0,0,0,0,0,0
1,0,16,0,0,0,0,0,16,14,0,0,0,0,0
1,0,16,0,0,0,0,0,16,0,0,0,0,0,0
1,0,16,0,0,14,0,0,16,0,0,0,0,0,0
1,0,15,16,16,15,16,16,15,0,0,0,0,0,0
1,0,0,0,0,0,0,0,0,0,0,0,0,0,0
1,0,0,0,0,0,0,0,0,0,0,0,0,0,0
1,0,0,0,0,0,0,0,0,0,0,0,0,0,0
endlayer

layer
1,23,22,0,0,0,0,0,21,20,0,0,0,0,0
1,23,24,24,24,24,24,24,24,20,0,0,0,0,0
1,23,24,8,9,8,9,8,24,20,0,0,0,0,0
1,23,24,9,8,9,8,9,24,20,0,0,0,0,0
1,23,24,8,9,8,9,8,24,20,0,0,0,0,0
1,23,24,9,8,9,8,9,24,20,0,0,0,0,0
1,23,24,8,9,8,9,8,24,20,0,0,0,0,0
1,23,24,18,8,9,8,9,24,20,0,0,0,0,0
1,23,24,8,9,8,9,8,24,20,0,0,0,0,0
1,23,24,9,8,9,8,9,24,20,0,0,0,0,0
1,23,24,8,9,8,9,8,24,20,0,0,0,0,0
1,23,24,9,8,9,8,9,24,20,0,0,0,0,0
1,23,24,8,9,8,9,8,24,20,0,0,0,0,0
1,23,24,24,24,24,24,24,24,20,0,0,0,0,0
1,23,22,0,0,0,0,0,21,20,0,0,0,0,0
endlayer

layer
1,0,24,0,0,0,0,0,24,0,0,0,0,0,0
1,0,24,6,6,6,6,6,24,0,0,0,0,0,0
1,0,24,0,0,30,0,0,24,0,0,0,0,0,0
1,0,24,16,15,0,15,16,24,0,0,0,0,0,0
1,0,24,0,0,0,0,0,24,0,0,0,0,0,0
1,0,24,0,0,0,0,0,24,0,0,0,0,0,0
1,0,24,0,0,0,0,0,24,0,0,0,0,0,0
1,0,24,0,0,0,0,0,24,0,0,0,0,0,0
1,0,24,0,0,0,0,0,24,0,0,0,0,0,0
1,0,24,0,0,0,0,0,24,0,0,0,0,0,0
1,0,24,0,0,0,0,0,24,0,0,0,0,0,0
1,0,24,16,15,0,15,16,24,0,0,0,0,0,0
1,0,24,0,0,30,0,0,24,0,0,0,0,0,0
1,0,24,6,6,6,6,6,24,0,0,0,0,0,0
1,0,24,0,0,0,0,0,24,0,0,0,0,0,0
endlayer

layer
1,0,24,0,0,0,0,0,24,0,0,0,0,0,0
1,0,24,14,0,0,0,14,24,0,0,0,0,0,0
1,0,24,0,0,0,0,0,24,0,0,0,0,0,0
1,0,24,16,15,0,15,16,24,0,0,0,0,0,0
1,0,24,0,6,0,6,0,24,0,0,0,0,0,0
1,0,24,0,0,0,0,0,24,0,0,0,0,0,0
1,0,16,0,0,0,0,0,16,0,0,0,0,0,0
1,0,6,0,0,0,0,0,6,0,0,0,0,0,0
1,0,16,0,0,0,0,0,16,0,0,0,0,0,0
1,0,24,0,0,0,0,0,24,0,0,0,0,0,0
1,0,24,0,6,0,6,0,24,0,0,0,0,0,0
1,0,24,16,15,0,15,16,24,0,0,0,0,0,0
1,0,24,0,0,0,0,0,24,0,0,0,0,0,0
1,0,24,14,0,0,0,14,24,0,0,0,0,0,0
1,0,24,0,0,0,0,0,24,0,0,0,0,0,0
endlayer

layer
1,0,24,0,0,0,0,0,24,0,0,0,0,0,0
1,0,24,0,0,0,0,0,24,0,0,0,0,0,0
1,0,24,0,0,0,0,0,24,0,0,0,0,0,0
1,0,24,16,15,16,15,16,24,0,0,0,0,0,0
1,0,24,0,14,0,14,0,24,0,0,0,0,0,0
1,25,24,0,0,0,0,0,24,25,0,0,0,0,0
1,26,16,0,0,0,0,0,16,26,0,0,0,0,0
1,0,16,0,0,0,0,0,16,0,0,0,0,0,0
1,27,16,0,0,0,0,0,16,27,0,0,0,0,0
1,28,24,0,0,0,0,0,24,28,0,0,0,0,0
1,0,24,0,14,0,14,0,24,0,0,0,0,0,0
1,0,24,16,15,16,15,16,24,0,0,0,0,0,0
1,0,24,0,0,0,0,0,24,0,0,0,0,0,0
1,0,24,0,0,0,0,0,24,0,0,0,0,0,0
1,0,24,0,0,0,0,0,24,0,0,0,0,0,0
endlayer

layer
1,0,23,22,6,6,6,21,20,0,0,0,0,0,0
1,0,23,22,0,0,0,21,20,0,0,0,0,0,0
1,0,23,22,0,0,0,21,20,0,0,0,0,0,0
1,0,23,15,15,16,15,15,20,0,0,0,0,0,0
1,0,23,22,0,0,0,21,20,0,0,0,0,0,0
1,0,23,22,0,0,0,21,20,0,0,0,0,0,0
1,25,25,22,0,0,0,21,25,25,0,0,0,0,0
1,24,24,22,0,0,0,21,24,24,0,0,0,0,0
1,28,28,22,0,0,0,21,28,28,0,0,0,0,0
1,0,23,22,0,0,0,21,20,0,0,0,0,0,0
1,0,23,22,0,0,0,21,20,0,0,0,0,0,0
1,0,23,15,15,16,15,15,20,0,0,0,0,0,0
1,0,23,22,0,0,0,21,20,0,0,0,0,0,0
1,0,23,22,0,0,0,21,20,0,0,0,0,0,0
1,0,23,22,6,6,6,21,20,0,0,0,0,0,0
endlayer

layer
1,0,0,24,24,24,24,24,0,0,0,0,0,0,0
1,0,0,24,24,24,24,24,0,0,0,0,0,0,0
1,0,0,24,24,24,24,24,0,0,0,0,0,0,0
1,0,0,24,24,24,24,24,0,0,0,0,0,0,0
1,0,0,24,24,24,24,24,0,0,0,0,0,0,0
1,0,0,24,24,24,24,24,0,0,0,0,0,0,0
1,0,0,24,24,24,24,24,0,0,0,0,0,0,0
1,23,24,24,24,24,24,24,24,20,0,0,0,0,0
1,0,0,24,24,24,24,24,0,0,0,0,0,0,0
1,0,0,24,24,24,24,24,0,0,0,0,0,0,0
1,0,0,24,24,24,24,24,0,0,0,0,0,0,0
1,0,0,24,24,24,24,24,0,0,0,0,0,0,0
1,0,0,24,24,24,24,24,0,0,0,0,0,0,0
1,0,0,24,24,24,24,24,0,0,0,0,0,0,0
1,0,0,24,24,24,24,24,0,0,0,0,0,0,0
endlayer

layer
1,0,0,29,29,24,29,29,0,0,0,0,0,0,0
1,0,0,29,29,24,29,29,0,0,0,0,0,0,0
1,0,0,29,29,24,29,29,0,0,0,0,0,0,0
1,0,0,29,29,24,29,29,0,0,0,0,0,0,0
1,0,0,29,29,24,29,29,0,0,0,0,0,0,0
1,0,0,29,29,24,29,29,0,0,0,0,0,0,0
1,0,0,29,29,24,29,29,0,0,0,0,0,0,0
1,0,23,24,24,24,24,24,20,0,0,0,0,0,0
1,0,0,29,29,24,29,29,0,0,0,0,0,0,0
1,0,0,29,29,24,29,29,0,0,0,0,0,0,0
1,0,0,29,29,24,29,29,0,0,0,0,0,0,0
1,0,0,29,29,24,29,29,0,0,0,0,0,0,0
1,0,0,29,29,24,29,29,0,0,0,0,0,0,0
1,0,0,29,29,24,29,29,0,0,0,0,0,0,0
1,0,0,29,29,24,29,29,0,0,0,0,0,0,0
endlayer

layer
1,0,0,0,0,24,0,0,0,0,0,0,0,0,0
1,0,0,0,0,28,0,0,0,0,0,0,0,0,0
1,0,0,0,0,29,0,0,0,0,0,0,0,0,0
1,0,0,0,0,29,0,0,0,0,0,0,0,0,0
1,0,0,0,0,29,0,0,0,0,0,0,0,0,0
1,0,0,0,0,29,0,0,0,0,0,0,0,0,0
1,0,0,0,0,25,0,0,0,0,0,0,0,0,0
1,0,0,29,23,24,20,29,0,0,0,0,0,0,0
1,0,0,0,0,28,0,0,0,0,0,0,0,0,0
1,0,0,0,0,29,0,0,0,0,0,0,0,0,0
1,0,0,0,0,29,0,0,0,0,0,0,0,0,0
1,0,0,0,0,29,0,0,0,0,0,0,0,0,0
1,0,0,0,0,29,0,0,0,0,0,0,0,0,0
1,0,0,0,0,25,0,0,0,0,0,0,0,0,0
1,0,0,0,0,24,0,0,0,0,0,0,0,0,0
endlayer

layer
1,0,0,0,0,29,0,0,0,0,0,0,0,0,0
1,0,0,0,0,0,0,0,0,0,0,0,0,0,0
1,0,0,0,0,0,0,0,0,0,0,0,0,0,0
1,0,0,0,0,0,0,0,0,0,0,0,0,0,0
1,0,0,0,0,0,0,0,0,0,0,0,0,0,0
1,0,0,0,0,0,0,0,0,0,0,0,0,0,0
1,0,0,0,0,0,0,0,0,0,0,0,0,0,0
1,0,0,0,0,24,0,0,0,0,0,0,0,0,0
1,0,0,0,0,0,0,0,0,0,0,0,0,0,0
1,0,0,0,0,0,0,0,0,0,0,0,0,0,0
1,0,0,0,0,0,0,0,0,0,0,0,0,0,0
1,0,0,0,0,0,0,0,0,0,0,0,0,0,0
1,0,0,0,0,0,0,0,0,0,0,0,0,0,0
1,0,0,0,0,0,0,0,0,0,0,0,0,0,0
1,0,0,0,0,29,0,0,0,0,0,0,0,0,0
endlayer

layer
1,0,0,0,0,0,0,0,0,0,0,0,0,0,0
1,0,0,0,0,0,0,0,0,0,0,0,0,0,0
1,0,0,0,0,0,0,0,0,0,0,0,0,0,0
1,0,0,0,0,0,0,0,0,0,0,0,0,0,0
1,0,0,0,0,0,0,0,0,0,0,0,0,0,0
1,0,0,0,0,0,0,0,0,0,0,0,0,0,0
1,0,0,0,0,6,0,0,0,0,0,0,0,0,0
1,0,0,0,6,6,6,0,0,0,0,0,0,0,0
1,0,0,0,0,6,0,0,0,0,0,0,0,0,0
1,0,0,0,0,0,0,0,0,0,0,0,0,0,0
1,0,0,0,0,0,0,0,0,0,0,0,0,0,0
1,0,0,0,0,0,0,0,0,0,0,0,0,0,0
1,0,0,0,0,0,0,0,0,0,0,0,0,0,0
1,0,0,0,0,0,0,0,0,0,0,0,0,0,0
1,0,0,0,0,0,0,0,0,0,0,0,0,0,0
endlayer

