# Nether Limbo Dungeon -- Hall #2: Nether Wart
# Created by Ruins mod version 15.1 Ingame Parser
# authoring Player: Jordan_Greywolf
# Note: Place in \templateparser folder.
# Last Updated 19 Feb 2016

weight=1
embed_into_distance=7
acceptable_target_blocks=
unacceptable_target_blocks=flowing_water,water,flowing_lava,lava
dimensions=7,9,13
allowable_overhang=0
max_leveling=2
leveling_buffer=0
preserve_water=0
preserve_lava=0

rule1=0,100,preserveBlock
rule2=0,100,minecraft:nether_brick-0
rule3=0,100,minecraft:nether_brick_stairs-4
rule4=0,100,minecraft:nether_brick_stairs-5
rule5=0,100,minecraft:nether_brick_stairs-7
rule6=0,100,minecraft:nether_brick_stairs-6
rule7=0,100,minecraft:soul_sand-0
rule8=0,100,minecraft:double_stone_slab-0
rule9=0,100,minecraft:stone_slab-0
rule10=0,100,minecraft:nether_wart-7
rule11=0,100,minecraft:fence_gate-1
rule12=0,100,minecraft:nether_brick_fence-0

rule13=0,100,CommandBlock:RUINSTRIGGER /summon Zombie ~0 ~0 ~0 {Equipment:[{Count:1,id:261,tag:{ench:[{id:50,lvl:3},{id:48,lvl:5}]}},{Count:1,id:305,tag:{ench:[{id:1,lvl:25},{id:7,lvl:2},{id:2,lvl:50}]}},{Count:1,id:304,tag:{ench:[{id:1,lvl:25},{id:7,lvl:2}]}},{Count:1,id:303,tag:{ench:[{id:1,lvl:25},{id:7,lvl:2}]}},{Count:1,id:397,Damage:3}],Attributes:[{Name:generic.maxHealth,Base:40}],DropChances:[0.5F,0.5F,0.5F,0.5F,0.5F],ActiveEffects:[{Id:12,Amplifier:1,Duration:999999,Ambient:1},{Id:3,Amplifier:1,Duration:999999,Ambient:1},{Id:5,Amplifier:1,Duration:999999,Ambient:1}],PersistenceRequired:1}:@

rule14=0,100,minecraft:fence_gate-3
rule15=0,100,minecraft:stained_glass-14
rule16=0,100,minecraft:glowstone-0
rule17=0,100,minecraft:stone_slab-6

layer
1,1,1,1,1,1,1,1,1,1,1,1,1
1,2,2,2,2,2,2,2,2,2,2,2,1
1,2,2,2,2,2,2,2,2,2,2,2,1
3,2,2,2,2,2,2,2,2,2,2,2,3
2,2,2,2,2,2,2,2,2,2,2,2,2
4,2,2,2,2,2,2,2,2,2,2,2,4
1,2,2,2,2,2,2,2,2,2,2,2,1
1,2,2,2,2,2,2,2,2,2,2,2,1
1,1,1,1,1,1,1,1,1,1,1,1,1
endlayer

layer
2,6,3,3,3,3,3,3,3,3,3,5,2
4,7,7,7,7,7,7,7,7,7,7,7,4
3,2,2,2,2,2,2,2,2,2,2,2,3
8,9,9,9,9,9,9,9,9,9,9,9,8
9,9,9,9,9,9,9,9,9,9,9,9,9
8,9,9,9,9,9,9,9,9,9,9,9,8
4,2,2,2,2,2,2,2,2,2,2,2,4
3,7,7,7,7,7,7,7,7,7,7,7,3
2,6,4,4,4,4,4,4,4,4,4,5,2
endlayer

layer
2,2,2,2,2,2,2,2,2,2,2,2,2
2,10,10,10,10,10,10,10,10,10,10,10,2
2,11,12,12,12,12,12,12,12,12,12,11,2
12,0,0,0,0,0,0,0,0,0,0,0,12
0,0,0,0,0,0,0,13,0,0,0,0,0
12,0,0,0,0,0,0,0,0,0,0,0,12
2,11,12,12,12,12,12,12,12,12,12,14,2
2,10,10,10,10,10,10,10,10,10,10,10,2
2,2,2,2,2,2,2,2,2,2,2,2,2
endlayer

layer
2,2,2,2,2,2,2,2,2,2,2,2,2
2,0,0,0,0,0,0,0,0,0,0,0,2
2,0,12,0,12,0,12,0,12,0,12,0,2
12,0,0,0,0,0,0,0,0,0,0,0,12
0,0,0,0,0,0,0,0,0,0,0,0,0
12,0,0,0,0,0,0,0,0,0,0,0,12
2,0,12,0,12,0,12,0,12,0,12,0,2
2,0,0,0,0,0,0,0,0,0,0,0,2
2,2,2,2,2,2,2,2,2,2,2,2,2
endlayer

layer
2,2,2,2,2,2,2,2,2,2,2,2,2
2,0,12,0,12,0,12,0,12,0,12,0,2
2,12,12,12,12,12,12,12,12,12,12,12,2
4,0,0,0,0,0,0,0,0,0,0,0,4
0,0,0,0,0,0,0,0,0,0,0,0,0
3,0,0,0,0,0,0,0,0,0,0,0,3
2,12,12,12,12,12,12,12,12,12,12,12,2
2,0,12,0,12,0,12,0,12,0,12,0,2
2,2,2,2,2,2,2,2,2,2,2,2,2
endlayer

layer
2,2,2,2,2,2,2,2,2,2,2,2,2
2,15,2,15,2,15,2,15,2,15,2,15,2
2,2,2,2,2,2,2,2,2,2,2,2,2
2,15,2,15,2,15,2,15,2,15,2,15,2
2,2,16,2,16,2,16,2,16,2,16,2,2
2,15,2,15,2,15,2,15,2,15,2,15,2
2,2,2,2,2,2,2,2,2,2,2,2,2
2,15,2,15,2,15,2,15,2,15,2,15,2
2,2,2,2,2,2,2,2,2,2,2,2,2
endlayer

layer
17,17,17,17,17,17,17,17,17,17,17,17,17
17,0,17,0,17,0,17,0,17,0,17,0,17
17,17,17,17,17,17,17,17,17,17,17,17,17
17,0,17,0,17,0,17,0,17,0,17,0,17
17,17,17,17,17,17,17,17,17,17,17,17,17
17,0,17,0,17,0,17,0,17,0,17,0,17
17,17,17,17,17,17,17,17,17,17,17,17,17
17,0,17,0,17,0,17,0,17,0,17,0,17
17,17,17,17,17,17,17,17,17,17,17,17,17
endlayer

