# Tree - Baobab
# MC 1.7.10; 25 Nov 2014
# Created by Ruins mod version 14.4 Ingame Parser
# authoring Player: Jordan_Greywolf
# Special Instructions: Place in \templateparser folder.
# Last Updated: 28 Apr 2015

weight=1
embed_into_distance=13
random_height_offset=-2,2
acceptable_target_blocks=
unacceptable_target_blocks=
dimensions=36,16,16
allowable_overhang=9999
max_leveling=0
leveling_buffer=-1
preserve_water=0
preserve_lava=0
preserve_plants=1

# Baobab Wood (all bark)
rule1=0,100,minecraft:log2-12

# Baobab Leaves (no decay)
rule2=0,100,minecraft:leaves2-4

# Preserve Terrain
rule3=0,100,preserveBlock

layer
3,3,3,3,3,3,3,3,3,3,3,3,3,3,3,3
3,3,3,3,3,3,3,3,3,3,3,3,3,3,3,3
3,3,3,3,3,3,3,3,3,3,3,3,3,3,3,3
3,3,3,3,3,3,3,3,3,3,3,3,3,3,3,3
3,3,3,3,3,3,3,3,3,3,3,3,3,3,3,3
3,3,3,3,3,3,3,3,3,3,3,3,3,3,3,3
3,3,3,3,3,3,3,3,3,3,3,3,3,3,3,3
3,3,3,3,3,3,3,3,3,3,3,3,3,3,3,3
3,3,3,3,3,3,3,3,1,3,3,3,3,3,3,3
3,3,3,3,3,3,3,3,3,3,3,3,3,3,3,3
3,3,3,3,3,3,3,3,3,3,3,3,3,3,3,3
3,3,3,3,3,3,3,3,3,3,3,3,3,3,3,3
3,3,3,3,3,3,3,3,3,3,3,3,3,3,3,3
3,3,3,3,3,3,3,3,3,3,3,3,3,3,3,3
3,3,3,3,3,3,3,3,3,3,3,3,3,3,3,3
3,3,3,3,3,3,3,3,3,3,3,3,3,3,3,3
endlayer

layer
3,3,3,3,3,3,3,3,3,3,3,3,3,3,3,3
3,3,3,3,3,3,3,3,3,3,3,3,3,3,3,3
3,3,3,3,3,3,3,3,3,3,3,3,3,3,3,3
3,3,3,3,3,3,3,3,3,3,3,3,3,3,3,3
3,3,3,3,3,3,3,3,3,3,3,3,3,3,3,3
3,3,3,3,3,3,3,3,3,3,3,3,3,3,3,3
3,3,3,3,3,3,3,3,3,3,3,3,3,3,3,3
3,3,3,3,3,3,3,3,3,3,3,3,3,3,3,3
3,3,3,3,3,3,3,3,1,3,3,3,3,3,3,3
3,3,3,3,3,3,3,3,3,3,3,3,3,3,3,3
3,3,3,3,3,3,3,3,3,3,3,3,3,3,3,3
3,3,3,3,3,3,3,3,3,3,3,3,3,3,3,3
3,3,3,3,3,3,3,3,3,3,3,3,3,3,3,3
3,3,3,3,3,3,3,3,3,3,3,3,3,3,3,3
3,3,3,3,3,3,3,3,3,3,3,3,3,3,3,3
3,3,3,3,3,3,3,3,3,3,3,3,3,3,3,3
endlayer


layer
3,3,3,3,3,3,3,3,3,3,3,3,3,3,3,3
3,3,3,3,3,3,3,3,3,3,3,3,3,3,3,3
3,3,3,3,3,3,3,3,3,3,3,3,3,3,3,3
3,3,3,3,3,3,3,3,3,3,3,3,3,3,3,3
3,3,3,3,3,3,3,3,3,3,3,3,3,3,3,3
3,3,3,3,3,3,3,3,3,3,3,3,3,3,3,3
3,3,3,3,3,3,3,3,3,3,3,3,3,3,3,3
3,3,3,3,3,3,3,3,3,3,3,3,3,3,3,3
3,3,3,3,3,3,3,3,1,3,3,3,3,3,3,3
3,3,3,3,3,3,3,3,3,3,3,3,3,3,3,3
3,3,3,3,3,3,3,3,3,3,3,3,3,3,3,3
3,3,3,3,3,3,3,3,3,3,3,3,3,3,3,3
3,3,3,3,3,3,3,3,3,3,3,3,3,3,3,3
3,3,3,3,3,3,3,3,3,3,3,3,3,3,3,3
3,3,3,3,3,3,3,3,3,3,3,3,3,3,3,3
3,3,3,3,3,3,3,3,3,3,3,3,3,3,3,3
endlayer


layer
3,3,3,3,3,3,3,3,3,3,3,3,3,3,3,3
3,3,3,3,3,3,3,3,3,3,3,3,3,3,3,3
3,3,3,3,3,3,3,3,3,3,3,3,3,3,3,3
3,3,3,3,3,3,3,3,3,3,3,3,3,3,3,3
3,3,3,3,3,3,3,3,3,3,3,3,3,3,3,3
3,3,3,3,3,3,3,3,3,3,3,3,3,3,3,3
3,3,3,3,3,3,3,3,3,3,3,3,3,3,3,3
3,3,3,3,3,3,3,3,3,3,3,3,3,3,3,3
3,3,3,3,3,3,3,3,1,3,3,3,3,3,3,3
3,3,3,3,3,3,3,3,3,3,3,3,3,3,3,3
3,3,3,3,3,3,3,3,3,3,3,3,3,3,3,3
3,3,3,3,3,3,3,3,3,3,3,3,3,3,3,3
3,3,3,3,3,3,3,3,3,3,3,3,3,3,3,3
3,3,3,3,3,3,3,3,3,3,3,3,3,3,3,3
3,3,3,3,3,3,3,3,3,3,3,3,3,3,3,3
3,3,3,3,3,3,3,3,3,3,3,3,3,3,3,3
endlayer


layer
3,3,3,3,3,3,3,3,3,3,3,3,3,3,3,3
3,3,3,3,3,3,3,3,3,3,3,3,3,3,3,3
3,3,3,3,3,3,3,3,3,3,3,3,3,3,3,3
3,3,3,3,3,3,3,3,3,3,3,3,3,3,3,3
3,3,3,3,3,3,3,3,3,3,3,3,3,3,3,3
3,3,3,3,3,3,3,3,3,3,3,3,3,3,3,3
3,3,3,3,3,3,3,3,3,3,3,3,3,3,3,3
3,3,3,3,3,3,3,3,1,3,3,3,3,3,3,3
3,3,3,3,3,3,3,1,1,1,3,3,3,3,3,3
3,3,3,3,3,3,3,3,1,3,3,3,3,3,3,3
3,3,3,3,3,3,3,3,3,3,3,3,3,3,3,3
3,3,3,3,3,3,3,3,3,3,3,3,3,3,3,3
3,3,3,3,3,3,3,3,3,3,3,3,3,3,3,3
3,3,3,3,3,3,3,3,3,3,3,3,3,3,3,3
3,3,3,3,3,3,3,3,3,3,3,3,3,3,3,3
3,3,3,3,3,3,3,3,3,3,3,3,3,3,3,3
endlayer

layer
3,3,3,3,3,3,3,3,3,3,3,3,3,3,3,3
3,3,3,3,3,3,3,3,3,3,3,3,3,3,3,3
3,3,3,3,3,3,3,3,3,3,3,3,3,3,3,3
3,3,3,3,3,3,3,3,3,3,3,3,3,3,3,3
3,3,3,3,3,3,3,3,3,3,3,3,3,3,3,3
3,3,3,3,3,3,3,3,3,3,3,3,3,3,3,3
3,3,3,3,3,3,3,3,3,3,3,3,3,3,3,3
3,3,3,3,3,3,3,3,1,3,3,3,3,3,3,3
3,3,3,3,3,3,3,1,1,1,3,3,3,3,3,3
3,3,3,3,3,3,3,3,1,3,3,3,3,3,3,3
3,3,3,3,3,3,3,3,3,3,3,3,3,3,3,3
3,3,3,3,3,3,3,3,3,3,3,3,3,3,3,3
3,3,3,3,3,3,3,3,3,3,3,3,3,3,3,3
3,3,3,3,3,3,3,3,3,3,3,3,3,3,3,3
3,3,3,3,3,3,3,3,3,3,3,3,3,3,3,3
3,3,3,3,3,3,3,3,3,3,3,3,3,3,3,3
endlayer


layer
3,3,3,3,3,3,3,3,3,3,3,3,3,3,3,3
3,3,3,3,3,3,3,3,3,3,3,3,3,3,3,3
3,3,3,3,3,3,3,3,3,3,3,3,3,3,3,3
3,3,3,3,3,3,3,3,3,3,3,3,3,3,3,3
3,3,3,3,3,3,3,3,3,3,3,3,3,3,3,3
3,3,3,3,3,3,3,3,3,3,3,3,3,3,3,3
3,3,3,3,3,3,3,3,3,3,3,3,3,3,3,3
3,3,3,3,3,3,3,3,1,3,3,3,3,3,3,3
3,3,3,3,3,3,3,1,1,1,3,3,3,3,3,3
3,3,3,3,3,3,3,3,1,3,3,3,3,3,3,3
3,3,3,3,3,3,3,3,3,3,3,3,3,3,3,3
3,3,3,3,3,3,3,3,3,3,3,3,3,3,3,3
3,3,3,3,3,3,3,3,3,3,3,3,3,3,3,3
3,3,3,3,3,3,3,3,3,3,3,3,3,3,3,3
3,3,3,3,3,3,3,3,3,3,3,3,3,3,3,3
3,3,3,3,3,3,3,3,3,3,3,3,3,3,3,3
endlayer


layer
3,3,3,3,3,3,3,3,3,3,3,3,3,3,3,3
3,3,3,3,3,3,3,3,3,3,3,3,3,3,3,3
3,3,3,3,3,3,3,3,3,3,3,3,3,3,3,3
3,3,3,3,3,3,3,3,3,3,3,3,3,3,3,3
3,3,3,3,3,3,3,3,3,3,3,3,3,3,3,3
3,3,3,3,3,3,3,3,3,3,3,3,3,3,3,3
3,3,3,3,3,3,3,3,1,3,3,3,3,3,3,3
3,3,3,3,3,3,3,1,1,1,3,3,3,3,3,3
3,3,3,3,3,3,1,1,1,1,1,3,3,3,3,3
3,3,3,3,3,3,3,1,1,1,3,3,3,3,3,3
3,3,3,3,3,3,3,3,1,3,3,3,3,3,3,3
3,3,3,3,3,3,3,3,3,3,3,3,3,3,3,3
3,3,3,3,3,3,3,3,3,3,3,3,3,3,3,3
3,3,3,3,3,3,3,3,3,3,3,3,3,3,3,3
3,3,3,3,3,3,3,3,3,3,3,3,3,3,3,3
3,3,3,3,3,3,3,3,3,3,3,3,3,3,3,3
endlayer

layer
3,3,3,3,3,3,3,3,3,3,3,3,3,3,3,3
3,3,3,3,3,3,3,3,3,3,3,3,3,3,3,3
3,3,3,3,3,3,3,3,3,3,3,3,3,3,3,3
3,3,3,3,3,3,3,3,3,3,3,3,3,3,3,3
3,3,3,3,3,3,3,3,3,3,3,3,3,3,3,3
3,3,3,3,3,3,3,3,3,3,3,3,3,3,3,3
3,3,3,3,3,3,3,3,1,3,3,3,3,3,3,3
3,3,3,3,3,3,3,1,1,1,3,3,3,3,3,3
3,3,3,3,3,3,1,1,1,1,1,3,3,3,3,3
3,3,3,3,3,3,3,1,1,1,3,3,3,3,3,3
3,3,3,3,3,3,3,3,1,3,3,3,3,3,3,3
3,3,3,3,3,3,3,3,3,3,3,3,3,3,3,3
3,3,3,3,3,3,3,3,3,3,3,3,3,3,3,3
3,3,3,3,3,3,3,3,3,3,3,3,3,3,3,3
3,3,3,3,3,3,3,3,3,3,3,3,3,3,3,3
3,3,3,3,3,3,3,3,3,3,3,3,3,3,3,3
endlayer


layer
3,3,3,3,3,3,3,3,3,3,3,3,3,3,3,3
3,3,3,3,3,3,3,3,3,3,3,3,3,3,3,3
3,3,3,3,3,3,3,3,3,3,3,3,3,3,3,3
3,3,3,3,3,3,3,3,3,3,3,3,3,3,3,3
3,3,3,3,3,3,3,3,3,3,3,3,3,3,3,3
3,3,3,3,3,3,3,3,3,3,3,3,3,3,3,3
3,3,3,3,3,3,3,3,1,3,3,3,3,3,3,3
3,3,3,3,3,3,3,1,1,1,3,3,3,3,3,3
3,3,3,3,3,3,1,1,1,1,1,3,3,3,3,3
3,3,3,3,3,3,3,1,1,1,3,3,3,3,3,3
3,3,3,3,3,3,3,3,1,3,3,3,3,3,3,3
3,3,3,3,3,3,3,3,3,3,3,3,3,3,3,3
3,3,3,3,3,3,3,3,3,3,3,3,3,3,3,3
3,3,3,3,3,3,3,3,3,3,3,3,3,3,3,3
3,3,3,3,3,3,3,3,3,3,3,3,3,3,3,3
3,3,3,3,3,3,3,3,3,3,3,3,3,3,3,3
endlayer


layer
3,3,3,3,3,3,3,3,3,3,3,3,3,3,3,3
3,3,3,3,3,3,3,3,3,3,3,3,3,3,3,3
3,3,3,3,3,3,3,3,3,3,3,3,3,3,3,3
3,3,3,3,3,3,3,3,3,3,3,3,3,3,3,3
3,3,3,3,3,3,3,3,3,3,3,3,3,3,3,3
3,3,3,3,3,3,3,3,1,3,3,3,3,3,3,3
3,3,3,3,3,3,1,1,1,1,1,3,3,3,3,3
3,3,3,3,3,3,1,1,1,1,1,3,3,3,3,3
3,3,3,3,3,1,1,1,1,1,1,1,3,3,3,3
3,3,3,3,3,3,1,1,1,1,1,3,3,3,3,3
3,3,3,3,3,3,1,1,1,1,1,3,3,3,3,3
3,3,3,3,3,3,3,3,1,3,3,3,3,3,3,3
3,3,3,3,3,3,3,3,3,3,3,3,3,3,3,3
3,3,3,3,3,3,3,3,3,3,3,3,3,3,3,3
3,3,3,3,3,3,3,3,3,3,3,3,3,3,3,3
3,3,3,3,3,3,3,3,3,3,3,3,3,3,3,3
endlayer

layer
3,3,3,3,3,3,3,3,3,3,3,3,3,3,3,3
3,3,3,3,3,3,3,3,3,3,3,3,3,3,3,3
3,3,3,3,3,3,3,3,3,3,3,3,3,3,3,3
3,3,3,3,3,3,3,3,3,3,3,3,3,3,3,3
3,3,3,3,3,3,3,3,3,3,3,3,3,3,3,3
3,3,3,3,3,3,1,1,1,1,1,3,3,3,3,3
3,3,3,3,3,1,1,1,1,1,1,1,3,3,3,3
3,3,3,3,3,1,1,1,1,1,1,1,3,3,3,3
3,3,3,3,3,1,1,1,1,1,1,1,3,3,3,3
3,3,3,3,3,1,1,1,1,1,1,1,3,3,3,3
3,3,3,3,3,1,1,1,1,1,1,1,3,3,3,3
3,3,3,3,3,3,1,1,1,1,1,3,3,3,3,3
3,3,3,3,3,3,3,3,3,3,3,3,3,3,3,3
3,3,3,3,3,3,3,3,3,3,3,3,3,3,3,3
3,3,3,3,3,3,3,3,3,3,3,3,3,3,3,3
3,3,3,3,3,3,3,3,3,3,3,3,3,3,3,3
endlayer

layer
3,3,3,3,3,3,3,3,3,3,3,3,3,3,3,3
3,3,3,3,3,3,3,3,3,3,3,3,3,3,3,3
3,3,3,3,3,3,3,3,3,3,3,3,3,3,3,3
3,3,3,3,3,3,3,3,3,3,3,3,3,3,3,3
3,3,3,3,3,3,3,3,3,3,3,3,3,3,3,3
3,3,3,3,3,3,1,1,1,1,1,3,3,3,3,3
3,3,3,3,3,1,1,1,1,1,1,1,3,3,3,3
3,3,3,3,3,1,1,1,1,1,1,1,3,3,3,3
3,3,3,3,3,1,1,1,1,1,1,1,3,3,3,3
3,3,3,3,3,1,1,1,1,1,1,1,3,3,3,3
3,3,3,3,3,1,1,1,1,1,1,1,3,3,3,3
3,3,3,3,3,3,1,1,1,1,1,3,3,3,3,3
3,3,3,3,3,3,3,3,3,3,3,3,3,3,3,3
3,3,3,3,3,3,3,3,3,3,3,3,3,3,3,3
3,3,3,3,3,3,3,3,3,3,3,3,3,3,3,3
3,3,3,3,3,3,3,3,3,3,3,3,3,3,3,3
endlayer

layer
3,3,3,3,3,3,3,3,3,3,3,3,3,3,3,3
3,3,3,3,3,3,3,3,3,3,3,3,3,3,3,3
3,3,3,3,3,3,3,3,3,3,3,3,3,3,3,3
3,3,3,3,3,3,3,3,3,3,3,3,3,3,3,3
3,3,3,3,3,3,3,3,3,3,3,3,3,3,3,3
3,3,3,3,3,3,1,1,1,1,1,3,3,3,3,3
3,3,3,3,3,1,1,1,1,1,1,1,3,3,3,3
3,3,3,3,3,1,1,1,1,1,1,1,3,3,3,3
3,3,3,3,3,1,1,1,1,1,1,1,3,3,3,3
3,3,3,3,3,1,1,1,1,1,1,1,3,3,3,3
3,3,3,3,3,1,1,1,1,1,1,1,3,3,3,3
3,3,3,3,3,3,1,1,1,1,1,3,3,3,3,3
3,3,3,3,3,3,3,3,3,3,3,3,3,3,3,3
3,3,3,3,3,3,3,3,3,3,3,3,3,3,3,3
3,3,3,3,3,3,3,3,3,3,3,3,3,3,3,3
3,3,3,3,3,3,3,3,3,3,3,3,3,3,3,3
endlayer

layer
3,3,3,3,3,3,3,3,3,3,3,3,3,3,3,3
3,3,3,3,3,3,3,3,3,3,3,3,3,3,3,3
3,3,3,3,3,3,3,3,3,3,3,3,3,3,3,3
3,3,3,3,3,3,3,3,3,3,3,3,3,3,3,3
3,3,3,3,3,3,3,3,3,3,3,3,3,3,3,3
3,3,3,3,3,3,1,1,1,1,1,3,3,3,3,3
3,3,3,3,3,1,1,1,1,1,1,1,3,3,3,3
3,3,3,3,3,1,1,1,1,1,1,1,3,3,3,3
3,3,3,3,3,1,1,1,1,1,1,1,3,3,3,3
3,3,3,3,3,1,1,1,1,1,1,1,3,3,3,3
3,3,3,3,3,1,1,1,1,1,1,1,3,3,3,3
3,3,3,3,3,3,1,1,1,1,1,3,3,3,3,3
3,3,3,3,3,3,3,3,3,3,3,3,3,3,3,3
3,3,3,3,3,3,3,3,3,3,3,3,3,3,3,3
3,3,3,3,3,3,3,3,3,3,3,3,3,3,3,3
3,3,3,3,3,3,3,3,3,3,3,3,3,3,3,3
endlayer

layer
3,3,3,3,3,3,3,3,3,3,3,3,3,3,3,3
3,3,3,3,3,3,3,3,3,3,3,3,3,3,3,3
3,3,3,3,3,3,3,3,3,3,3,3,3,3,3,3
3,3,3,3,3,3,3,3,3,3,3,3,3,3,3,3
3,3,3,3,3,3,3,3,3,3,3,3,3,3,3,3
3,3,3,3,3,3,1,1,1,1,1,3,3,3,3,3
3,3,3,3,3,1,1,1,1,1,1,1,3,3,3,3
3,3,3,3,3,1,1,1,1,1,1,1,3,3,3,3
3,3,3,3,3,1,1,1,1,1,1,1,3,3,3,3
3,3,3,3,3,1,1,1,1,1,1,1,3,3,3,3
3,3,3,3,3,1,1,1,1,1,1,1,3,3,3,3
3,3,3,3,3,3,1,1,1,1,1,3,3,3,3,3
3,3,3,3,3,3,3,3,3,3,3,3,3,3,3,3
3,3,3,3,3,3,3,3,3,3,3,3,3,3,3,3
3,3,3,3,3,3,3,3,3,3,3,3,3,3,3,3
3,3,3,3,3,3,3,3,3,3,3,3,3,3,3,3
endlayer

layer
3,3,3,3,3,3,3,3,3,3,3,3,3,3,3,3
3,3,3,3,3,3,3,3,3,3,3,3,3,3,3,3
3,3,3,3,3,3,3,3,3,3,3,3,3,3,3,3
3,3,3,3,3,3,3,3,3,3,3,3,3,3,3,3
3,3,3,3,3,3,3,3,3,3,3,3,3,3,3,3
3,3,3,3,3,3,1,1,1,1,1,3,3,3,3,3
3,3,3,3,3,1,1,1,1,1,1,1,3,3,3,3
3,3,3,3,3,1,1,1,1,1,1,1,3,3,3,3
3,3,3,3,3,1,1,1,1,1,1,1,3,3,3,3
3,3,3,3,3,1,1,1,1,1,1,1,3,3,3,3
3,3,3,3,3,1,1,1,1,1,1,1,3,3,3,3
3,3,3,3,3,3,1,1,1,1,1,3,3,3,3,3
3,3,3,3,3,3,3,3,3,3,3,3,3,3,3,3
3,3,3,3,3,3,3,3,3,3,3,3,3,3,3,3
3,3,3,3,3,3,3,3,3,3,3,3,3,3,3,3
3,3,3,3,3,3,3,3,3,3,3,3,3,3,3,3
endlayer

layer
3,3,3,3,3,3,3,3,3,3,3,3,3,3,3,3
3,3,3,3,3,3,3,3,3,3,3,3,3,3,3,3
3,3,3,3,3,3,3,3,3,3,3,3,3,3,3,3
3,3,3,3,3,3,3,3,3,3,3,3,3,3,3,3
3,3,3,3,3,3,3,3,3,3,3,3,3,3,3,3
3,3,3,3,3,3,1,1,1,1,1,3,3,3,3,3
3,3,3,3,3,1,1,1,1,1,1,1,3,3,3,3
3,3,3,3,3,1,1,1,1,1,1,1,3,3,3,3
3,3,3,3,3,1,1,1,1,1,1,1,3,3,3,3
3,3,3,3,3,1,1,1,1,1,1,1,3,3,3,3
3,3,3,3,3,1,1,1,1,1,1,1,3,3,3,3
3,3,3,3,3,3,1,1,1,1,1,3,3,3,3,3
3,3,3,3,3,3,3,3,3,3,3,3,3,3,3,3
3,3,3,3,3,3,3,3,3,3,3,3,3,3,3,3
3,3,3,3,3,3,3,3,3,3,3,3,3,3,3,3
3,3,3,3,3,3,3,3,3,3,3,3,3,3,3,3
endlayer

layer
3,3,3,3,3,3,3,3,3,3,3,3,3,3,3,3
3,3,3,3,3,3,3,3,3,3,3,3,3,3,3,3
3,3,3,3,3,3,3,3,3,3,3,3,3,3,3,3
3,3,3,3,3,3,3,3,3,3,3,3,3,3,3,3
3,3,3,3,3,3,3,3,3,3,3,3,3,3,3,3
3,3,3,3,3,3,1,1,1,1,1,3,3,3,3,3
3,3,3,3,3,1,1,1,1,1,1,1,3,3,3,3
3,3,3,3,3,1,1,1,1,1,1,1,3,3,3,3
3,3,3,3,3,1,1,1,1,1,1,1,3,3,3,3
3,3,3,3,3,1,1,1,1,1,1,1,3,3,3,3
3,3,3,3,3,1,1,1,1,1,1,1,3,3,3,3
3,3,3,3,3,3,1,1,1,1,1,3,3,3,3,3
3,3,3,3,3,3,3,3,3,3,3,3,3,3,3,3
3,3,3,3,3,3,3,3,3,3,3,3,3,3,3,3
3,3,3,3,3,3,3,3,3,3,3,3,3,3,3,3
3,3,3,3,3,3,3,3,3,3,3,3,3,3,3,3
endlayer

layer
3,3,3,3,3,3,3,3,3,3,3,3,3,3,3,3
3,3,3,3,3,3,3,3,3,3,3,3,3,3,3,3
3,3,3,3,3,3,3,3,3,3,3,3,3,3,3,3
3,3,3,3,3,3,3,3,3,3,3,3,3,3,3,3
3,3,3,3,3,3,3,3,3,3,3,3,3,3,3,3
3,3,3,3,3,3,1,1,1,1,1,3,3,3,3,3
3,3,3,3,3,1,1,1,1,1,1,1,3,3,3,3
3,3,3,3,3,1,1,1,1,1,1,1,3,3,3,3
3,3,3,3,3,1,1,1,1,1,1,1,3,3,3,3
3,3,3,3,3,1,1,1,1,1,1,1,3,3,3,3
3,3,3,3,3,1,1,1,1,1,1,1,3,3,3,3
3,3,3,3,3,3,1,1,1,1,1,3,3,3,3,3
3,3,3,3,3,3,3,3,3,3,3,3,3,3,3,3
3,3,3,3,3,3,3,3,3,3,3,3,3,3,3,3
3,3,3,3,3,3,3,3,3,3,3,3,3,3,3,3
3,3,3,3,3,3,3,3,3,3,3,3,3,3,3,3
endlayer

layer
3,3,3,3,3,3,3,3,3,3,3,3,3,3,3,3
3,3,3,3,3,3,3,3,3,3,3,3,3,3,3,3
3,3,3,3,3,3,3,3,3,3,3,3,3,3,3,3
3,3,3,3,3,3,3,3,3,3,3,3,3,3,3,3
3,3,3,3,3,3,3,3,3,3,3,3,3,3,3,3
3,3,3,3,3,3,1,1,1,1,1,3,3,3,3,3
3,3,3,3,3,1,1,1,1,1,1,1,3,3,3,3
3,3,3,3,3,1,1,1,1,1,1,1,3,3,3,3
3,3,3,3,3,1,1,1,1,1,1,1,3,3,3,3
3,3,3,3,3,1,1,1,1,1,1,1,3,3,3,3
3,3,3,3,3,1,1,1,1,1,1,1,3,3,3,3
3,3,3,3,3,3,1,1,1,1,1,3,3,3,3,3
3,3,3,3,3,3,3,3,3,3,3,3,3,3,3,3
3,3,3,3,3,3,3,3,3,3,3,3,3,3,3,3
3,3,3,3,3,3,3,3,3,3,3,3,3,3,3,3
3,3,3,3,3,3,3,3,3,3,3,3,3,3,3,3
endlayer

layer
3,3,3,3,3,3,3,3,3,3,3,3,3,3,3,3
3,3,3,3,3,3,3,3,3,3,3,3,3,3,3,3
3,3,3,3,3,3,3,3,3,3,3,3,3,3,3,3
3,3,3,3,3,3,3,3,3,3,3,3,3,3,3,3
3,3,3,3,3,3,3,3,3,3,3,3,3,3,3,3
3,3,3,3,3,3,1,1,1,1,1,3,3,3,3,3
3,3,3,3,3,1,1,1,1,1,1,1,3,3,3,3
3,3,3,3,3,1,1,1,1,1,1,1,3,3,3,3
3,3,3,3,3,1,1,1,1,1,1,1,3,3,3,3
3,3,3,3,3,1,1,1,1,1,1,1,3,3,3,3
3,3,3,3,3,1,1,1,1,1,1,1,3,3,3,3
3,3,3,3,3,3,1,1,1,1,1,3,3,3,3,3
3,3,3,3,3,3,3,3,3,3,3,3,3,3,3,3
3,3,3,3,3,3,3,3,3,3,3,3,3,3,3,3
3,3,3,3,3,3,3,3,3,3,3,3,3,3,3,3
3,3,3,3,3,3,3,3,3,3,3,3,3,3,3,3
endlayer

layer
3,3,3,3,3,3,3,3,3,3,3,3,3,3,3,3
3,3,3,3,3,3,3,3,3,3,3,3,3,3,3,3
3,3,3,3,3,3,3,3,3,3,3,3,3,3,3,3
3,3,3,3,3,3,3,3,3,3,3,3,3,3,3,3
3,3,3,3,3,3,3,3,3,3,3,3,3,3,3,3
3,3,3,3,3,3,1,1,1,1,1,3,3,3,3,3
3,3,3,3,3,1,1,1,1,1,1,1,3,3,3,3
3,3,3,3,3,1,1,1,1,1,1,1,3,3,3,3
3,3,3,3,3,1,1,1,1,1,1,1,3,3,3,3
3,3,3,3,3,1,1,1,1,1,1,1,3,3,3,3
3,3,3,3,3,1,1,1,1,1,1,1,3,3,3,3
3,3,3,3,3,3,1,1,1,1,1,3,3,3,3,3
3,3,3,3,3,3,3,3,3,3,3,3,3,3,3,3
3,3,3,3,3,3,3,3,3,3,3,3,3,3,3,3
3,3,3,3,3,3,3,3,3,3,3,3,3,3,3,3
3,3,3,3,3,3,3,3,3,3,3,3,3,3,3,3
endlayer

layer
3,3,3,3,3,3,3,3,3,3,3,3,3,3,3,3
3,3,3,3,3,3,3,3,3,3,3,3,3,3,3,3
3,3,3,3,3,3,3,3,3,3,3,3,3,3,3,3
3,3,3,3,3,3,3,3,3,3,3,3,3,3,3,3
3,3,3,3,3,3,3,3,3,3,3,3,3,3,3,3
3,3,3,3,3,3,1,1,1,1,1,3,3,3,3,3
3,3,3,3,3,1,1,1,1,1,1,1,3,3,3,3
3,3,3,3,3,1,1,1,1,1,1,1,3,3,3,3
3,3,3,3,3,1,1,1,1,1,1,1,3,3,3,3
3,3,3,3,3,1,1,1,1,1,1,1,3,3,3,3
3,3,3,3,3,1,1,1,1,1,1,1,3,3,3,3
3,3,3,3,3,3,1,1,1,1,1,3,3,3,3,3
3,3,3,3,3,3,3,3,3,3,3,3,3,3,3,3
3,3,3,3,3,3,3,3,3,3,3,3,3,3,3,3
3,3,3,3,3,3,3,3,3,3,3,3,3,3,3,3
3,3,3,3,3,3,3,3,3,3,3,3,3,3,3,3
endlayer

layer
3,3,3,3,3,3,3,3,3,3,3,3,3,3,3,3
3,3,3,3,3,3,3,3,3,3,3,3,3,3,3,3
3,3,3,3,3,3,3,3,3,3,3,3,3,3,3,3
3,3,3,3,3,3,3,3,3,3,3,3,3,3,3,3
3,3,3,3,3,3,3,3,3,3,3,3,3,3,3,3
3,3,3,3,3,3,3,1,1,1,3,3,3,3,3,3
3,3,3,3,3,3,1,1,1,1,1,3,3,3,3,3
3,3,3,3,3,1,1,1,1,1,1,1,3,3,3,3
3,3,3,3,3,1,1,1,1,1,1,1,3,3,3,3
3,3,3,3,3,1,1,1,1,1,1,1,3,3,3,3
3,3,3,3,3,3,1,1,1,1,1,3,3,3,3,3
3,3,3,3,3,3,3,1,1,1,3,3,3,3,3,3
3,3,3,3,3,3,3,3,3,3,3,3,3,3,3,3
3,3,3,3,3,3,3,3,3,3,3,3,3,3,3,3
3,3,3,3,3,3,3,3,3,3,3,3,3,3,3,3
3,3,3,3,3,3,3,3,3,3,3,3,3,3,3,3
endlayer

layer
3,3,3,3,3,3,3,3,3,3,3,3,3,3,3,3
3,3,3,3,3,3,3,3,3,3,3,3,3,3,3,3
3,3,3,3,3,3,3,3,3,3,3,3,3,3,3,3
3,3,3,3,3,3,3,3,3,3,3,3,3,3,3,3
3,3,3,3,3,3,3,3,3,3,3,3,3,3,3,3
3,3,3,3,3,3,3,1,1,1,3,3,3,3,3,3
3,3,3,3,3,3,1,1,1,1,1,3,3,3,3,3
3,3,3,3,3,1,1,1,1,1,1,1,3,3,3,3
3,3,3,3,3,1,1,1,1,1,1,1,3,3,3,3
3,3,3,3,3,1,1,1,1,1,1,1,3,3,3,3
3,3,3,3,3,3,1,1,1,1,1,3,3,3,3,3
3,3,3,3,3,3,3,1,1,1,3,3,3,3,3,3
3,3,3,3,3,3,3,3,3,3,3,3,3,3,3,3
3,3,3,3,3,3,3,3,3,3,3,3,3,3,3,3
3,3,3,3,3,3,3,3,3,3,3,3,3,3,3,3
3,3,3,3,3,3,3,3,3,3,3,3,3,3,3,3
endlayer

layer
3,3,3,3,3,3,3,3,3,3,3,3,3,3,3,3
3,3,3,3,3,3,3,3,3,3,3,3,3,3,3,3
3,3,3,3,3,3,3,3,3,3,3,3,3,3,3,3
3,3,3,3,3,3,3,3,3,3,3,3,3,3,3,3
3,3,3,3,3,3,3,3,3,3,3,3,3,3,3,3
3,3,3,3,3,3,3,1,1,1,3,3,3,3,3,3
3,3,3,3,3,3,1,1,1,1,1,3,3,3,3,3
3,3,3,3,3,1,1,1,1,1,1,1,3,3,3,3
3,3,3,3,3,1,1,1,1,1,1,1,3,3,3,3
3,3,3,3,3,1,1,1,1,1,1,1,3,3,3,3
3,3,3,3,3,3,1,1,1,1,1,3,3,3,3,3
3,3,3,3,3,3,3,1,1,1,3,3,3,3,3,3
3,3,3,3,3,3,3,3,3,3,3,3,3,3,3,3
3,3,3,3,3,3,3,3,3,3,3,3,3,3,3,3
3,3,3,3,3,3,3,3,3,3,3,3,3,3,3,3
3,3,3,3,3,3,3,3,3,3,3,3,3,3,3,3
endlayer

layer
3,3,3,3,3,3,3,3,3,3,3,3,3,3,3,3
3,3,3,3,3,3,3,3,3,3,3,3,3,3,3,3
3,3,3,3,3,3,3,3,3,3,3,3,3,3,3,3
3,3,3,3,3,3,3,3,3,3,3,3,3,3,3,3
3,3,3,3,3,3,3,3,3,3,3,3,3,3,3,3
3,3,3,3,3,3,3,3,1,3,3,3,3,3,3,3
3,3,3,3,3,3,3,1,1,1,3,3,3,3,3,3
3,3,3,3,3,3,1,1,1,1,1,3,3,3,3,3
3,3,3,3,3,1,1,1,1,1,1,1,3,3,3,3
3,3,3,3,3,3,1,1,1,1,1,3,3,3,3,3
3,3,3,3,3,3,3,1,1,1,3,3,3,3,3,3
3,3,3,3,3,3,3,3,1,3,3,3,3,3,3,3
3,3,3,3,3,3,3,3,3,3,3,3,3,3,3,3
3,3,3,3,3,3,3,3,3,3,3,3,3,3,3,3
3,3,3,3,3,3,3,3,3,3,3,3,3,3,3,3
3,3,3,3,3,3,3,3,3,3,3,3,3,3,3,3
endlayer

layer
3,3,3,3,3,3,3,3,3,3,3,3,3,3,3,3
3,3,3,3,3,3,3,3,3,3,3,3,3,3,3,3
3,3,3,3,3,3,3,3,3,3,3,3,3,3,3,3
3,3,3,3,3,3,3,3,3,3,3,3,3,3,3,3
3,3,3,3,3,3,3,3,3,3,3,3,3,3,3,3
3,3,3,3,3,3,3,3,1,3,3,3,3,3,3,3
3,3,3,3,3,3,3,1,1,1,3,3,3,3,3,3
3,3,3,3,3,3,1,1,1,1,1,3,3,3,3,3
3,3,3,3,3,1,1,1,1,1,1,1,3,3,3,3
3,3,3,3,3,3,1,1,1,1,1,3,3,3,3,3
3,3,3,3,3,3,3,1,1,1,3,3,3,3,3,3
3,3,3,3,3,3,3,3,1,3,3,3,3,3,3,3
3,3,3,3,3,3,3,3,3,3,3,3,3,3,3,3
3,3,3,3,3,3,3,3,3,3,3,3,3,3,3,3
3,3,3,3,3,3,3,3,3,3,3,3,3,3,3,3
3,3,3,3,3,3,3,3,3,3,3,3,3,3,3,3
endlayer

layer
3,3,3,3,3,3,3,3,3,3,3,3,3,3,3,3
3,3,3,3,3,3,3,3,3,3,3,3,3,3,3,3
3,3,3,3,3,3,3,3,3,3,3,3,3,3,3,3
3,3,3,3,3,3,3,3,3,3,3,3,3,3,3,3
3,3,3,3,3,3,3,3,3,3,3,3,3,3,3,3
3,3,3,3,3,3,3,3,3,3,3,3,3,3,3,3
3,3,3,3,3,3,3,1,1,1,3,3,3,3,3,3
3,3,3,3,3,3,1,1,1,1,1,3,3,3,3,3
3,3,3,3,3,3,1,1,1,1,1,3,3,3,3,3
3,3,3,3,3,3,1,1,1,1,1,3,3,3,3,3
3,3,3,3,3,3,3,1,1,1,3,3,3,3,3,3
3,3,3,3,3,3,3,3,3,3,3,3,3,3,3,3
3,3,3,3,3,3,3,3,3,3,3,3,3,3,3,3
3,3,3,3,3,3,3,3,3,3,3,3,3,3,3,3
3,3,3,3,3,3,3,3,3,3,3,3,3,3,3,3
3,3,3,3,3,3,3,3,3,3,3,3,3,3,3,3
endlayer

layer
3,3,3,3,3,3,3,3,3,3,3,3,3,3,3,3
3,3,3,3,3,3,3,3,3,3,3,3,3,3,3,3
3,3,3,3,3,3,3,3,3,3,3,3,3,3,3,3
3,3,3,3,3,3,3,3,3,3,3,3,3,3,3,3
3,3,3,3,3,3,3,3,3,3,3,3,3,3,3,3
3,3,3,3,3,3,3,3,3,3,3,3,3,3,3,3
3,3,3,3,3,3,3,3,1,3,3,3,3,3,3,3
3,3,3,3,3,3,3,1,1,1,3,3,3,3,3,3
3,3,3,3,3,3,1,1,1,1,1,3,3,3,3,3
3,3,3,3,3,3,3,1,1,1,3,3,3,3,3,3
3,3,3,3,3,3,3,3,1,3,3,3,3,3,3,3
3,3,3,3,3,3,3,3,3,3,3,3,3,3,3,3
3,3,3,3,3,3,3,3,3,3,3,3,3,3,3,3
3,3,3,3,3,3,3,3,3,3,3,3,3,3,3,3
3,3,3,3,3,3,3,3,3,3,3,3,3,3,3,3
3,3,3,3,3,3,3,3,3,3,3,3,3,3,3,3
endlayer

layer
3,3,3,3,3,3,3,3,3,3,3,3,3,3,3,3
3,3,3,3,3,3,3,3,3,3,3,3,3,3,3,3
3,3,3,3,3,3,3,3,3,3,3,3,3,3,3,3
3,3,3,3,3,3,3,3,3,3,3,3,3,3,3,3
3,3,3,3,3,3,3,3,3,3,3,3,3,3,3,3
3,3,3,3,3,3,3,3,3,3,3,3,3,3,3,3
3,3,3,3,3,3,3,3,1,3,3,3,3,3,3,3
3,3,3,3,3,3,3,1,1,1,3,3,3,3,3,3
3,3,3,3,3,1,1,1,1,1,3,3,3,3,3,3
3,3,3,3,3,3,3,1,1,1,3,3,3,3,3,3
3,3,3,3,3,3,3,3,3,3,3,3,3,3,3,3
3,3,3,3,3,3,3,3,3,3,3,3,3,3,3,3
3,3,3,3,3,3,3,3,3,3,3,3,3,3,3,3
3,3,3,3,3,3,3,3,3,3,3,3,3,3,3,3
3,3,3,3,3,3,3,3,3,3,3,3,3,3,3,3
3,3,3,3,3,3,3,3,3,3,3,3,3,3,3,3
endlayer

layer
3,3,3,3,3,3,3,3,3,3,3,3,3,3,3,3
3,3,3,3,3,1,3,3,3,3,1,3,3,3,3,3
3,3,3,3,3,3,1,3,3,1,3,3,3,3,3,3
3,3,3,3,3,3,3,1,3,1,3,3,3,3,3,3
3,3,3,3,3,3,3,1,1,3,3,3,3,3,1,3
3,3,3,3,3,3,3,3,1,3,3,3,1,1,3,3
3,1,3,3,3,3,3,3,1,3,3,1,1,3,3,3
3,3,1,1,1,3,3,3,3,1,1,1,3,3,3,3
3,3,3,3,1,1,3,3,1,3,3,3,1,1,1,1
3,3,3,3,3,3,3,1,3,1,1,3,3,3,3,3
3,3,3,3,3,3,1,1,3,1,1,1,3,3,3,3
3,3,3,1,1,1,1,3,3,1,3,1,1,3,3,3
3,3,1,3,3,1,3,3,1,3,3,3,3,1,3,3
3,3,3,3,3,1,3,3,1,3,3,3,3,3,1,3
3,3,3,3,1,3,3,3,1,3,3,3,3,3,3,3
3,3,3,3,3,3,3,3,1,3,3,3,3,3,3,3
endlayer

layer
3,3,3,3,2,2,2,3,3,2,2,2,3,3,3,3
3,3,3,2,2,2,2,2,3,2,2,2,3,3,3,3
3,3,3,3,2,2,2,1,3,2,2,2,3,3,2,3
3,3,3,3,3,2,3,1,3,3,3,3,3,2,2,2
3,2,3,3,3,3,3,3,3,3,3,3,2,2,2,2
2,2,2,3,3,3,3,3,3,3,3,3,1,2,2,2
2,2,2,2,3,3,3,3,3,3,3,3,3,3,2,3
2,2,2,1,3,3,3,1,3,3,3,3,3,3,2,2
3,2,3,3,3,3,3,3,1,1,3,3,3,3,2,2
3,3,3,3,3,3,3,3,3,3,3,3,3,3,2,2
3,3,3,3,3,3,3,3,3,3,3,3,3,3,3,3
3,2,2,2,3,3,3,3,3,3,3,3,1,3,3,3
3,2,2,2,3,1,3,3,3,3,3,3,3,2,2,2
3,2,2,2,2,2,3,3,2,3,3,3,3,2,2,2
3,3,2,2,2,2,3,2,2,2,3,3,3,2,2,2
3,3,3,2,2,2,2,2,2,2,2,3,3,3,3,3
endlayer

layer
3,3,3,3,3,3,3,2,3,3,3,3,3,3,3,3
3,3,3,3,3,3,2,2,2,3,3,3,3,3,3,3
3,3,3,3,3,2,2,2,2,2,3,3,3,3,3,3
3,3,3,3,3,3,2,2,2,3,3,3,2,3,3,3
3,3,3,3,3,3,3,2,3,3,3,2,2,2,3,3
3,3,3,2,3,3,3,3,3,3,2,2,2,2,2,3
3,3,2,2,2,3,3,3,3,3,3,2,2,2,3,3
3,2,2,2,2,2,3,1,3,3,3,3,2,3,3,3
3,3,2,2,2,3,3,3,3,1,3,3,3,3,3,3
3,3,3,2,3,3,3,1,3,3,3,3,2,3,3,3
3,3,3,3,3,2,3,3,3,3,3,2,2,2,3,3
3,3,3,3,2,2,2,3,3,3,2,2,2,2,2,3
3,3,3,2,2,2,2,2,3,3,3,2,2,2,3,3
3,3,3,3,2,2,2,3,3,3,3,3,2,3,3,3
3,3,3,3,3,2,3,3,3,3,3,3,3,3,3,3
3,3,3,3,3,3,3,3,3,3,3,3,3,3,3,3
endlayer

layer
3,3,3,3,3,3,3,3,3,3,3,3,3,3,3,3
3,3,3,3,3,3,3,3,3,3,3,3,3,3,3,3
3,3,3,3,3,3,3,3,3,3,3,3,3,3,3,3
3,3,3,3,3,3,3,3,3,3,3,3,3,3,3,3
3,3,3,3,3,3,3,3,3,3,3,3,3,3,3,3
3,3,3,3,3,3,3,3,3,3,3,3,3,3,3,3
3,3,3,3,3,3,2,2,2,2,3,3,3,3,3,3
3,3,3,3,3,3,2,2,2,2,2,3,3,3,3,3
3,3,3,3,3,3,2,2,2,2,2,3,3,3,3,3
3,3,3,3,3,3,2,2,2,2,2,3,3,3,3,3
3,3,3,3,3,3,2,2,2,2,2,3,3,3,3,3
3,3,3,3,3,3,3,2,2,2,3,3,3,3,3,3
3,3,3,3,3,3,3,3,3,3,3,3,3,3,3,3
3,3,3,3,3,3,3,3,3,3,3,3,3,3,3,3
3,3,3,3,3,3,3,3,3,3,3,3,3,3,3,3
3,3,3,3,3,3,3,3,3,3,3,3,3,3,3,3
endlayer


