# Savanna Statue
# 17 Oct 2014, updated 15 Dec 2014 -- MC 1.7.10
# Created by Ruins mod version 13.8 Ingame Parser
# authoring Player: Jordan_Greywolf
# Updated for MC 1.8: 23 Jul 2015

biomesToSpawnIn=savanna,savanna m,savanna plateau,savanna plateau m

weight=1
embed_into_distance=2
acceptable_target_blocks=

unacceptable_target_blocks=flowing_water,water,flowing_lava,lava,cloud,Natura:Cloud,slime_congealed,slime_dirt,slime_grass,command_block

dimensions=17,3,7
allowable_overhang=0
max_leveling=2
leveling_buffer=-1
preserve_water=0
preserve_lava=0
preserve_plants=1

rule1=0,100,minecraft:stained_hardened_clay-11
rule2=0,100,minecraft:stained_hardened_clay-1
rule3=0,100,minecraft:stained_hardened_clay-15
rule4=0,100,minecraft:redstone_torch-5
rule5=0,100,preserveBlock

layer
5,5,1,5,1,5,5
5,5,1,5,1,5,5
5,5,5,5,5,5,5
endlayer

layer
5,5,1,5,1,5,5
5,5,1,5,1,5,5
5,5,5,5,5,5,5
endlayer


layer
5,5,1,5,1,5,5
5,5,1,5,1,5,5
5,5,5,5,5,5,5
endlayer

layer
5,5,1,2,1,5,5
5,5,5,2,5,5,5
5,5,5,5,5,5,5
endlayer

layer
5,5,1,3,1,5,5
5,5,5,3,5,5,5
5,5,5,5,5,5,5
endlayer

layer
5,1,5,1,5,1,5
5,3,5,1,5,3,5
5,1,5,5,5,1,5
endlayer

layer
5,5,1,1,1,5,5
5,5,1,3,1,5,5
5,4,5,5,5,4,5
endlayer

layer
5,5,5,3,5,5,5
5,5,5,1,5,5,5
5,5,5,5,5,5,5
endlayer

layer
5,5,5,1,5,5,5
5,5,2,5,2,5,5
5,5,5,5,5,5,5
endlayer

layer
5,5,1,3,1,5,5
5,1,2,1,2,1,5
5,5,5,3,5,5,5
endlayer

layer
5,5,1,1,1,5,5
5,1,2,1,2,1,5
5,5,5,3,5,5,5
endlayer

layer
5,5,1,1,1,5,5
5,1,4,1,4,1,5
5,5,5,3,5,5,5
endlayer

layer
5,5,1,1,1,5,5
5,2,1,1,1,2,5
5,5,1,3,1,5,5
endlayer

layer
5,5,5,1,5,5,5
5,1,2,1,2,1,5
5,5,5,1,5,5,5
endlayer

layer
5,5,5,1,5,5,5
1,3,3,1,3,3,1
5,5,5,1,5,5,5
endlayer

layer
5,5,5,5,5,5,5
1,2,3,1,3,2,1
5,5,5,5,5,5,5
endlayer

layer
5,5,5,5,5,5,5
5,5,2,1,2,5,5
5,5,5,5,5,5,5
endlayer


