
# Watchtower (ruined) (27 Mar 2014; MC 1.5.*)
# authoring Player: Jordan_Greywolf
# Updated to MC 1.7.10, 11 Oct 2014
# Last Updated: 22 Nov 2015

biomesToSpawnIn=alps,alps forest,autumn hills,autumn woods,cold taiga,cold taiga hills,cold taiga m,extreme hills,extreme hills edge,forest,foresthills,frost forest,highland,highlands,ice plains,ice wasteland,grove,jungle,lavender fields,magical forest,meadow,mega spruce taiga,mega taiga,mega tiaga hills,mountain,mountain ridge,ominous woods,orchard,pasture,plains,prairie,rainforest,savanna,scrubland,shrubland,snow forest,snowy forest,snowy coniferousforest,snowy dead forest,snowy rainforest,taiga,taiga m,taigahills,temperate rainforest,wonderous woods,woodland,woodlands,dead forest,dead swamp,badlands,sludgepit,wasteland,rwg_coldforest,rwg_snowforest,rwg_temperateforest


weight=1
embed_into_distance=7

unacceptable_target_blocks=lava,lava_flowing,water,water_flowing,cloud,Natura:Cloud,red_mushroom_block,brown_mushroom_block

dimensions=23,7,7
allowable_overhang=0
max_cut_in=0
cut_in_buffer=0
max_leveling=3
leveling_buffer=-1
preserve_water=0
preserve_lava=0
preserve_plants=1

#Terrain Blending
rule1=0,100,preserveBlock

#Stone Brick Base (randomized: regular, mossy, cracked)
rule2=0,100,minecraft:stonebrick-0,minecraft:stonebrick-1,minecraft:stonebrick-2

#Cobblestone Floor (randomized: regular, mossy)
rule3=0,100,minecraft:cobblestone,minecraft:mossy_cobblestone

#Spruce Plank Flooring
rule4=2,100,minecraft:planks-1

#Underground Cobblestone (randomized: mostly mossy)
rule5=0,100,minecraft:cobblestone,minecraft:mossy_cobblestone,minecraft:mossy_cobblestone,minecraft:gravel

#Wooden Fence/Trim
rule6=2,75,minecraft:fence

#Cobblestone Wall
rule7=2,50,minecraft:cobblestone_wall-1,minecraft:cobblestone_wall-0

#Iron Bars
rule8=1,75,minecraft:iron_bars

#Ladder - North Wall
rule9=2,50,minecraft:ladder-2

#Spruce Stairs - Ascend N
rule10=2,75,minecraft:spruce_stairs-3

#Spruce Stairs - Ascend S
rule11=2,75,minecraft:spruce_stairs-2

#Spruce Stairs - Ascend E
rule12=2,75,minecraft:spruce_stairs-0

#Spruce Stairs - Ascend W
rule13=2,75,minecraft:spruce_stairs-1

#Torch - Standing
rule14=1,50,minecraft:redstone_torch-5

#Gate
rule15=1,50,minecraft:fence_gate-3

#Pressure Plate 
rule16=1,75,minecraft:stone_pressure_plate

#Chiseled Stone
rule17=2,75,minecraft:stonebrick-3

#Double Stone Slab
rule18=2,75,minecraft:double_stone_slab

#Wood Fence/Needle
rule19=1,75,minecraft:fence

#Trap
rule20=0,100,minecraft:tnt,MobSpawner:Creeper


# Foundation (-7)
layer
1,1,1,1,1,1,1
1,1,2,2,2,1,1
1,2,5,5,5,2,1
1,2,5,5,5,2,1
1,2,5,5,5,2,1
1,1,2,2,2,1,1
1,1,1,1,1,1,1
endlayer

# Foundation (-6)
layer
1,1,1,1,1,1,1
1,1,2,2,2,1,1
1,2,5,5,5,2,1
1,2,5,5,5,2,1
1,2,5,5,5,2,1
1,1,2,2,2,1,1
1,1,1,1,1,1,1
endlayer

# Foundation (-5)
layer
1,1,1,1,1,1,1
1,1,2,2,2,1,1
1,2,5,5,5,2,1
1,2,5,5,5,2,1
1,2,5,5,5,2,1
1,1,2,2,2,1,1
1,1,1,1,1,1,1
endlayer

# Foundation (-4)
layer
1,1,1,1,1,1,1
1,1,2,2,2,1,1
1,2,5,5,5,2,1
1,2,5,5,5,2,1
1,2,5,5,5,2,1
1,1,2,2,2,1,1
1,1,1,1,1,1,1
endlayer

# Foundation (-3)
layer
1,1,1,1,1,1,1
1,1,2,2,2,1,1
1,2,5,5,5,2,1
1,2,5,5,5,2,1
1,2,5,5,5,2,1
1,1,2,2,2,1,1
1,1,1,1,1,1,1
endlayer

# Foundation (-2)
layer
1,1,1,1,1,1,1
1,1,2,2,2,1,1
1,2,5,5,5,2,1
1,2,5,5,5,2,1
1,2,5,20,5,2,1
1,1,2,2,2,1,1
1,1,1,1,1,1,1
endlayer

# Ground Base (-1)
layer
1,1,1,1,1,1,1
1,1,2,2,2,1,1
1,2,3,3,3,2,1
1,2,3,3,3,2,1
1,2,3,3,3,2,1
1,1,2,3,2,1,1
1,1,1,1,1,1,1
endlayer

# Floor 1: Gate & Torch Stands (+1)
layer
1,1,1,1,1,1,1
1,7,2,2,2,7,1
1,2,9,1,1,2,1
1,2,1,1,1,2,1
1,2,1,16,1,2,1
1,7,2,15,2,7,1
1,1,1,1,1,1,1
endlayer

# Floor 1: Torches, Windows (+2)
layer
1,1,1,1,1,1,1
1,14,2,8,2,14,1
1,2,9,1,1,2,1
1,8,1,1,1,8,1
1,2,1,1,1,2,1
1,14,2,1,2,14,1
1,1,1,1,1,1,1
endlayer

# Floor 1: Upper Window & Door Cap (+3)
layer
1,1,1,1,1,1,1
1,1,2,8,2,1,1
1,2,9,1,1,2,1
1,8,1,1,1,8,1
1,2,1,1,1,2,1
1,1,2,17,2,1,1
1,1,1,1,1,1,1
endlayer

# Floor 2: Spruce Flooring & Trim (+4)
layer
1,1,6,6,6,1,1
1,6,2,2,2,6,1
6,2,9,4,4,2,6
6,2,4,18,4,2,6
6,2,4,4,4,2,6
1,6,2,2,2,6,1
1,1,6,6,6,1,1
endlayer

# Floor 2: Upper Torches, Windows (+5)
layer
1,1,1,1,1,1,1
1,14,2,8,2,14,1
1,2,1,1,1,2,1
1,8,1,1,1,8,1
1,2,1,1,1,2,1
1,14,2,8,2,14,1
1,1,1,1,1,1,1
endlayer

# Floor 2: Windows (+6)
layer
1,1,1,1,1,1,1
1,1,2,8,2,1,1
1,2,1,1,1,2,1
1,8,1,1,1,8,1
1,2,1,1,1,2,1
1,1,2,8,2,1,1
1,1,1,1,1,1,1
endlayer

# Floor 2: Windows (+7)
layer
1,1,1,1,1,1,1
1,1,2,8,2,1,1
1,2,1,1,1,2,1
1,8,1,1,1,8,1
1,2,1,1,1,2,1
1,1,2,8,2,1,1
1,1,1,1,1,1,1
endlayer

# Rooftop: Fringe (+8)
layer
1,12,12,12,12,12,1
10,4,2,2,2,4,11
10,2,1,1,1,2,11
10,2,1,1,1,2,11
10,2,1,1,1,2,11
10,4,2,2,2,4,11
1,13,13,13,13,13,1
endlayer

# Rooftop: Base (+9)
layer
1,1,1,1,1,1,1
1,6,4,4,4,6,1
1,4,4,6,4,4,1
1,4,6,6,6,4,1
1,4,4,6,4,4,1
1,6,4,4,4,6,1
1,1,1,1,1,1,1
endlayer

# Rooftop: Cone (+10)
layer
1,1,1,1,1,1,1
1,1,12,12,12,1,1
1,10,4,4,4,11,1
1,10,4,6,4,11,1
1,10,4,4,4,11,1
1,1,13,13,13,1,1
1,1,1,1,1,1,1
endlayer

# Rooftop: Cone (+11)
layer
1,1,1,1,1,1,1
1,1,1,1,1,1,1
1,1,6,4,6,1,1
1,1,4,6,4,1,1
1,1,6,4,6,1,1
1,1,1,1,1,1,1
1,1,1,1,1,1,1
endlayer

# Rooftop: Cone (+12)
layer
1,1,1,1,1,1,1
1,1,1,1,1,1,1
1,1,1,12,1,1,1
1,1,10,4,11,1,1
1,1,1,13,1,1,1
1,1,1,1,1,1,1
1,1,1,1,1,1,1
endlayer

# Rooftop: Cone (+13)
layer
1,1,1,1,1,1,1
1,1,1,1,1,1,1
1,1,1,1,1,1,1
1,1,1,4,1,1,1
1,1,1,1,1,1,1
1,1,1,1,1,1,1
1,1,1,1,1,1,1
endlayer

# Rooftop: Spire (+14)
layer
1,1,1,1,1,1,1
1,1,1,1,1,1,1
1,1,1,1,1,1,1
1,1,1,19,1,1,1
1,1,1,1,1,1,1
1,1,1,1,1,1,1
1,1,1,1,1,1,1
endlayer

# Rooftop: Spire (+15)
layer
1,1,1,1,1,1,1
1,1,1,1,1,1,1
1,1,1,1,1,1,1
1,1,1,19,1,1,1
1,1,1,1,1,1,1
1,1,1,1,1,1,1
1,1,1,1,1,1,1
endlayer

# Rooftop: Spire (+16)
layer
1,1,1,1,1,1,1
1,1,1,1,1,1,1
1,1,1,1,1,1,1
1,1,1,14,1,1,1
1,1,1,1,1,1,1
1,1,1,1,1,1,1
1,1,1,1,1,1,1
endlayer




