# Cobblestone Mansion 10/20/2014
# Created by Ruins mod version 13.8 Ingame Parser
# authoring Player: Kujaku10
# Last Upated 9 Nov 2015

biomesToSpawnIn=plains,sunflower plains

weight=1
embed_into_distance=4
acceptable_target_blocks=

unacceptable_target_blocks=flowing_water,water,flowing_lava,lava,cloud,Natura:Cloud,slime_congealed,slime_dirt,slime_grass

dimensions=19,13,15
allowable_overhang=0
max_leveling=3
leveling_buffer=-1
preserve_water=0
preserve_lava=0
preserve_plants=1

rule1=0,100,preserveBlock
rule2=0,100,minecraft:dirt-0
rule3=0,100,minecraft:double_plant-1
rule4=1,100,minecraft:leaves-14
rule5=0,100,minecraft:cobblestone-0
rule6=0,100,minecraft:quartz_block-0
rule7=0,100,minecraft:quartz_block-2
rule8=0,100,minecraft:quartz_block-4
rule9=0,100,minecraft:quartz_block-3
rule10=0,100,minecraft:double_plant-4
rule11=0,100,minecraft:stone_stairs-1
rule12=0,100,minecraft:double_plant-9
rule13=0,100,minecraft:double_plant-8
rule14=0,100,minecraft:double_stone_slab-0
rule15=0,100,minecraft:glass_pane-0
rule16=0,100,minecraft:quartz_stairs-2
rule17=0,100,minecraft:lit_furnace-5
rule18=0,100,minecraft:jukebox-0
rule19=0,100,minecraft:crafting_table-0
rule20=0,100,ChestGenHook:bonusChest:1-5
rule21=0,100,minecraft:flower_pot-1
rule22=0,100,minecraft:carpet-1
rule23=0,100,minecraft:carpet-4
rule24=0,100,minecraft:carpet-5
rule25=0,100,minecraft:birch_stairs-2
rule26=0,100,minecraft:flower_pot-2
rule27=0,100,minecraft:carpet-10
rule28=0,100,minecraft:carpet-11
rule29=0,100,minecraft:carpet-14
rule30=0,100,minecraft:birch_stairs-0
rule31=1,100,minecraft:wooden_door-2
rule32=0,100,minecraft:double_plant-11
rule33=0,100,minecraft:flower_pot-4
rule34=1,100,minecraft:wooden_door-8
rule35=0,100,minecraft:spruce_stairs-2
rule36=0,100,minecraft:spruce_stairs-3
rule37=2,100,minecraft:torch-3
rule38=2,100,minecraft:torch-4
rule39=0,100,minecraft:stonebrick-0
rule40=0,100,minecraft:spruce_stairs-0
rule41=0,100,minecraft:spruce_stairs-1
rule42=0,100,minecraft:wooden_slab-1
rule43=0,100,minecraft:quartz_block-1
rule44=0,100,minecraft:bed-3
rule45=0,100,minecraft:bed-11
rule46=0,100,minecraft:oak_stairs-4
rule47=0,100,minecraft:stone_brick_stairs-4
rule48=0,100,minecraft:stone_brick_stairs-6
rule49=0,100,minecraft:stone_brick_stairs-7
rule50=0,100,minecraft:oak_stairs-6
rule51=0,100,minecraft:oak_stairs-7
rule52=0,100,minecraft:oak_stairs-5
rule53=0,100,minecraft:stone_brick_stairs-5
rule54=0,100,minecraft:planks-0
rule55=0,100,minecraft:oak_stairs-1
rule56=0,100,minecraft:oak_stairs-3
rule57=0,100,minecraft:oak_stairs-2
rule58=0,100,minecraft:oak_stairs-0
rule59=0,100,minecraft:glass-0

rule60=0,100,CommandBlock:RUINSTRIGGER /summon Skeleton ~0 ~1 ~0 {CustomName:Bandit,Equipment:[{Count:1,id:261,tag:{display:{Name:Bandit Bow},ench:[{id:21,lvl:5},{id:48,lvl:2},{id:49,lvl:3}]}},{Count:1,id:301},{Count:1,id:300},{Count:1,id:299},{Count:1,id:397,Damage:3}],Attributes:[{Name:generic.maxHealth,Base:15}],DropChances:[1.0F,0.5F,0.5F,0.5F,0.5F],PersistenceRequired:1}:@

layer
1,1,1,1,1,1,1,1,1,1,1,1,1,1,1
1,1,1,1,1,1,1,1,1,1,1,1,1,1,1
1,1,2,2,2,2,2,2,2,2,2,2,2,1,1
1,1,2,2,2,2,2,2,2,2,2,2,2,1,1
1,1,2,2,2,2,2,2,2,2,2,2,2,1,1
1,1,2,2,2,2,2,2,2,2,2,2,2,1,1
1,1,2,2,2,2,2,2,2,2,2,2,2,1,1
1,1,2,2,2,2,2,2,2,2,2,2,2,1,1
1,1,2,2,2,2,2,2,2,2,2,2,2,1,1
1,1,2,2,2,2,2,2,2,2,2,2,2,1,1
1,1,1,1,1,1,1,1,1,2,2,2,1,1,1
1,1,1,1,1,1,1,1,1,2,1,2,1,1,1
1,1,1,1,1,1,1,1,1,1,1,1,1,1,1
endlayer

layer
1,1,1,1,1,1,1,1,1,1,1,1,1,1,1
1,1,1,1,1,1,1,1,1,1,1,1,1,1,1
1,1,2,2,2,2,2,2,2,2,2,2,2,1,1
1,1,2,2,2,2,2,2,2,2,2,2,2,1,1
1,1,2,2,2,2,2,2,2,2,2,2,2,1,1
1,1,2,2,2,2,2,2,2,2,2,2,2,1,1
1,1,2,2,2,2,2,2,2,2,2,2,2,1,1
1,1,2,2,2,2,2,2,2,2,2,2,2,1,1
1,1,2,2,2,2,2,2,2,2,2,2,2,1,1
1,1,2,2,2,2,2,2,2,2,2,2,2,1,1
1,1,1,1,1,1,1,1,1,2,2,2,1,1,1
1,1,1,1,1,1,1,1,1,2,1,2,1,1,1
1,1,1,1,1,1,1,1,1,1,1,1,1,1,1
endlayer

layer
1,1,1,1,1,1,1,1,1,1,1,1,1,1,1
1,1,1,1,1,1,1,1,1,1,1,1,1,1,1
1,1,2,2,2,2,2,2,2,2,2,2,2,1,1
1,1,2,2,2,2,2,2,2,2,2,2,2,1,1
1,1,2,2,2,2,2,2,2,2,2,2,2,1,1
1,1,2,2,2,2,2,2,2,2,2,2,2,1,1
1,1,2,2,2,2,2,2,2,2,2,2,2,1,1
1,1,2,2,2,2,2,2,2,2,2,2,2,1,1
1,1,2,2,2,2,2,2,2,2,2,2,2,1,1
1,1,2,2,2,2,2,2,2,2,2,2,2,1,1
1,1,1,1,1,1,1,1,1,2,2,2,1,1,1
1,1,1,1,1,1,1,1,1,2,1,2,1,1,1
1,1,1,1,1,1,1,1,1,1,1,1,1,1,1
endlayer

layer
1,1,1,1,1,1,1,1,1,1,1,1,1,1,1
1,1,1,1,1,1,1,1,1,1,1,1,1,1,1
1,1,2,2,2,2,2,2,2,2,2,2,2,1,1
1,1,2,2,2,2,2,2,2,2,2,2,2,1,1
1,1,2,2,2,2,2,2,2,2,2,2,2,1,1
1,1,2,2,2,2,2,2,2,2,2,2,2,1,1
1,1,2,2,2,2,2,2,2,2,2,2,2,1,1
1,1,2,2,2,2,2,2,2,2,2,2,2,1,1
1,1,2,2,2,2,2,2,2,2,2,2,2,1,1
1,1,2,2,2,2,2,2,2,2,2,2,2,1,1
1,1,1,1,1,1,1,1,1,2,2,2,1,1,1
1,1,1,1,1,1,1,1,1,2,1,2,1,1,1
1,1,1,1,1,1,1,1,1,1,1,1,1,1,1
endlayer


layer
1,1,1,1,1,1,1,1,1,1,1,1,1,1,1
1,1,3,1,4,4,4,4,4,4,4,1,3,1,1
1,1,5,5,5,5,5,5,5,5,5,5,5,1,1
1,1,5,6,6,6,6,6,6,6,6,6,5,1,1
1,4,5,6,7,8,8,8,8,8,7,6,5,4,1
1,4,5,6,9,6,6,6,6,6,9,6,5,4,1
1,4,5,6,9,6,6,6,6,6,9,6,5,4,1
1,4,5,6,7,8,8,8,8,8,7,6,5,4,1
1,1,5,6,6,6,6,6,6,6,6,6,5,1,1
1,1,5,5,5,5,5,5,5,5,5,5,5,1,1
1,1,3,1,4,4,4,4,10,5,5,5,10,1,1
1,1,1,1,1,1,1,1,1,5,11,5,1,1,1
1,1,1,1,1,1,1,1,1,1,1,1,1,1,1
endlayer


layer
0,0,0,0,0,0,0,0,0,0,0,0,0,0,0
0,0,13,0,0,0,0,0,0,0,0,0,12,0,0
0,0,14,5,5,5,5,14,15,15,14,5,14,0,0
0,0,5,20,19,18,17,16,0,0,0,0,5,0,0
0,0,14,0,0,0,0,0,0,0,0,0,14,0,0
0,0,15,25,0,60,24,23,22,0,0,21,15,0,0
0,0,15,25,0,0,29,28,27,0,0,26,15,0,0
0,0,14,0,0,0,0,0,0,0,0,0,14,0,0
0,0,5,0,30,30,30,30,0,0,0,0,5,0,0
0,0,14,5,14,15,15,14,5,5,31,5,14,0,0
0,0,32,0,0,0,0,0,32,5,0,5,32,0,0
0,0,0,0,0,0,0,0,0,0,0,0,0,0,0
0,0,0,0,0,0,0,0,0,0,0,0,0,0,0
endlayer

layer
0,0,0,0,0,0,0,0,0,0,0,0,0,0,0
0,0,0,0,0,0,0,0,0,0,0,0,0,0,0
0,0,14,5,5,5,5,14,15,15,14,5,14,0,0
0,0,5,20,33,0,16,0,0,0,0,0,5,0,0
0,0,14,0,0,0,0,0,0,0,0,0,14,0,0
0,0,15,0,0,0,0,0,0,0,0,0,15,0,0
0,0,15,0,0,0,0,0,0,0,0,0,15,0,0
0,0,14,0,0,0,0,0,0,0,0,0,14,0,0
0,0,5,0,0,0,0,0,0,0,0,0,5,0,0
0,0,14,5,14,15,15,14,5,5,34,5,14,0,0
0,0,0,0,0,0,0,0,36,5,0,5,35,0,0
0,0,0,0,0,0,0,0,36,0,0,0,35,0,0
0,0,0,0,0,0,0,0,0,0,0,0,0,0,0
endlayer

layer
0,0,0,0,0,0,0,0,0,0,0,0,0,0,0
0,0,0,0,0,0,0,0,0,0,0,0,0,0,0
0,0,14,5,5,5,5,14,15,15,14,5,14,0,0
0,0,5,20,0,16,0,0,0,0,0,0,5,0,0
0,0,14,38,0,0,0,0,0,0,0,37,14,0,0
0,0,15,0,0,0,0,0,0,0,0,0,15,0,0
0,0,15,0,0,0,0,0,0,0,0,0,15,0,0
0,0,14,38,0,0,0,0,0,0,0,37,14,0,0
0,0,5,0,0,0,0,0,0,0,0,0,5,0,0
0,0,14,5,14,15,15,14,5,14,39,14,14,0,0
0,0,0,0,0,0,0,0,0,36,5,35,0,0,0
0,0,0,0,0,0,0,0,0,36,0,35,0,0,0
0,0,0,0,0,0,0,0,0,0,0,0,0,0,0
endlayer

layer
0,0,0,0,0,0,36,40,40,40,40,40,40,40,0
0,0,0,0,0,0,36,39,39,39,39,39,39,35,0
0,0,14,5,5,5,5,14,39,39,14,5,14,0,0
0,0,5,0,16,0,0,0,0,0,0,0,5,0,0
0,0,14,0,0,0,0,0,0,0,0,0,14,0,0
0,0,15,0,0,0,0,0,0,0,0,0,15,0,0
0,0,15,0,0,0,0,0,0,0,0,0,15,0,0
0,0,14,0,0,0,0,0,0,0,0,0,14,0,0
0,0,5,0,0,0,0,0,0,0,0,0,5,0,0
0,0,14,5,14,39,39,14,5,5,5,5,14,0,0
0,36,39,39,39,39,39,39,35,0,41,0,0,0,0
0,36,41,41,41,41,41,41,35,0,42,0,0,0,0
0,0,0,0,0,0,0,0,0,0,0,0,0,0,0
endlayer

layer
0,0,0,0,0,0,0,0,0,0,0,0,0,0,0
0,0,0,0,0,0,0,36,40,40,40,40,35,0,0
0,0,39,39,39,39,39,39,39,39,39,39,39,0,0
0,0,39,16,0,0,0,6,6,6,6,6,39,0,0
0,0,39,6,43,6,43,6,43,6,43,6,39,0,0
0,0,39,6,6,6,6,6,6,6,6,6,39,0,0
0,0,39,6,6,6,6,6,6,6,6,6,39,0,0
0,0,39,6,43,6,43,6,43,6,43,6,39,0,0
0,0,39,6,6,6,6,6,6,6,6,6,39,0,0
0,0,39,39,39,39,39,39,39,39,39,39,39,0,0
0,0,36,41,41,41,41,35,0,0,0,0,0,0,0
0,0,0,0,0,0,0,0,0,0,0,0,0,0,0
0,0,0,0,0,0,0,0,0,0,0,0,0,0,0
endlayer

layer
0,0,0,0,0,0,0,0,0,0,0,0,0,0,0
0,0,0,0,0,0,0,0,0,0,0,0,0,0,0
0,0,14,5,5,5,14,15,14,5,5,5,14,0,0
0,0,5,0,0,0,0,0,0,0,0,0,5,0,0
0,0,14,0,0,0,0,0,0,0,0,0,14,0,0
0,0,15,0,0,0,60,0,0,0,0,0,15,0,0
0,0,15,0,0,0,0,0,0,0,0,0,15,0,0
0,0,14,0,0,44,0,0,0,44,0,0,14,0,0
0,0,5,0,40,45,40,0,40,45,40,0,5,0,0
0,0,14,5,5,14,5,15,5,14,5,5,14,0,0
0,0,0,0,0,0,0,0,0,0,0,0,0,0,0
0,0,0,0,0,0,0,0,0,0,0,0,0,0,0
0,0,0,0,0,0,0,0,0,0,0,0,0,0,0
endlayer

layer
0,0,0,0,0,0,0,0,0,0,0,0,0,0,0
0,0,0,0,0,0,0,0,0,0,0,0,0,0,0
0,0,14,5,5,5,14,15,14,5,5,5,14,0,0
0,0,5,0,0,0,0,0,0,0,0,0,5,0,0
0,0,14,0,0,0,0,0,0,0,0,0,14,0,0
0,0,15,0,0,0,0,0,0,0,0,0,15,0,0
0,0,15,0,0,0,0,0,0,0,0,0,15,0,0
0,0,14,0,0,0,0,0,0,0,0,0,14,0,0
0,0,5,0,0,0,0,0,0,0,0,0,5,0,0
0,0,14,5,5,14,5,15,5,14,5,5,14,0,0
0,0,0,0,0,0,0,0,0,0,0,0,0,0,0
0,0,0,0,0,0,0,0,0,0,0,0,0,0,0
0,0,0,0,0,0,0,0,0,0,0,0,0,0,0
endlayer

layer
0,0,0,0,0,0,0,0,0,0,0,0,0,0,0
0,46,47,47,47,46,47,47,47,46,47,47,47,46,0
0,49,39,39,39,39,14,39,14,39,39,39,39,48,0
0,49,39,0,0,0,0,0,0,0,0,0,39,48,0
0,51,14,38,0,0,0,0,0,0,0,37,14,50,0
0,49,39,0,0,0,0,0,0,0,0,0,39,48,0
0,49,39,0,0,0,0,0,0,0,0,0,39,48,0
0,51,14,38,0,0,0,0,0,0,0,37,14,50,0
0,49,39,0,0,0,0,0,0,0,0,0,39,48,0
0,49,39,39,39,14,39,39,39,14,39,39,39,48,0
0,51,53,53,53,52,53,53,53,52,53,53,53,52,0
0,0,0,0,0,0,0,0,0,0,0,0,0,0,0
0,0,0,0,0,0,0,0,0,0,0,0,0,0,0
endlayer

layer
0,0,0,0,0,0,0,0,0,0,0,0,0,0,0
0,54,6,6,6,54,6,6,6,54,6,6,6,54,0
0,6,0,0,0,55,0,0,0,55,0,0,0,6,0
0,6,0,0,0,0,0,0,0,0,0,0,0,6,0
0,54,57,0,0,0,0,0,0,0,0,0,56,54,0
0,6,0,0,0,0,0,0,0,0,0,0,0,6,0
0,6,0,0,0,0,0,0,0,0,0,0,0,6,0
0,54,57,0,0,0,0,0,0,0,0,0,56,54,0
0,6,0,0,0,0,0,0,0,0,0,0,0,6,0
0,6,0,0,0,58,0,0,0,58,0,0,0,6,0
0,54,6,6,6,54,6,6,6,54,6,6,6,54,0
0,0,0,0,0,0,0,0,0,0,0,0,0,0,0
0,0,0,0,0,0,0,0,0,0,0,0,0,0,0
endlayer

layer
0,0,0,0,0,0,0,0,0,0,0,0,0,0,0
0,54,6,6,6,54,6,6,6,54,6,6,6,54,0
0,6,0,0,0,0,0,0,0,0,0,0,0,6,0
0,6,0,0,0,0,0,0,0,0,0,0,0,6,0
0,54,0,0,0,0,0,0,0,0,0,0,0,54,0
0,6,0,0,0,0,0,0,0,0,0,0,0,6,0
0,6,0,0,0,0,0,0,0,0,0,0,0,6,0
0,54,0,0,0,0,0,0,0,0,0,0,0,54,0
0,6,0,0,0,0,0,0,0,0,0,0,0,6,0
0,6,0,0,0,0,0,0,0,0,0,0,0,6,0
0,54,6,6,6,54,6,6,6,54,6,6,6,54,0
0,0,0,0,0,0,0,0,0,0,0,0,0,0,0
0,0,0,0,0,0,0,0,0,0,0,0,0,0,0
endlayer

layer
36,40,40,40,40,40,40,40,40,40,40,40,40,40,40
36,54,54,6,54,54,54,6,54,54,54,6,54,54,35
36,54,0,0,51,52,50,0,51,52,50,0,0,54,35
36,54,46,0,0,0,0,0,0,0,0,0,46,54,35
36,54,50,0,0,0,0,0,0,0,0,0,51,54,35
36,54,52,0,0,0,0,0,0,0,0,0,52,54,35
36,54,46,0,0,0,0,0,0,0,0,0,46,54,35
36,54,50,0,0,0,0,0,0,0,0,0,51,54,35
36,54,52,0,0,0,0,0,0,0,0,0,52,54,35
36,54,0,0,51,46,50,0,51,46,50,0,0,54,35
36,54,54,6,54,54,54,6,54,54,54,6,54,54,35
36,41,41,41,41,41,41,41,41,41,41,41,41,41,35
0,0,0,0,0,0,0,0,0,0,0,0,0,0,0
endlayer

layer
0,0,0,0,0,0,0,0,0,0,0,0,0,0,0
0,40,40,40,40,40,40,40,40,40,40,40,40,40,0
0,36,54,54,54,54,54,54,54,54,54,54,54,35,0
0,36,54,0,0,0,0,0,0,0,0,0,54,35,0
0,36,54,0,0,0,0,0,0,0,0,0,54,35,0
0,36,54,0,0,0,0,0,0,0,0,0,54,35,0
0,36,54,0,0,0,0,0,0,0,0,0,54,35,0
0,36,54,0,0,0,0,0,0,0,0,0,54,35,0
0,36,54,0,0,0,0,0,0,0,0,0,54,35,0
0,36,54,54,54,54,54,54,54,54,54,54,54,35,0
0,41,41,41,41,41,41,41,41,41,41,41,41,41,0
0,0,0,0,0,0,0,0,0,0,0,0,0,0,0
0,0,0,0,0,0,0,0,0,0,0,0,0,0,0
endlayer

layer
0,0,0,0,0,0,0,0,0,0,0,0,0,0,0
0,0,0,0,0,0,0,0,0,0,0,0,0,0,0
0,0,36,40,40,40,40,40,40,40,40,40,40,0,0
0,0,36,54,54,54,54,54,54,54,54,54,35,0,0
0,0,36,54,54,54,54,54,54,54,54,54,35,0,0
0,0,36,54,54,59,59,59,59,59,54,54,35,0,0
0,0,36,54,54,59,59,59,59,59,54,54,35,0,0
0,0,36,54,54,54,54,54,54,54,54,54,35,0,0
0,0,36,54,54,54,54,54,54,54,54,54,35,0,0
0,0,41,41,41,41,41,41,41,41,41,41,35,0,0
0,0,0,0,0,0,0,0,0,0,0,0,0,0,0
0,0,0,0,0,0,0,0,0,0,0,0,0,0,0
0,0,0,0,0,0,0,0,0,0,0,0,0,0,0
endlayer

layer
0,0,0,0,0,0,0,0,0,0,0,0,0,0,0
0,0,0,0,0,0,0,0,0,0,0,0,0,0,0
0,0,0,0,0,0,0,0,0,0,0,0,0,0,0
0,0,0,42,42,42,42,42,42,42,42,42,0,0,0
0,0,0,42,42,42,42,42,42,42,42,42,0,0,0
0,0,0,42,42,0,0,0,0,0,42,42,0,0,0
0,0,0,42,42,0,0,0,0,0,42,42,0,0,0
0,0,0,42,42,42,42,42,42,42,42,42,0,0,0
0,0,0,42,42,42,42,42,42,42,42,42,0,0,0
0,0,0,0,0,0,0,0,0,0,0,0,0,0,0
0,0,0,0,0,0,0,0,0,0,0,0,0,0,0
0,0,0,0,0,0,0,0,0,0,0,0,0,0,0
0,0,0,0,0,0,0,0,0,0,0,0,0,0,0
endlayer

