# Large Inn 10/19/2014
# Created by Ruins mod version 13.8 Ingame Parser
# authoring Player: Kujaku10
# Last Updated 7 Feb 2016

biomesToSpawnIn=plains,sunflower plains

weight=1
embed_into_distance=5
acceptable_target_blocks=

unacceptable_target_blocks=flowing_water,water,flowing_lava,lava,cloud,Natura:Cloud,slime_congealed,slime_dirt,slime_grass

dimensions=23,15,20
allowable_overhang=0
max_leveling=2
leveling_buffer=-1
preserve_water=0
preserve_lava=0
preserve_plants=1

rule1=0,100,preserveBlock
rule2=0,100,minecraft:grass-0
rule3=0,100,minecraft:netherrack-0
rule4=1,100,minecraft:leaves-6
rule5=0,100,minecraft:double_plant-4
rule6=0,100,minecraft:stonebrick-0
rule7=0,100,minecraft:double_plant-1
rule8=0,100,minecraft:brick_stairs-3
rule9=0,100,minecraft:brick_stairs-1
rule10=0,100,minecraft:brick_stairs-2
rule11=0,100,minecraft:fire-15
rule12=0,100,minecraft:brick_stairs-0
rule13=0,100,minecraft:stone_brick_stairs-2
rule14=0,100,minecraft:stone_brick_stairs-1
rule15=0,100,minecraft:stone_brick_stairs-3
rule16=0,100,minecraft:double_plant-8
rule17=0,100,minecraft:double_plant-10
rule18=0,100,minecraft:planks-1
rule19=0,100,minecraft:quartz_block-0
rule20=0,100,minecraft:planks-5
rule21=0,100,minecraft:spruce_stairs-3
rule22=0,100,minecraft:wooden_slab-13
rule23=0,100,minecraft:spruce_stairs-2
rule24=0,100,minecraft:spruce_stairs-3
rule25=1,100,minecraft:wooden_door-2
rule26=0,100,minecraft:double_plant-9
rule27=0,100,minecraft:double_plant-11
rule28=0,100,minecraft:glass_pane-0
rule29=2,100,minecraft:torch-1
rule30=2,100,minecraft:torch-3
rule31=0,100,minecraft:flower_pot-7
rule32=0,100,minecraft:spruce_stairs-0
rule33=1,100,minecraft:wooden_door-8
rule34=2,100,minecraft:torch-2
rule35=0,100,minecraft:spruce_stairs-2
rule36=0,100,minecraft:wooden_slab-9
rule37=0,100,minecraft:birch_stairs-0
rule38=0,100,minecraft:iron_bars-0
rule39=0,100,minecraft:spruce_stairs-1
rule40=0,100,minecraft:birch_stairs-1
rule41=0,100,minecraft:spruce_stairs-4
rule42=0,100,minecraft:spruce_stairs-6
rule43=0,100,minecraft:spruce_stairs-7
rule44=0,100,minecraft:spruce_stairs-5
rule45=0,100,minecraft:stone_brick_stairs-6
rule46=0,100,minecraft:stone_brick_stairs-4
rule47=0,100,minecraft:stone_brick_stairs-7
rule48=0,100,minecraft:stone_brick_stairs-5
rule49=0,100,minecraft:bed-10
rule50=0,100,minecraft:bed-2
rule51=0,100,minecraft:bed-0
rule52=0,100,minecraft:bed-8
rule53=0,100,minecraft:wooden_slab-2
rule54=0,100,ChestGenHook:dungeonChest:1-4
rule55=0,100,minecraft:flower_pot-3
rule56=0,100,minecraft:flower_pot-0
rule57=2,100,minecraft:torch-4
rule58=0,100,minecraft:birch_stairs-2
rule59=0,100,minecraft:birch_stairs-3
rule60=0,100,ChestGenHook:dungeonChest:1-5
rule61=0,100,minecraft:noteblock-0
rule62=0,100,minecraft:fence-0
rule63=1,100,minecraft:torch-5
rule64=0,100,minecraft:flower_pot-1

rule65=0,100,CommandBlock:RUINSTRIGGER /summon Skeleton ~0 ~1 ~0 {CustomName:Bandit,Equipment:[{Count:1,id:261,tag:{display:{Name:Bandit Bow},ench:[{id:21,lvl:5},{id:48,lvl:2},{id:49,lvl:3}]}},{Count:1,id:301},{Count:1,id:300},{Count:1,id:299},{Count:1,id:397,Damage:3}],Attributes:[{Name:generic.maxHealth,Base:15}],DropChances:[1.0F,0.5F,0.5F,0.5F,0.5F],PersistenceRequired:1}:@

rule66=0,100,minecraft:fence_gate-1

rule67=0,100,CommandBlock:RUINSTRIGGER /summon Villager ~0 ~0 ~0 {Profession:0,CustomName:Innkeeper,Offers:{Recipes:[{uses:-25,maxUses:25,buy:{id:388,Count:1},sell:{id:391,Count:16}},{uses:-25,maxUses:25,buy:{id:388,Count:1},sell:{id:393,Count:8}},{uses:-25,maxUses:25,buy:{id:388,Count:1},sell:{id:320,Count:8}},{uses:-25,maxUses:25,buy:{id:388,Count:1},sell:{id:350,Count:5}},{uses:-25,maxUses:25,buy:{id:388,Count:1},sell:{id:366,Count:6}},{uses:-25,maxUses:25,buy:{id:367,Count:32},sell:{id:388,Count:1}},{uses:-25,maxUses:25,buy:{id:375,Count:32},sell:{id:388,Count:1}},{uses:-8,maxUses:8,buy:{id:388,Count:3},sell:{id:395,Count:1}}]}}:@

rule68=0,100,CommandBlock:RUINSTRIGGER /summon Skeleton ~0 ~1 ~0 {CustomName:Bandit,Equipment:[{Count:1,id:268,tag:{display:{Name:Bandit Bludgeon},ench:[{id:21,lvl:5},{id:16,lvl:3},{id:19,lvl:3}]}},{Count:1,id:301},{Count:1,id:300},{Count:1,id:299},{Count:1,id:397,Damage:3}],Attributes:[{Name:generic.maxHealth,Base:15}],DropChances:[1.0F,0.5F,0.5F,0.5F,0.5F],PersistenceRequired:1}:@

layer
1,1,1,1,1,1,1,1,1,1,1,1,1,1,1,1,1,1,1,1
1,1,1,1,1,1,1,1,1,1,1,1,1,1,1,1,1,1,1,1
1,1,1,1,1,1,1,1,1,1,1,1,1,1,1,1,1,1,1,1
1,1,1,1,1,6,6,6,6,6,6,6,6,6,6,6,6,1,1,1
1,1,1,1,1,6,6,6,6,6,6,6,6,6,6,6,6,1,1,1
1,6,6,6,6,6,6,6,6,6,6,6,6,6,6,6,6,1,1,1
1,6,6,6,6,6,6,6,6,6,6,6,6,6,6,6,6,1,1,1
1,6,6,6,6,6,6,6,6,6,6,6,6,6,6,6,6,1,1,1
1,6,6,6,6,6,6,6,6,6,6,6,6,6,6,6,6,1,1,1
1,6,6,6,6,6,6,6,6,6,6,6,6,6,6,6,6,1,1,1
1,6,6,6,2,6,6,6,6,6,6,6,6,6,6,6,6,1,1,1
1,6,6,6,1,6,6,6,6,6,6,6,6,6,6,6,6,1,1,1
1,6,6,6,1,1,1,1,1,1,1,1,1,1,1,1,1,1,1,1
1,6,6,6,1,1,1,1,1,1,1,1,1,1,1,1,1,1,1,1
1,6,6,6,1,1,1,1,1,1,1,1,1,1,1,1,1,1,1,1
endlayer


layer
1,1,1,1,1,1,1,1,1,1,1,1,1,1,1,1,1,1,1,1
1,1,1,1,1,1,1,1,1,1,1,1,1,1,1,1,1,1,1,1
1,1,1,1,1,1,1,1,1,1,1,1,1,1,1,1,1,1,1,1
1,1,1,1,1,6,6,6,6,6,6,6,6,6,6,6,6,1,1,1
1,1,1,1,1,6,6,6,6,6,6,6,6,6,6,6,6,1,1,1
1,6,6,6,6,6,6,6,6,6,6,6,6,6,6,6,6,1,1,1
1,6,6,6,6,6,6,6,6,6,6,6,6,6,6,6,6,1,1,1
1,6,6,6,6,6,6,6,6,6,6,6,6,6,6,6,6,1,1,1
1,6,6,6,6,6,6,6,6,6,6,6,6,6,6,6,6,1,1,1
1,6,6,6,6,6,6,6,6,6,6,6,6,6,6,6,6,1,1,1
1,6,6,6,2,6,6,6,6,6,6,6,6,6,6,6,6,1,1,1
1,6,6,6,1,6,6,6,6,6,6,6,6,6,6,6,6,1,1,1
1,6,6,6,1,1,1,1,1,1,1,1,1,1,1,1,1,1,1,1
1,6,6,6,1,1,1,1,1,1,1,1,1,1,1,1,1,1,1,1
1,1,1,1,1,1,1,1,1,1,1,1,1,1,1,1,1,1,1,1
endlayer


layer
1,1,1,1,1,1,1,1,1,1,1,1,1,1,1,1,1,1,1,1
1,1,1,1,1,1,1,1,1,1,1,1,1,1,1,1,1,1,1,1
1,1,1,1,1,1,1,1,1,1,1,1,1,1,1,1,1,1,1,1
1,1,1,1,1,6,6,6,6,6,6,6,6,6,6,6,6,1,1,1
1,1,1,1,1,6,6,6,6,6,6,6,6,6,6,6,6,1,1,1
1,6,6,6,6,6,6,6,6,6,6,6,6,6,6,6,6,1,1,1
1,6,6,6,6,6,6,6,6,6,6,6,6,6,6,6,6,1,1,1
1,6,6,6,6,6,6,6,6,6,6,6,6,6,6,6,6,1,1,1
1,6,6,6,6,6,6,6,6,6,6,6,6,6,6,6,6,1,1,1
1,6,6,6,6,6,6,6,6,6,6,6,6,6,6,6,6,1,1,1
1,6,6,6,2,6,6,6,6,6,6,6,6,6,6,6,6,1,1,1
1,6,6,6,1,6,6,6,6,6,6,6,6,6,6,6,6,1,1,1
1,6,6,6,1,1,1,1,1,1,1,1,1,1,1,1,1,1,1,1
1,1,1,1,1,1,1,1,1,1,1,1,1,1,1,1,1,1,1,1
1,1,1,1,1,1,1,1,1,1,1,1,1,1,1,1,1,1,1,1
endlayer


layer
1,1,1,1,1,1,1,1,1,1,1,1,1,1,1,1,1,1,1,1
1,1,1,1,1,1,1,1,1,1,1,1,1,1,1,1,1,1,1,1
1,1,1,1,1,1,1,1,1,1,1,1,1,1,1,1,1,1,1,1
1,1,1,1,1,6,6,6,6,6,6,6,6,6,6,6,6,1,1,1
1,1,1,1,1,6,6,6,6,6,6,6,6,6,6,6,6,1,1,1
1,6,6,6,6,6,6,6,6,6,6,6,6,6,6,6,6,1,1,1
1,6,6,6,6,6,6,6,6,6,6,6,6,6,6,6,6,1,1,1
1,6,6,6,6,6,6,6,6,6,6,6,6,6,6,6,6,1,1,1
1,6,6,6,6,6,6,6,6,6,6,6,6,6,6,6,6,1,1,1
1,6,6,6,6,6,6,6,6,6,6,6,6,6,6,6,6,1,1,1
1,6,6,6,2,6,6,6,6,6,6,6,6,6,6,6,6,1,1,1
1,6,6,6,1,6,6,6,6,6,6,6,6,6,6,6,6,1,1,1
1,1,1,1,1,1,1,1,1,1,1,1,1,1,1,1,1,1,1,1
1,1,1,1,1,1,1,1,1,1,1,1,1,1,1,1,1,1,1,1
1,1,1,1,1,1,1,1,1,1,1,1,1,1,1,1,1,1,1,1
endlayer

layer
1,1,1,1,1,1,1,1,1,1,1,1,1,1,1,1,1,1,1,1
1,1,1,1,1,1,1,1,1,1,1,1,1,1,1,1,1,1,1,1
1,1,1,1,1,1,1,1,1,1,1,1,1,1,1,1,1,1,1,1
1,1,1,1,1,6,6,6,6,6,6,6,6,6,6,6,6,1,1,1
1,1,1,1,1,6,6,6,6,6,6,6,6,6,6,6,6,1,1,1
1,6,6,6,6,6,6,6,6,6,6,6,6,6,6,6,6,1,1,1
1,6,6,6,6,6,6,6,6,6,6,6,6,6,6,6,6,1,1,1
1,6,6,6,6,6,6,6,6,6,6,6,6,6,6,6,6,1,1,1
1,6,6,6,6,6,6,6,6,6,6,6,6,6,6,6,6,1,1,1
1,6,6,6,6,6,6,6,6,6,6,6,6,6,6,6,6,1,1,1
1,6,6,6,2,6,6,6,6,6,6,6,6,6,6,6,6,1,1,1
1,1,1,1,1,6,6,6,6,6,6,6,6,6,6,6,6,1,1,1
1,1,1,1,1,1,1,1,1,1,1,1,1,1,1,1,1,1,1,1
1,1,1,1,1,1,1,1,1,1,1,1,1,1,1,1,1,1,1,1
1,1,1,1,1,1,1,1,1,1,1,1,1,1,1,1,1,1,1,1
endlayer


layer
1,1,1,1,1,1,1,1,1,1,1,1,1,1,1,1,1,1,1,1
1,1,1,1,1,1,1,1,1,1,1,1,1,1,1,1,1,1,1,1
1,1,1,1,4,4,4,4,5,4,4,4,4,5,4,4,4,4,1,1
1,1,1,1,4,6,6,6,6,6,6,6,6,6,6,6,6,4,1,1
1,1,1,1,4,6,6,6,6,6,6,6,6,6,6,6,6,4,1,1
4,6,6,6,6,6,6,6,6,6,6,6,6,6,6,6,6,7,1,1
4,6,6,6,6,6,6,6,10,9,8,6,6,6,6,6,6,4,1,1
4,6,6,6,6,6,6,6,10,11,8,6,6,6,6,6,6,4,1,1
4,6,6,6,6,6,6,6,12,12,8,6,6,6,6,6,6,4,1,1
4,6,6,6,6,6,6,6,6,6,6,6,6,6,6,6,6,7,1,1
1,15,14,13,5,6,6,6,6,6,6,6,6,6,6,6,6,4,1,1
1,1,1,1,1,6,6,6,6,6,6,6,6,6,6,6,6,4,1,1
1,1,1,1,1,4,4,4,5,4,4,4,4,5,4,4,4,4,1,1
1,1,1,1,1,1,1,1,1,1,1,1,1,1,1,1,1,1,1,1
1,1,1,1,1,1,1,1,1,1,1,1,1,1,1,1,1,1,1,1
endlayer

layer
0,0,0,0,0,0,0,0,0,0,0,0,0,0,0,0,0,0,0,0
0,0,0,0,0,0,0,0,0,0,0,0,0,0,0,0,0,0,0,0
0,0,0,0,0,0,0,0,17,0,0,0,0,16,0,0,0,0,0,0
0,0,0,0,0,18,19,18,19,18,19,19,18,19,18,19,18,0,0,0
0,0,0,0,0,19,23,22,21,23,22,21,23,22,21,20,19,0,0,0
0,18,19,18,19,18,0,68,0,0,0,68,0,0,0,0,18,17,0,0
0,19,67,20,20,0,0,0,38,38,38,0,0,24,18,0,19,0,0,0
0,18,66,62,0,0,0,0,0,0,0,0,0,18,0,0,19,0,0,0
0,19,25,0,0,0,0,0,38,38,38,0,0,0,0,0,19,0,0,0
0,18,0,18,19,18,0,0,68,0,0,0,68,0,0,0,18,26,0,0
0,0,0,0,27,19,23,22,21,23,22,21,23,22,21,20,19,0,0,0
0,0,0,0,0,18,19,18,19,18,19,19,18,19,18,19,18,0,0,0
0,0,0,0,0,0,0,0,27,0,0,0,0,27,0,0,0,0,0,0
0,0,0,0,0,0,0,0,0,0,0,0,0,0,0,0,0,0,0,0
0,0,0,0,0,0,0,0,0,0,0,0,0,0,0,0,0,0,0,0
endlayer

layer
0,0,0,0,0,0,0,0,0,0,0,0,0,0,0,0,0,0,0,0
0,0,0,0,0,0,0,0,0,0,0,0,0,0,0,0,0,0,0,0
0,0,0,0,0,0,0,0,0,0,0,0,0,0,0,0,0,0,0,0
0,0,0,0,0,18,19,18,19,18,28,28,18,19,18,19,18,0,0,0
0,0,0,0,0,19,0,0,0,29,0,0,0,0,0,0,28,0,0,0
0,18,19,18,19,18,0,0,0,0,0,0,0,0,0,30,18,0,0,0
0,19,29,31,0,29,0,0,38,38,38,0,0,0,0,0,28,0,0,0
0,18,0,0,0,0,0,0,38,0,38,0,0,18,32,0,28,0,0,0
0,19,33,0,0,0,0,0,38,38,38,0,0,0,18,0,28,0,0,0
0,18,0,18,19,18,0,0,0,0,0,0,0,0,0,30,18,0,0,0
0,0,0,0,0,19,0,0,0,34,0,0,0,0,0,0,28,0,0,0
0,0,0,0,0,18,19,18,19,18,28,28,18,19,18,19,18,0,0,0
0,0,0,0,0,0,0,0,0,0,0,0,0,0,0,0,0,0,0,0
0,0,0,0,0,0,0,0,0,0,0,0,0,0,0,0,0,0,0,0
0,0,0,0,0,0,0,0,0,0,0,0,0,0,0,0,0,0,0,0
endlayer

layer
0,0,0,0,0,0,0,0,0,0,0,0,0,0,0,0,0,0,0,0
0,0,0,0,0,0,0,0,0,0,0,0,0,0,0,0,0,0,0,0
0,0,0,0,0,0,0,0,0,0,0,0,0,0,0,0,0,0,0,0
0,0,0,0,0,18,19,18,19,18,28,28,18,19,18,19,18,0,0,0
0,0,0,0,0,19,0,0,0,0,0,0,0,0,0,0,28,0,0,0
0,18,19,18,19,18,0,0,0,0,0,0,0,0,0,0,18,0,0,0
0,19,0,62,0,0,0,0,38,38,38,0,0,0,0,0,28,0,0,0
0,18,0,62,0,0,0,0,38,0,38,0,0,18,0,0,28,0,0,0
0,19,0,62,0,0,0,0,38,38,38,0,18,35,0,0,28,0,0,0
0,18,19,18,19,18,0,0,0,0,0,0,0,0,0,0,18,0,0,0
0,0,0,0,0,19,0,0,0,0,0,0,0,0,0,0,28,0,0,0
0,0,0,0,0,18,19,18,19,18,28,28,18,19,18,19,18,0,0,0
0,0,0,0,0,0,0,0,0,0,0,0,0,0,0,0,0,0,0,0
0,0,0,0,0,0,0,0,0,0,0,0,0,0,0,0,0,0,0,0
0,0,0,0,0,0,0,0,0,0,0,0,0,0,0,0,0,0,0,0
endlayer

layer
0,0,0,0,0,0,0,0,0,0,0,0,0,0,0,0,0,0,0,0
0,0,0,0,0,0,0,0,0,0,0,0,0,0,0,0,0,0,0,0
0,0,0,0,36,0,36,0,36,0,36,36,0,36,0,36,0,36,0,0
0,0,0,0,0,18,18,18,18,18,18,18,18,18,18,18,18,0,0,0
37,37,37,0,36,18,0,0,0,0,0,0,0,0,0,0,18,36,0,0
0,18,18,18,18,18,0,0,0,0,0,0,0,0,0,0,18,0,0,0
0,18,0,0,0,0,0,0,38,38,38,0,18,0,0,0,18,36,0,0
0,18,0,0,0,0,0,0,38,0,38,0,39,18,0,0,18,0,0,0
0,18,0,0,0,0,0,0,38,38,38,0,0,0,0,0,18,36,0,0
0,18,18,18,18,18,0,0,0,0,0,0,0,0,0,0,18,0,0,0
40,40,40,0,36,18,0,0,0,0,0,0,0,0,0,0,18,36,0,0
0,0,0,0,0,18,18,18,18,18,18,18,18,18,18,18,18,0,0,0
0,0,0,0,36,0,36,0,36,0,36,36,0,36,0,36,0,36,0,0
0,0,0,0,0,0,0,0,0,0,0,0,0,0,0,0,0,0,0,0
0,0,0,0,0,0,0,0,0,0,0,0,0,0,0,0,0,0,0,0
endlayer

layer
0,0,0,0,0,0,0,0,0,0,0,0,0,0,0,0,0,0,0,0
0,0,0,0,41,0,41,0,41,0,41,41,0,41,0,41,0,41,0,0
0,0,0,43,19,19,19,19,19,19,19,19,19,19,19,19,19,19,42,0
0,0,0,0,19,0,0,44,0,44,0,0,44,0,44,0,0,19,0,0
0,0,0,43,19,0,0,0,0,0,0,0,0,0,0,0,0,19,42,0
37,37,37,18,19,42,0,0,0,0,0,0,0,0,0,0,43,19,0,0
0,18,18,18,0,0,0,0,46,46,45,0,0,24,18,0,0,19,42,0
0,19,0,0,0,0,0,0,47,6,45,0,0,18,0,0,43,19,0,0
0,18,18,18,0,0,0,0,48,48,45,0,0,0,0,0,0,19,42,0
40,40,40,18,19,42,0,0,0,0,0,0,0,0,0,0,43,19,0,0
0,0,0,43,19,0,0,0,0,0,0,0,0,0,0,0,0,19,42,0
0,0,0,0,19,0,0,41,0,41,0,0,41,0,0,41,0,19,0,0
0,0,0,43,19,19,19,19,19,19,19,19,19,19,19,19,19,19,42,0
0,0,0,0,44,0,44,0,44,0,44,44,0,44,0,44,0,44,0,0
0,0,0,0,0,0,0,0,0,0,0,0,0,0,0,0,0,0,0,0
endlayer

layer
0,0,0,0,0,0,0,0,0,0,0,0,0,0,0,0,0,0,0,0
0,0,0,18,18,18,18,18,18,18,18,18,18,18,18,18,18,18,18,0
0,0,0,18,18,18,18,18,18,18,18,18,18,18,18,18,18,18,18,0
0,0,0,18,18,18,18,18,18,18,18,18,18,18,18,18,18,18,18,0
0,0,0,18,18,18,18,18,18,18,18,18,18,18,18,18,18,18,18,0
0,0,0,18,18,18,18,18,18,18,18,18,18,18,18,18,18,18,18,0
37,37,37,18,18,18,18,18,18,18,18,18,0,0,0,18,18,18,18,0
0,18,18,18,18,18,18,18,18,18,18,18,0,18,32,18,18,18,18,0
40,40,40,18,18,18,18,18,18,18,18,18,0,18,18,18,18,18,18,0
0,0,0,18,18,18,18,18,18,18,18,18,18,18,18,18,18,18,18,0
0,0,0,18,18,18,18,18,18,18,18,18,18,18,18,18,18,18,18,0
0,0,0,18,18,18,18,18,18,18,18,18,18,18,18,18,18,18,18,0
0,0,0,18,18,18,18,18,18,18,18,18,18,18,18,18,18,18,18,0
0,0,0,18,18,18,18,18,18,18,18,18,18,18,18,18,18,18,18,0
0,0,0,0,0,0,0,0,0,0,0,0,0,0,0,0,0,0,0,0
endlayer

layer
0,0,0,0,0,0,0,0,0,0,0,0,0,0,0,0,0,0,0,0
0,0,0,18,19,18,28,28,28,18,19,19,18,28,28,28,18,19,18,0
0,0,0,19,23,0,0,0,21,0,20,20,0,0,0,0,0,20,19,0
0,0,0,18,52,51,0,50,49,0,0,0,0,0,0,0,0,0,18,0
0,0,0,28,23,0,0,0,21,0,0,0,68,0,0,0,0,0,28,0
0,0,0,28,52,51,0,50,49,0,0,0,0,0,0,0,0,0,28,0
0,0,0,18,23,0,0,0,21,0,0,0,0,0,0,0,0,0,18,0
53,53,53,19,52,51,0,50,49,0,0,0,30,18,0,0,0,20,19,0
0,0,0,18,23,0,0,0,21,0,0,0,18,35,0,0,0,0,18,0
0,0,0,28,52,51,0,50,49,0,0,0,0,0,0,0,0,0,28,0
0,0,0,28,0,0,0,0,0,0,0,0,0,65,0,0,0,0,28,0
0,0,0,18,0,0,0,65,0,0,0,0,0,0,0,0,0,0,18,0
0,0,0,19,0,0,0,0,0,0,54,54,0,0,0,0,0,54,19,0
0,0,0,18,19,18,28,28,28,18,19,19,18,28,28,28,18,19,18,0
0,0,0,0,0,0,0,0,0,0,0,0,0,0,0,0,0,0,0,0
endlayer

layer
0,0,0,0,0,0,0,0,0,0,0,0,0,0,0,0,0,0,0,0
0,0,0,18,19,18,28,28,28,18,19,19,18,28,28,28,18,19,18,0
0,0,0,19,0,0,0,0,0,29,56,0,29,0,0,0,0,55,19,0
0,0,0,18,57,0,0,0,0,0,0,0,0,0,0,0,0,30,18,0
0,0,0,28,0,0,0,0,0,0,0,0,0,0,0,0,0,0,28,0
0,0,0,28,0,0,0,0,0,0,0,0,0,0,0,0,0,0,28,0
0,0,0,18,57,0,0,0,0,0,0,0,18,0,0,0,0,30,18,0
0,0,0,19,0,0,0,0,0,0,0,0,39,18,57,0,0,56,19,0
0,0,0,18,57,0,0,0,0,0,0,0,0,0,0,0,0,30,18,0
0,0,0,28,0,0,0,0,0,0,0,0,0,0,0,0,0,0,28,0
0,0,0,28,0,0,0,0,0,0,0,0,0,0,0,0,0,0,28,0
0,0,0,18,57,0,0,0,0,0,0,0,0,0,0,0,0,30,18,0
0,0,0,19,0,0,0,0,0,34,54,54,34,0,0,0,0,54,19,0
0,0,0,18,19,18,28,28,28,18,19,19,18,28,28,28,18,19,18,0
0,0,0,0,0,0,0,0,0,0,0,0,0,0,0,0,0,0,0,0
endlayer

layer
0,0,0,0,0,0,0,0,0,0,0,0,0,0,0,0,0,0,0,0
0,0,0,18,19,18,28,28,28,18,19,19,18,28,28,28,18,19,18,0
0,0,0,19,0,0,0,0,0,0,0,0,0,0,0,0,0,0,19,0
0,0,0,18,0,0,0,0,0,0,0,0,0,0,0,0,0,0,18,0
0,0,0,28,0,0,0,0,0,0,0,0,0,0,0,0,0,0,28,0
0,0,0,28,0,0,0,0,0,0,0,0,0,0,0,0,0,0,28,0
0,0,0,18,0,0,0,0,0,0,0,0,0,24,18,0,0,0,18,0
0,0,0,19,0,0,0,0,0,0,0,0,0,18,0,0,0,0,19,0
0,0,0,18,0,0,0,0,0,0,0,0,0,0,0,0,0,0,18,0
0,0,0,28,0,0,0,0,0,0,0,0,0,0,0,0,0,0,28,0
0,0,0,28,0,0,0,0,0,0,0,0,0,0,0,0,0,0,28,0
0,0,0,18,0,0,0,0,0,0,0,0,0,0,0,0,0,0,18,0
0,0,0,19,0,0,0,0,0,0,0,0,0,0,0,0,0,0,19,0
0,0,0,18,19,18,28,28,28,18,19,19,18,28,28,28,18,19,18,0
0,0,0,0,0,0,0,0,0,0,0,0,0,0,0,0,0,0,0,0
endlayer

layer
0,0,0,0,0,0,0,0,0,0,0,0,0,0,0,0,0,0,0,0
0,0,0,18,18,18,18,18,18,18,18,18,18,18,18,18,18,18,18,0
0,0,0,18,0,0,0,0,18,18,18,18,18,18,18,18,18,18,18,0
0,0,0,18,0,0,0,0,18,18,18,18,18,18,18,18,18,18,18,0
0,0,0,18,0,0,0,0,18,18,18,18,18,18,18,18,18,18,18,0
0,0,0,18,0,0,0,0,18,18,18,18,18,18,18,18,18,18,18,0
0,0,0,18,0,0,0,0,18,18,18,18,0,0,0,18,18,18,18,0
0,0,0,18,0,0,0,0,18,18,18,18,0,18,32,18,18,18,18,0
0,0,0,18,0,0,0,0,18,18,18,18,0,18,18,18,18,18,18,0
0,0,0,18,0,0,0,0,18,18,18,18,18,18,18,18,18,18,18,0
0,0,0,18,0,0,0,0,18,18,18,18,18,18,18,18,18,18,18,0
0,0,0,18,0,0,0,0,18,18,18,18,18,18,18,18,18,18,18,0
0,0,0,18,0,0,0,0,18,18,18,18,18,18,18,18,18,18,18,0
0,0,0,18,18,18,18,18,18,18,18,18,18,18,18,18,18,18,18,0
0,0,0,0,0,0,0,0,0,0,0,0,0,0,0,0,0,0,0,0
endlayer

layer
0,0,0,0,59,0,0,0,0,0,0,0,0,0,0,0,0,58,0,0
0,0,37,37,59,18,19,19,19,19,19,19,19,19,19,19,18,37,37,37
0,0,0,18,18,18,0,0,62,0,60,61,0,60,60,0,18,18,18,0
0,0,0,19,0,0,0,0,62,0,0,0,0,0,0,0,61,0,19,0
0,0,0,19,0,0,0,0,62,0,0,0,0,65,0,0,0,0,19,0
0,0,0,19,0,0,0,0,62,0,0,0,0,0,0,0,0,0,19,0
0,0,0,28,0,0,0,0,62,0,0,0,0,0,0,0,0,0,28,0
0,0,0,28,0,0,0,0,62,0,0,65,0,63,0,0,0,0,28,0
0,0,0,28,0,0,0,0,62,0,0,0,0,0,0,0,0,0,28,0
0,0,0,19,0,0,0,0,62,0,0,0,0,0,0,0,0,0,19,0
0,0,0,19,0,0,0,0,62,0,0,0,0,65,0,0,0,0,19,0
0,0,0,19,0,0,0,0,62,0,0,0,0,0,0,0,0,0,19,0
0,0,0,18,18,18,0,0,62,54,54,64,0,54,61,61,18,18,18,0
0,0,40,40,40,18,19,19,19,19,19,19,19,19,19,19,18,40,40,40
0,0,0,0,59,0,0,0,0,0,0,0,0,0,0,0,0,58,0,0
endlayer

layer
0,0,0,0,0,59,0,0,0,0,0,0,0,0,0,0,58,0,0,0
0,0,0,0,0,59,18,19,19,19,19,19,19,19,19,18,58,0,0,0
0,0,37,37,37,59,18,0,0,0,0,61,0,0,0,18,58,37,37,37
0,0,0,18,18,18,18,0,0,0,0,0,0,0,0,18,18,18,18,0
0,0,0,19,0,0,0,0,0,0,0,0,0,0,0,0,0,0,19,0
0,0,0,19,0,0,0,0,63,0,0,0,0,0,0,0,0,30,19,0
0,0,0,28,0,0,0,0,0,0,0,0,0,0,0,0,0,0,28,0
0,0,0,28,0,0,0,0,0,0,0,0,0,0,0,0,0,0,28,0
0,0,0,28,0,0,0,0,0,0,0,0,0,0,0,0,0,0,28,0
0,0,0,19,0,0,0,0,63,0,0,0,0,0,0,0,0,30,19,0
0,0,0,19,0,0,0,0,0,0,0,0,0,0,0,0,0,0,19,0
0,0,0,18,18,18,18,0,0,0,0,0,0,0,0,18,18,18,18,0
0,0,40,40,40,59,18,0,0,0,0,0,0,54,0,18,40,40,40,40
0,0,0,0,0,59,18,19,19,19,19,19,19,19,19,18,58,0,0,0
0,0,0,0,0,59,0,0,0,0,0,0,0,0,0,0,58,0,0,0
endlayer

layer
0,0,0,0,0,0,59,0,0,0,0,0,0,0,0,58,0,0,0,0
0,0,0,0,0,0,59,18,19,28,28,28,28,19,18,58,0,0,0,0
0,0,0,0,0,0,59,18,0,0,0,0,0,0,18,58,0,0,0,0
0,0,37,37,37,37,37,18,0,0,0,0,0,0,18,58,37,37,37,37
0,0,0,18,18,18,18,18,0,0,0,0,0,0,18,18,18,18,18,0
0,0,0,19,0,0,0,0,0,0,0,0,0,0,0,0,0,0,19,0
0,0,0,28,0,0,0,0,0,0,0,0,0,0,0,0,0,0,28,0
0,0,0,28,0,0,0,0,0,0,0,0,0,0,0,0,0,0,28,0
0,0,0,28,0,0,0,0,0,0,0,0,0,0,0,0,0,0,28,0
0,0,0,19,0,0,0,0,0,0,0,0,0,0,0,0,0,0,19,0
0,0,0,18,18,18,18,18,0,0,0,0,0,0,18,18,18,18,18,0
0,0,40,40,40,40,40,18,0,0,0,0,0,0,18,40,40,40,40,40
0,0,0,0,0,0,59,18,0,0,0,0,0,0,18,58,0,0,0,0
0,0,0,0,0,0,59,18,19,28,28,28,28,19,18,58,0,0,0,0
0,0,0,0,0,0,59,0,0,0,0,0,0,0,0,58,0,0,0,0
endlayer

layer
0,0,0,0,0,0,0,59,0,0,0,0,0,0,58,0,0,0,0,0
0,0,0,0,0,0,0,59,18,19,18,18,19,18,58,0,0,0,0,0
0,0,0,0,0,0,0,59,18,0,0,0,0,18,58,0,0,0,0,0
0,0,0,0,0,0,0,59,18,0,0,0,0,18,58,0,0,0,0,0
0,0,37,37,37,37,37,37,18,0,0,0,0,18,37,37,37,37,37,37
0,0,0,18,18,18,18,18,18,0,0,0,0,18,18,18,18,18,18,0
0,0,0,19,0,0,0,0,0,0,0,0,0,0,0,0,0,0,19,0
0,0,0,18,0,0,0,0,0,0,0,0,0,0,0,0,0,0,18,0
0,0,0,19,0,0,0,0,0,0,0,0,0,0,0,0,0,0,19,0
0,0,0,18,18,18,18,18,18,0,0,0,0,18,18,18,18,18,18,0
0,0,40,40,40,40,40,59,18,0,0,0,0,18,40,40,40,40,40,40
0,0,0,0,0,0,0,59,18,0,0,0,0,18,58,0,0,0,0,0
0,0,0,0,0,0,0,59,18,0,0,0,0,18,58,0,0,0,0,0
0,0,0,0,0,0,0,59,18,19,18,18,19,18,58,0,0,0,0,0
0,0,0,0,0,0,0,59,0,0,0,0,0,0,58,0,0,0,0,0
endlayer

layer
0,0,0,0,0,0,0,0,59,0,0,0,0,58,0,0,0,0,0,0
0,0,0,0,0,0,0,0,59,18,19,19,18,58,0,0,0,0,0,0
0,0,0,0,0,0,0,0,59,18,0,0,18,58,0,0,0,0,0,0
0,0,0,0,0,0,0,0,59,18,0,0,18,58,0,0,0,0,0,0
0,0,0,0,0,0,0,0,59,18,0,0,18,58,0,0,0,0,0,0
0,0,37,37,37,37,37,37,59,18,0,0,18,58,37,37,37,37,37,37
0,0,0,18,18,18,18,18,18,18,0,0,18,18,18,18,18,18,18,0
0,0,0,19,0,0,0,0,0,0,0,0,0,0,0,0,0,0,19,0
0,0,0,18,18,18,18,18,18,18,0,0,18,18,18,18,18,18,18,0
0,0,40,40,40,40,40,40,59,18,0,0,18,58,40,40,40,40,40,40
0,0,0,0,0,0,0,0,59,18,0,0,18,58,0,0,0,0,0,0
0,0,0,0,0,0,0,0,59,18,0,0,18,58,0,0,0,0,0,0
0,0,0,0,0,0,0,0,59,18,0,0,18,58,0,0,0,0,0,0
0,0,0,0,0,0,0,0,59,18,19,19,18,58,0,0,0,0,0,0
0,0,0,0,0,0,0,0,59,0,0,0,0,58,0,0,0,0,0,0
endlayer

layer
0,0,0,0,0,0,0,0,0,59,0,0,58,0,0,0,0,0,0,0
0,0,0,0,0,0,0,0,0,59,18,18,58,0,0,0,0,0,0,0
0,0,0,0,0,0,0,0,0,59,18,18,58,0,0,0,0,0,0,0
0,0,0,0,0,0,0,0,0,59,18,18,58,0,0,0,0,0,0,0
0,0,0,0,0,0,0,0,0,59,18,18,58,0,0,0,0,0,0,0
0,0,0,0,0,0,0,0,0,59,18,18,58,0,0,0,0,0,0,0
0,0,37,37,37,37,37,37,37,37,18,18,37,37,37,37,37,37,37,37
0,0,0,18,18,18,18,18,18,18,18,18,18,18,18,18,18,18,18,0
0,0,40,40,40,40,40,40,40,59,18,18,40,40,40,40,40,40,40,40
0,0,0,0,0,0,0,0,0,59,18,18,58,0,0,0,0,0,0,0
0,0,0,0,0,0,0,0,0,59,18,18,58,0,0,0,0,0,0,0
0,0,0,0,0,0,0,0,0,59,18,18,58,0,0,0,0,0,0,0
0,0,0,0,0,0,0,0,0,59,18,18,58,0,0,0,0,0,0,0
0,0,0,0,0,0,0,0,0,59,18,18,58,0,0,0,0,0,0,0
0,0,0,0,0,0,0,0,0,59,0,0,58,0,0,0,0,0,0,0
endlayer

layer
0,0,0,0,0,0,0,0,0,0,53,53,0,0,0,0,0,0,0,0
0,0,0,0,0,0,0,0,0,0,53,53,0,0,0,0,0,0,0,0
0,0,0,0,0,0,0,0,0,0,53,53,0,0,0,0,0,0,0,0
0,0,0,0,0,0,0,0,0,0,53,53,0,0,0,0,0,0,0,0
0,0,0,0,0,0,0,0,0,0,53,53,0,0,0,0,0,0,0,0
0,0,0,0,0,0,0,0,0,0,53,53,0,0,0,0,0,0,0,0
0,0,0,0,0,0,0,0,0,0,53,53,0,0,0,0,0,0,0,0
0,0,53,53,53,53,53,53,53,53,53,53,53,53,53,53,53,53,53,53
0,0,0,0,0,0,0,0,0,0,53,53,0,0,0,0,0,0,0,0
0,0,0,0,0,0,0,0,0,0,53,53,0,0,0,0,0,0,0,0
0,0,0,0,0,0,0,0,0,0,53,53,0,0,0,0,0,0,0,0
0,0,0,0,0,0,0,0,0,0,53,53,0,0,0,0,0,0,0,0
0,0,0,0,0,0,0,0,0,0,53,53,0,0,0,0,0,0,0,0
0,0,0,0,0,0,0,0,0,0,53,53,0,0,0,0,0,0,0,0
0,0,0,0,0,0,0,0,0,0,53,53,0,0,0,0,0,0,0,0
endlayer

