# Bedrock Dungeon Tunnel -- MC 1.7.10 -- 29 Jan 2016
# Created by Ruins mod version 15.1 Ingame Parser
# authoring Player: Jordan_Greywolf
# Note: Place in \templateparser folder.

weight=1
embed_into_distance=1
acceptable_target_blocks=
unacceptable_target_blocks=flowing_water,water,flowing_lava,lava
dimensions=5,5,21
allowable_overhang=0
max_leveling=0
leveling_buffer=-1
preserve_water=0
preserve_lava=0

rule1=0,100,minecraft:stone-0
rule2=0,100,minecraft:cobblestone-0
rule3=0,100,minecraft:cobblestone_wall-0
rule4=0,100,minecraft:rail-0
rule5=0,100,CommandBlock:RUINSTRIGGER /setblock ~0 ~-1 ~0 mob_spawner 0 replace {SpawnCount:1,SpawnRange:4,maxNearbyEntities:6,Delay:20,MinSpawnDelay:60,MaxSpawnDelay:120,EntityId:Skeleton,SpawnData:{Equipment:[{Count:1,id:257,tag:{ench:[{id:16,lvl:3},{id:33,lvl:1}]}},{id:301},{id:300},{id:299},{Count:1,id:306,tag:{ench:[{id:3,lvl:2},{id:5,lvl:2}]}}],DropChances:[0.2F,0.0F,0.0F,0.0F,0.1F],ActiveEffects:[{Id:14,Amplifier:1,Duration:999999}]}}:@,CommandBlock:RUINSTRIGGER /setblock ~0 ~-1 ~0 mob_spawner 0 replace {SpawnCount:1,SpawnRange:4,maxNearbyEntities:6,Delay:20,MinSpawnDelay:60,MaxSpawnDelay:120,EntityId:Skeleton,SpawnData:{Equipment:[{Count:1,id:66},{id:301},{id:300},{id:299},{id:306,tag:{ench:[{id:3,lvl:2},{id:5,lvl:2}]}}],DropChances:[2.0F,0.0F,0.0F,0.0F,0.0F],ActiveEffects:[{Id:21,Amplifier:1,Duration:999999},{Id:14,Amplifier:1,Duration:999999},{Id:5,Amplifier:1,Duration:999999}]}}:@
rule6=0,100,minecraft:stone_slab-8


layer
1,1,1,1,1,1,1,1,1,1,1,1,1,1,1,1,1,1,1,1,1
1,1,1,1,1,1,1,1,1,1,1,1,1,1,1,1,1,1,1,1,1
1,1,1,1,1,1,1,1,1,1,1,1,1,1,1,1,1,1,1,1,1
1,1,1,1,1,1,1,1,1,1,1,1,1,1,1,1,1,1,1,1,1
1,1,1,1,1,1,1,1,1,1,1,1,1,1,1,1,1,1,1,1,1
endlayer

layer
2,3,0,3,2,3,0,3,2,3,0,3,2,3,0,3,2,3,0,3,2
3,0,0,0,3,0,0,0,3,0,0,0,3,0,0,0,3,0,0,0,3
4,4,4,4,4,4,4,4,4,4,4,4,4,4,4,4,4,4,4,4,4
3,0,0,0,3,0,0,0,3,0,0,0,3,0,0,0,3,0,0,0,3
2,3,0,3,2,3,0,3,2,3,0,3,2,3,0,3,2,3,0,3,2
endlayer

layer
2,3,0,3,2,3,0,3,2,3,0,3,2,3,0,3,2,3,0,3,2
3,0,0,0,3,0,0,0,3,0,0,0,3,0,0,0,3,0,0,0,3
0,0,0,0,0,0,0,0,0,0,0,0,0,0,0,0,0,0,0,0,0
3,0,0,0,3,0,0,0,3,0,0,0,3,0,0,0,3,0,0,0,3
2,3,0,3,2,3,0,3,2,3,5,3,2,3,0,3,2,3,0,3,2
endlayer

layer
2,3,3,3,2,3,3,3,2,3,3,3,2,3,3,3,2,3,3,3,2
3,0,0,0,3,0,0,0,3,0,0,0,3,0,0,0,3,0,0,0,3
0,0,0,0,0,0,0,0,0,0,0,0,0,0,0,0,0,0,0,0,0
3,0,0,0,3,0,0,0,3,0,0,0,3,0,0,0,3,0,0,0,3
2,3,3,3,2,3,3,3,2,3,3,3,2,3,3,3,2,3,3,3,2
endlayer

layer
2,2,2,2,2,2,2,2,2,2,2,2,2,2,2,2,2,2,2,2,2
2,6,6,6,2,6,6,6,2,6,6,6,2,6,6,6,2,6,6,6,2
2,6,6,6,2,6,6,6,2,6,6,6,2,6,6,6,2,6,6,6,2
2,6,6,6,2,6,6,6,2,6,6,6,2,6,6,6,2,6,6,6,2
2,2,2,2,2,2,2,2,2,2,2,2,2,2,2,2,2,2,2,2,2
endlayer

