
# Created by Ruins mod version 15.1 Ingame Parser
# authoring Player: Jordan_Greywolf

weight=1
embed_into_distance=0
acceptable_target_blocks=
unacceptable_target_blocks=flowing_water,water,flowing_lava,lava
dimensions=11,5,13
allowable_overhang=0
max_leveling=2
leveling_buffer=0
preserve_water=0
preserve_lava=0

rule1=0,100,minecraft:stonebrick-1
rule2=0,100,minecraft:stained_glass-3
rule3=0,100,minecraft:stained_hardened_clay-11
rule4=0,100,minecraft:stained_hardened_clay-9
rule5=0,100,minecraft:glass_pane-0
rule6=0,100,minecraft:cobblestone_wall-1
rule7=0,100,minecraft:sponge-0
rule8=0,100,CommandBlock:continue:@
rule9=0,100,minecraft:stone_brick_stairs-5
rule10=0,100,minecraft:vine-1
rule11=0,100,minecraft:stone_brick_stairs-4
rule12=0,100,minecraft:vine-2
rule13=0,100,minecraft:vine-4
rule14=0,100,minecraft:vine-8
rule15=0,100,minecraft:glass-0
rule16=1,100,minecraft:redstone_torch-5

layer
1,1,1,1,1,1,1,1,1,1,1,1,1
1,2,2,2,1,2,2,2,1,2,2,2,1
1,2,2,2,1,2,2,2,1,2,2,2,1
1,2,2,2,1,2,2,2,1,2,2,2,1
1,1,1,1,1,1,1,1,1,1,1,1,1
endlayer

layer
1,0,0,0,1,0,0,0,1,0,0,0,1
0,0,0,0,0,0,0,0,0,0,0,0,0
0,0,0,0,0,0,0,0,0,0,0,0,0
0,0,0,0,0,0,0,0,0,0,0,0,0
1,0,0,0,1,0,0,0,1,0,0,0,1
endlayer

layer
1,0,0,0,1,0,0,0,1,0,0,0,1
0,0,0,0,0,0,0,0,0,0,0,0,0
0,0,0,0,0,0,0,0,0,0,0,0,0
0,0,0,0,0,0,0,0,0,0,0,0,0
1,0,0,0,1,0,0,0,1,0,0,0,1
endlayer

layer
1,1,0,1,1,1,0,1,1,1,0,1,1
1,0,0,0,1,0,0,0,1,0,0,0,1
0,0,0,0,0,0,0,0,0,0,0,0,0
1,0,0,0,1,0,0,0,1,0,0,0,1
1,1,0,1,1,1,0,1,1,1,0,1,1
endlayer

layer
1,1,1,1,1,1,1,1,1,1,1,1,1
1,3,4,3,1,3,4,3,1,3,4,3,1
1,4,4,4,1,4,4,4,1,4,4,4,1
1,3,4,3,1,3,4,3,1,3,4,3,1
1,1,1,1,1,1,1,1,1,1,1,1,1
endlayer

layer
1,5,5,5,1,5,5,5,1,5,5,5,1
6,0,0,0,0,0,0,0,0,0,0,0,6
0,8,0,0,0,0,7,0,0,0,0,0,0
6,0,0,0,0,0,0,0,0,0,0,0,6
1,5,5,5,1,5,5,5,1,5,5,5,1
endlayer

layer
1,5,5,5,1,5,5,5,1,5,5,5,1
6,0,0,0,0,0,0,0,0,0,0,0,6
0,0,0,0,0,0,0,0,0,0,0,0,0
6,0,0,0,0,0,0,0,0,0,0,0,6
1,5,5,5,1,5,5,5,1,5,5,5,1
endlayer

layer
1,1,5,1,1,1,5,1,1,1,5,1,1
6,0,0,0,9,0,0,0,9,0,0,0,6
0,0,0,0,0,10,0,0,0,0,0,0,0
6,0,0,0,11,0,0,0,11,0,0,0,6
1,1,5,1,1,1,5,1,1,1,5,1,1
endlayer

layer
1,1,1,1,1,1,1,1,1,1,1,1,1
1,10,12,12,1,12,12,13,1,10,12,12,1
1,10,0,13,1,10,0,13,1,10,0,13,1
1,14,14,13,1,10,14,14,1,14,14,13,1
1,1,1,1,1,1,1,1,1,1,1,1,1
endlayer

layer
2,2,2,2,2,2,2,2,2,2,2,2,2
1,15,15,15,1,15,15,15,1,15,15,15,1
15,0,0,0,16,0,0,0,16,0,0,0,15
1,15,15,15,1,15,15,15,1,15,15,15,1
2,2,2,2,2,2,2,2,2,2,2,2,2
endlayer

layer
2,2,2,2,2,2,2,2,2,2,2,2,2
2,2,2,2,2,2,2,2,2,2,2,2,2
1,1,1,1,1,1,1,1,1,1,1,1,1
2,2,2,2,2,2,2,2,2,2,2,2,2
2,2,2,2,2,2,2,2,2,2,2,2,2
endlayer

