# Haunted Chalet -- MC 1.7.10
# Created by Ruins mod version 15.1 Ingame Parser
# authoring Player: Jordan_Greywolf
# Created 8 Nov 2015
# Last Updated 22 Nov 2015

biomesToSpawnIn=alps,alps forest,cold taiga hills,cold taiga m,icy hills,ice mountains,snowy coniferous forest,rwg_coldforest,rwg_snowforest

uniqueMinDistance=500

weight=1
embed_into_distance=10
acceptable_target_blocks=

unacceptable_target_blocks=flowing_water,water,flowing_lava,lava,cloud,Natura:Cloud,slime_congealed,slime_dirt,slime_grass

dimensions=30,15,15
allowable_overhang=50

max_leveling=10
leveling_buffer=-1

preserve_water=0
preserve_lava=0
preserve_plants=1

rule1=0,100,preserveBlock
rule2=0,100,minecraft:log-0
rule3=0,100,minecraft:stone_stairs-7
rule4=0,100,minecraft:stone_slab-11
rule5=0,100,minecraft:stone_stairs-6
rule6=0,100,minecraft:stone_stairs-5
rule7=0,100,minecraft:stone_stairs-4
rule8=0,100,minecraft:stone_slab-8
rule9=0,100,minecraft:stone_brick_stairs-4
rule10=0,100,minecraft:stone_brick_stairs-6
rule11=0,100,minecraft:stonebrick-0
rule12=0,100,minecraft:stone_brick_stairs-7
rule13=0,100,minecraft:double_stone_slab-0
rule14=0,100,minecraft:water-0
rule15=0,100,minecraft:grass-0
rule16=0,100,minecraft:stone_brick_stairs-5
rule17=0,100,minecraft:fence-0
rule18=0,100,minecraft:cobblestone-0
rule19=0,100,minecraft:lit_furnace-5
rule20=0,100,minecraft:crafting_table-0
rule21=0,100,minecraft:oak_stairs-3

rule22=0,100,CommandBlock:RUINSTRIGGER /summon Skeleton ~0 ~2 ~0 {Equipment:[{Count:1,id:278,tag:{display:{Name:Ice Pick},ench:[{id:16,lvl:10},{id:19,lvl:10}]}},{Count:1,id:313,tag:{display:{Name:Frozen Boots},ench:[{id:2,lvl:10},{id:3,lvl:5}],AttributeModifiers:[{AttributeName:"generic.knockbackResistance",Name:"Knockback Resistance",Amount:1,Operation:0,UUIDLeast:894654,UUIDMost:2872}]}},{Count:1,id:312,tag:{display:{Name:Ice Greaves},ench:[{id:3,lvl:5}]}},{Count:1,id:311,tag:{display:{Name:Ice Armor},ench:[{id:0,lvl:5},{id:4,lvl:5}]}},{Count:1,id:79,tag:{display:{Name:Enchanted Ice Block},ench:[{id:5,lvl:10},{id:0,lvl:5}]}}],CustomName:Ice Golem,Attributes:[{Name:generic.maxHealth,Base:50},{Name:generic.movementSpeed,Base:0.3}],DropChances:[0.3F,0.3F,0.3F,0.3F,0.5F],ActiveEffects:[{Id:10,Amplifier:1,Duration:999999},{Id:5,Amplifier:1,Duration:999999}],PersistenceRequired:1}:@

rule23=0,100,minecraft:red_flower-4
rule24=0,100,minecraft:wooden_door-1
rule25=0,100,minecraft:trapdoor-14
rule26=0,100,minecraft:planks-0
rule27=0,100,minecraft:glass_pane-0
rule28=0,100,minecraft:trapdoor-12
rule29=0,100,minecraft:trapdoor-13
rule30=0,100,minecraft:trapdoor-15
rule31=0,100,minecraft:wooden_door-9
rule32=0,100,minecraft:wooden_door-8
rule33=0,100,minecraft:log-8
rule34=0,100,minecraft:log-4
rule35=0,100,minecraft:wooden_slab-8
rule36=0,100,minecraft:oak_stairs-7
rule37=0,100,minecraft:oak_stairs-6
rule38=0,100,minecraft:oak_stairs-0
rule39=0,100,minecraft:oak_stairs-5
rule40=0,100,minecraft:oak_stairs-4
rule41=0,100,ChestGenHook:dungeonChest:2-5
rule42=0,100,minecraft:wooden_door-0
rule43=0,100,minecraft:dark_oak_stairs-0
rule44=0,100,minecraft:dark_oak_stairs-2
rule45=0,100,minecraft:planks-5
rule46=0,100,minecraft:dark_oak_stairs-3
rule47=0,100,minecraft:dark_oak_stairs-5
rule48=0,100,minecraft:planks-1
rule49=0,100,minecraft:cobblestone_wall-0
rule50=0,100,minecraft:dark_oak_stairs-4
rule51=0,100,minecraft:dark_oak_stairs-1
rule52=0,100,minecraft:dark_oak_stairs-7
rule53=0,100,minecraft:dark_oak_stairs-6
rule54=0,100,minecraft:spruce_stairs-0
rule55=0,100,minecraft:spruce_stairs-5
rule56=0,100,minecraft:spruce_stairs-7
rule57=0,100,minecraft:spruce_stairs-6
rule58=0,100,minecraft:spruce_stairs-4
rule59=0,100,minecraft:spruce_stairs-1
rule60=0,100,minecraft:spruce_stairs-2
rule61=0,100,minecraft:spruce_stairs-3

layer
1,1,1,1,1,1,1,1,1,1,1,1,1,1,1
1,1,1,1,1,1,1,1,1,1,1,1,1,1,1
1,1,2,1,1,1,1,2,1,1,1,1,2,1,1
1,1,1,1,1,1,1,1,1,1,1,1,1,1,1
1,1,1,1,1,1,1,1,1,1,1,1,1,1,1
1,1,1,1,1,1,1,1,1,1,1,1,1,1,1
1,1,1,1,1,1,1,1,1,1,1,1,1,1,1
1,1,2,1,1,1,1,2,1,1,1,1,2,1,1
1,1,1,1,1,1,1,1,1,1,1,1,1,1,1
1,1,1,1,1,1,1,1,1,1,1,1,1,1,1
1,1,1,1,1,1,1,1,1,1,1,1,1,1,1
1,1,1,1,1,1,1,1,1,1,1,1,1,1,1
1,1,2,1,1,1,1,2,1,1,1,1,2,1,1
1,1,1,1,1,1,1,1,1,1,1,1,1,1,1
1,1,1,1,1,1,1,1,1,1,1,1,1,1,1
endlayer

layer
1,1,1,1,1,1,1,1,1,1,1,1,1,1,1
1,1,1,1,1,1,1,1,1,1,1,1,1,1,1
1,1,2,1,1,1,1,2,1,1,1,1,2,1,1
1,1,1,1,1,1,1,1,1,1,1,1,1,1,1
1,1,1,1,1,1,1,1,1,1,1,1,1,1,1
1,1,1,1,1,1,1,1,1,1,1,1,1,1,1
1,1,1,1,1,1,1,1,1,1,1,1,1,1,1
1,1,2,1,1,1,1,2,1,1,1,1,2,1,1
1,1,1,1,1,1,1,1,1,1,1,1,1,1,1
1,1,1,1,1,1,1,1,1,1,1,1,1,1,1
1,1,1,1,1,1,1,1,1,1,1,1,1,1,1
1,1,1,1,1,1,1,1,1,1,1,1,1,1,1
1,1,2,1,1,1,1,2,1,1,1,1,2,1,1
1,1,1,1,1,1,1,1,1,1,1,1,1,1,1
1,1,1,1,1,1,1,1,1,1,1,1,1,1,1
endlayer

layer
1,1,1,1,1,1,1,1,1,1,1,1,1,1,1
1,1,1,1,1,1,1,1,1,1,1,1,1,1,1
1,1,2,1,1,1,1,2,1,1,1,1,2,1,1
1,1,1,1,1,1,1,1,1,1,1,1,1,1,1
1,1,1,1,1,1,1,1,1,1,1,1,1,1,1
1,1,1,1,1,1,1,1,1,1,1,1,1,1,1
1,1,1,1,1,1,1,1,1,1,1,1,1,1,1
1,1,2,1,1,1,1,2,1,1,1,1,2,1,1
1,1,1,1,1,1,1,1,1,1,1,1,1,1,1
1,1,1,1,1,1,1,1,1,1,1,1,1,1,1
1,1,1,1,1,1,1,1,1,1,1,1,1,1,1
1,1,1,1,1,1,1,1,1,1,1,1,1,1,1
1,1,2,1,1,1,1,2,1,1,1,1,2,1,1
1,1,1,1,1,1,1,1,1,1,1,1,1,1,1
1,1,1,1,1,1,1,1,1,1,1,1,1,1,1
endlayer

layer
1,1,1,1,1,1,1,1,1,1,1,1,1,1,1
1,1,1,1,1,1,1,1,1,1,1,1,1,1,1
1,1,2,1,1,1,1,2,1,1,1,1,2,1,1
1,1,1,1,1,1,1,1,1,1,1,1,1,1,1
1,1,1,1,1,1,1,1,1,1,1,1,1,1,1
1,1,1,1,1,1,1,1,1,1,1,1,1,1,1
1,1,1,1,1,1,1,1,1,1,1,1,1,1,1
1,1,2,1,1,1,1,2,1,1,1,1,2,1,1
1,1,1,1,1,1,1,1,1,1,1,1,1,1,1
1,1,1,1,1,1,1,1,1,1,1,1,1,1,1
1,1,1,1,1,1,1,1,1,1,1,1,1,1,1
1,1,1,1,1,1,1,1,1,1,1,1,1,1,1
1,1,2,1,1,1,1,2,1,1,1,1,2,1,1
1,1,1,1,1,1,1,1,1,1,1,1,1,1,1
1,1,1,1,1,1,1,1,1,1,1,1,1,1,1
endlayer

layer
1,1,1,1,1,1,1,1,1,1,1,1,1,1,1
1,1,1,1,1,1,1,1,1,1,1,1,1,1,1
1,1,2,1,1,1,1,2,1,1,1,1,2,1,1
1,1,1,1,1,1,1,1,1,1,1,1,1,1,1
1,1,1,1,1,1,1,1,1,1,1,1,1,1,1
1,1,1,1,1,1,1,1,1,1,1,1,1,1,1
1,1,1,1,1,1,1,1,1,1,1,1,1,1,1
1,1,2,1,1,1,1,2,1,1,1,1,2,1,1
1,1,1,1,1,1,1,1,1,1,1,1,1,1,1
1,1,1,1,1,1,1,1,1,1,1,1,1,1,1
1,1,1,1,1,1,1,1,1,1,1,1,1,1,1
1,1,1,1,1,1,1,1,1,1,1,1,1,1,1
1,1,2,1,1,1,1,2,1,1,1,1,2,1,1
1,1,1,1,1,1,1,1,1,1,1,1,1,1,1
1,1,1,1,1,1,1,1,1,1,1,1,1,1,1
endlayer


layer
1,1,1,1,1,1,1,1,1,1,1,1,1,1,1
1,1,1,1,1,1,1,1,1,1,1,1,1,1,1
1,1,2,1,1,1,1,2,1,1,1,1,2,1,1
1,1,1,1,1,1,1,1,1,1,1,1,1,1,1
1,1,1,1,1,1,1,1,1,1,1,1,1,1,1
1,1,1,1,1,1,1,1,1,1,1,1,1,1,1
1,1,1,1,1,1,1,1,1,1,1,1,1,1,1
1,1,2,1,1,1,1,2,1,1,1,1,2,1,1
1,1,1,1,1,1,1,1,1,1,1,1,1,1,1
1,1,1,1,1,1,1,1,1,1,1,1,1,1,1
1,1,1,1,1,1,1,1,1,1,1,1,1,1,1
1,1,1,1,1,1,1,1,1,1,1,1,1,1,1
1,1,2,1,1,1,1,2,1,1,1,1,2,1,1
1,1,1,1,1,1,1,1,1,1,1,1,1,1,1
1,1,1,1,1,1,1,1,1,1,1,1,1,1,1
endlayer

layer
1,1,1,1,1,1,1,1,1,1,1,1,1,1,1
1,1,1,1,1,1,1,1,1,1,1,1,1,1,1
1,1,2,1,1,1,1,2,1,1,1,1,2,1,1
1,1,1,1,1,1,1,1,1,1,1,1,1,1,1
1,1,1,1,1,1,1,1,1,1,1,1,1,1,1
1,1,1,1,1,1,1,1,1,1,1,1,1,1,1
1,1,1,1,1,1,1,1,1,1,1,1,1,1,1
1,1,2,1,1,1,1,2,1,1,1,1,2,1,1
1,1,1,1,1,1,1,1,1,1,1,1,1,1,1
1,1,1,1,1,1,1,1,1,1,1,1,1,1,1
1,1,1,1,1,1,1,1,1,1,1,1,1,1,1
1,1,1,1,1,1,1,1,1,1,1,1,1,1,1
1,1,2,1,1,1,1,2,1,1,1,1,2,1,1
1,1,1,1,1,1,1,1,1,1,1,1,1,1,1
1,1,1,1,1,1,1,1,1,1,1,1,1,1,1
endlayer

layer
1,1,1,1,1,1,1,1,1,1,1,1,1,1,1
1,1,1,1,1,1,1,1,1,1,1,1,1,1,1
1,1,2,1,1,1,1,2,1,1,1,1,2,1,1
1,1,1,1,1,1,1,1,1,1,1,1,1,1,1
1,1,1,1,1,1,1,1,1,1,1,1,1,1,1
1,1,1,1,1,1,1,1,1,1,1,1,1,1,1
1,1,1,1,1,1,1,1,1,1,1,1,1,1,1
1,1,2,1,1,1,1,2,1,1,1,1,2,1,1
1,1,1,1,1,1,1,1,1,1,1,1,1,1,1
1,1,1,1,1,1,1,1,1,1,1,1,1,1,1
1,1,1,1,1,1,1,1,1,1,1,1,1,1,1
1,1,1,1,1,1,1,1,1,1,1,1,1,1,1
1,1,2,1,1,1,1,2,1,1,1,1,2,1,1
1,1,1,1,1,1,1,1,1,1,1,1,1,1,1
1,1,1,1,1,1,1,1,1,1,1,1,1,1,1
endlayer

layer
1,1,1,1,1,1,1,1,1,1,1,1,1,1,1
1,1,1,1,1,1,1,1,1,1,1,1,1,1,1
1,1,2,1,1,1,1,2,1,1,1,1,2,1,1
1,1,1,1,1,1,1,1,1,1,1,1,1,1,1
1,1,1,1,1,1,1,1,1,1,1,1,1,1,1
1,1,1,1,1,1,1,1,1,1,1,1,1,1,1
1,1,1,1,1,1,1,1,1,1,1,1,1,1,1
1,1,2,1,1,1,1,2,1,1,1,1,2,1,1
1,1,1,1,1,1,1,1,1,1,1,1,1,1,1
1,1,1,1,1,1,1,1,1,1,1,1,1,1,1
1,1,1,1,1,1,1,1,1,1,1,1,1,1,1
1,1,1,1,1,1,1,1,1,1,1,1,1,1,1
1,1,2,1,1,1,1,2,1,1,1,1,2,1,1
1,1,1,1,1,1,1,1,1,1,1,1,1,1,1
1,1,1,1,1,1,1,1,1,1,1,1,1,1,1
endlayer

layer
1,1,1,1,1,1,1,1,1,1,1,1,1,1,1
1,1,1,1,1,1,1,1,1,1,1,1,1,1,1
1,1,2,1,1,1,1,2,1,1,1,1,2,1,1
1,1,1,1,1,1,1,1,1,1,1,1,1,1,1
1,1,1,1,1,1,1,1,1,1,1,1,1,1,1
1,1,1,1,1,1,1,1,1,1,1,1,1,1,1
1,1,1,1,1,1,1,1,1,1,1,1,1,1,1
1,1,2,1,1,1,1,2,1,1,1,1,2,1,1
1,1,1,1,1,1,1,1,1,1,1,1,1,1,1
1,1,1,1,1,1,1,1,1,1,1,1,1,1,1
1,1,1,1,1,1,1,1,1,1,1,1,1,1,1
1,1,1,1,1,1,1,1,1,1,1,1,1,1,1
1,1,2,1,1,1,1,2,1,1,1,1,2,1,1
1,1,1,1,1,1,1,1,1,1,1,1,1,1,1
1,1,1,1,1,1,1,1,1,1,1,1,1,1,1
endlayer


layer
1,1,1,1,1,1,1,1,1,1,1,1,1,1,1
1,1,1,1,1,1,1,1,1,1,1,1,1,1,1
1,1,2,1,1,1,1,2,1,1,1,1,2,1,1
1,1,1,1,1,1,1,1,1,1,1,1,1,1,1
1,1,1,1,1,1,1,1,1,1,1,1,1,1,1
1,1,1,1,1,1,1,1,1,1,1,1,1,1,1
1,1,1,1,1,1,1,1,1,1,1,1,1,1,1
1,1,2,1,1,1,1,2,1,1,1,1,2,1,1
1,1,1,1,1,1,1,1,1,1,1,1,1,1,1
1,1,1,1,1,1,1,1,1,1,1,1,1,1,1
1,1,1,1,1,1,1,1,1,1,1,1,1,1,1
1,1,1,1,1,1,1,1,1,1,1,1,1,1,1
1,1,2,1,1,1,1,2,1,1,1,1,2,1,1
1,1,1,1,1,1,1,1,1,1,1,1,1,1,1
1,1,1,1,1,1,1,1,1,1,1,1,1,1,1
endlayer

layer
1,1,1,1,1,1,1,1,1,1,1,1,1,1,1
1,1,1,1,1,1,1,1,1,1,1,1,1,1,1
1,1,2,1,1,1,1,2,1,1,1,1,2,1,1
1,1,1,1,1,1,1,1,1,1,1,1,1,1,1
1,1,1,1,1,1,1,1,1,1,1,1,1,1,1
1,1,1,1,1,1,1,1,1,1,1,1,1,1,1
1,1,1,1,1,1,1,1,1,1,1,1,1,1,1
1,1,2,1,1,1,1,2,1,1,1,1,2,1,1
1,1,1,1,1,1,1,1,1,1,1,1,1,1,1
1,1,1,1,1,1,1,1,1,1,1,1,1,1,1
1,1,1,1,1,1,1,1,1,1,1,1,1,1,1
1,1,1,1,1,1,1,1,1,1,1,1,1,1,1
1,1,2,1,1,1,1,2,1,1,1,1,2,1,1
1,1,1,1,1,1,1,1,1,1,1,1,1,1,1
1,1,1,1,1,1,1,1,1,1,1,1,1,1,1
endlayer

layer
1,1,1,1,1,1,1,1,1,1,1,1,1,1,1
1,1,1,1,1,1,1,1,1,1,1,1,1,1,1
1,1,2,1,1,1,1,2,1,1,1,1,2,1,1
1,1,1,1,1,1,1,1,1,1,1,1,1,1,1
1,1,1,1,1,1,1,1,1,1,1,1,1,1,1
1,1,1,1,1,1,1,1,1,1,1,1,1,1,1
1,1,1,1,1,1,1,1,1,1,1,1,1,1,1
1,1,2,1,1,1,1,2,1,1,1,1,2,1,1
1,1,1,1,1,1,1,1,1,1,1,1,1,1,1
1,1,1,1,1,1,1,1,1,1,1,1,1,1,1
1,1,1,1,1,1,1,1,1,1,1,1,1,1,1
1,1,1,1,1,1,1,1,1,1,1,1,1,1,1
1,1,2,1,1,1,1,2,1,1,1,1,2,1,1
1,1,1,1,1,1,1,1,1,1,1,1,1,1,1
1,1,1,1,1,1,1,1,1,1,1,1,1,1,1
endlayer

layer
1,1,1,1,1,1,1,1,1,1,1,1,1,1,1
1,1,1,1,1,1,1,1,1,1,1,1,1,1,1
1,1,2,5,4,4,3,2,5,4,4,3,2,1,1
1,1,6,1,1,1,1,6,1,1,1,1,6,1,1
1,1,4,1,1,1,1,4,1,1,1,1,4,1,1
1,1,4,1,1,1,1,4,1,1,1,1,4,1,1
1,1,7,1,1,1,1,7,1,1,1,1,7,1,1
1,1,2,5,4,4,3,2,5,4,4,3,2,1,1
1,1,6,1,1,1,1,6,1,1,1,1,6,1,1
1,1,4,1,1,1,1,4,1,1,1,1,4,1,1
1,1,4,1,1,1,1,4,1,1,1,1,4,1,1
1,1,7,1,1,1,1,7,1,1,1,1,7,1,1
1,1,2,5,4,4,3,2,5,4,4,3,2,1,1
1,1,1,1,1,1,1,1,1,1,1,1,1,1,1
1,1,1,1,1,1,1,1,1,1,1,1,1,1,1
endlayer


layer
8,8,8,8,8,8,8,8,8,8,8,8,8,8,8
8,9,9,9,9,9,9,9,9,9,9,9,9,9,8
8,12,11,11,11,11,11,11,11,11,11,11,11,10,8
8,12,11,13,13,13,13,11,13,13,13,13,11,10,8
8,12,11,13,8,8,13,11,13,8,8,13,11,10,8
8,12,11,13,8,8,13,11,13,8,8,13,11,10,8
8,12,11,13,13,13,13,11,13,13,13,13,11,10,8
8,12,11,11,11,11,11,11,14,14,14,14,11,10,8
8,12,11,13,13,13,13,11,13,13,13,13,15,10,8
8,12,11,13,8,8,13,11,13,8,8,13,11,10,8
8,12,11,13,8,8,13,11,13,8,8,13,11,10,8
8,12,11,13,13,13,13,11,13,13,13,13,15,10,8
8,12,11,11,11,11,11,11,15,15,15,15,15,10,8
8,16,16,16,16,16,16,16,16,16,16,16,16,10,8
8,8,8,8,8,8,8,8,8,8,8,8,8,8,8
endlayer

layer
17,17,17,17,17,17,17,17,17,17,17,17,17,17,17
17,0,0,18,18,18,18,0,0,0,0,0,0,0,17
17,0,11,18,19,19,18,11,11,11,11,11,11,0,17
17,0,11,0,0,0,0,0,0,0,21,20,11,0,17
17,0,11,0,0,0,0,0,22,0,0,0,11,0,17
17,0,11,0,0,0,0,0,0,0,0,0,11,0,17
17,0,11,0,0,0,0,0,0,0,0,0,11,0,17
17,0,11,0,0,0,0,11,11,9,9,11,11,0,17
17,0,11,0,0,0,0,11,0,0,0,0,23,0,17
17,0,11,0,0,0,0,24,0,0,0,0,0,0,0
17,0,11,0,0,22,0,24,0,0,0,0,0,0,0
17,0,11,0,0,0,0,11,0,0,0,0,23,0,17
17,0,11,11,11,11,11,11,23,23,23,23,23,0,17
17,0,0,0,0,0,0,0,0,0,0,0,0,0,17
17,17,17,17,17,17,17,17,17,17,17,17,17,17,17
endlayer

layer
0,0,0,0,0,0,0,0,0,0,0,0,0,0,0
0,0,0,18,18,18,18,0,25,0,0,25,0,0,0
0,0,2,18,19,19,18,2,26,27,27,26,2,0,0
0,29,26,0,0,0,0,0,0,0,0,21,26,28,0
0,0,27,0,0,0,0,0,0,0,0,0,27,0,0
0,0,27,0,0,0,0,0,0,0,0,0,27,0,0
0,29,26,0,0,0,0,0,0,0,0,0,26,28,0
0,0,2,0,0,0,0,2,26,27,27,26,2,0,0
0,29,26,0,0,0,0,26,30,0,0,30,0,0,0
0,0,27,0,0,0,0,31,0,0,0,0,0,0,0
0,0,27,0,0,0,0,32,0,0,0,0,0,0,0
0,29,26,0,0,0,0,26,0,0,0,0,0,0,0
0,0,2,26,27,27,26,2,0,0,0,0,0,0,0
0,0,0,30,0,0,30,0,0,0,0,0,0,0,0
0,0,0,0,0,0,0,0,0,0,0,0,0,0,0
endlayer

layer
0,0,0,0,0,0,0,0,0,0,0,0,0,0,0
0,0,0,18,18,18,18,0,0,0,0,0,0,0,0
0,0,2,18,18,18,18,2,33,33,33,33,2,0,0
0,0,34,37,6,6,36,34,35,0,0,0,34,0,0
0,0,34,37,0,0,36,34,35,35,35,38,34,0,0
0,0,34,37,0,0,36,34,35,35,35,35,34,0,0
0,0,34,37,0,0,36,34,35,35,35,35,34,0,0
0,0,2,37,0,0,36,2,33,33,33,33,2,0,0
0,0,34,37,0,0,36,34,0,39,39,0,0,0,0
0,0,34,37,0,0,36,34,0,0,0,0,0,0,0
0,0,34,37,0,0,36,34,0,0,0,0,0,0,0
0,0,34,37,40,40,40,34,0,0,0,0,0,0,0
0,0,2,33,33,33,33,2,0,0,0,0,0,0,0
0,0,0,0,0,0,0,0,0,0,0,0,0,0,0
0,0,0,0,0,0,0,0,0,0,0,0,0,0,0
endlayer

layer
0,0,0,0,0,0,0,0,0,0,0,0,0,0,0
0,0,0,0,18,18,0,0,25,0,0,25,0,0,0
0,0,2,26,41,41,26,2,26,27,27,26,2,0,0
0,29,26,0,0,0,0,0,0,0,0,0,26,28,0
0,0,27,0,0,0,0,0,0,0,0,0,27,0,0
0,0,27,0,0,0,0,0,0,22,0,0,27,0,0
0,29,26,0,0,0,0,0,0,0,0,0,26,28,0
0,0,2,0,0,0,0,2,26,42,42,26,2,0,0
0,29,26,0,0,0,0,26,28,17,17,0,0,0,0
0,0,27,0,0,0,0,27,0,0,0,0,0,0,0
0,0,27,0,0,0,0,27,0,0,0,0,0,0,0
0,29,26,0,0,0,0,26,28,0,0,0,0,0,0
0,0,2,26,27,27,26,2,0,0,0,0,0,0,0
0,0,0,30,0,0,30,0,0,0,0,0,0,0,0
0,0,0,0,0,0,0,0,0,0,0,0,0,0,0
endlayer

layer
0,0,0,0,0,0,0,0,0,0,0,0,0,0,0
0,0,0,0,18,18,0,0,25,0,0,25,0,0,0
0,0,2,26,0,0,26,2,26,27,27,26,2,0,0
0,29,26,0,0,0,0,0,0,0,0,0,26,28,0
0,0,27,0,0,0,0,0,0,0,0,0,27,0,0
0,0,27,0,0,0,0,0,0,0,0,0,27,0,0
0,29,26,0,0,0,0,0,0,0,0,0,26,28,0
0,0,2,0,0,0,0,2,26,31,32,26,2,0,0
0,29,26,0,0,0,0,26,28,0,0,0,0,0,0
0,0,27,0,0,0,0,27,0,0,0,0,0,0,0
0,0,27,0,0,0,0,27,0,0,0,0,0,0,0
0,29,26,0,0,0,0,26,28,0,0,0,0,0,0
0,0,2,26,27,27,26,2,0,0,0,0,0,0,0
0,0,0,30,0,0,30,0,0,0,0,0,0,0,0
0,0,0,0,0,0,0,0,0,0,0,0,0,0,0
endlayer

layer
0,0,0,0,0,0,0,0,0,0,0,0,0,0,0
0,0,0,0,18,18,0,0,25,0,0,25,0,0,0
0,0,2,26,0,0,26,2,26,27,27,26,2,0,0
0,29,26,0,0,0,0,0,0,0,0,0,26,28,0
0,0,27,0,0,0,0,0,0,0,0,0,27,0,0
0,0,27,0,0,0,0,0,0,0,0,0,27,0,0
0,29,26,0,0,0,0,0,0,0,0,0,26,28,0
0,0,2,0,0,0,0,2,26,27,27,26,2,0,0
0,29,26,0,0,0,0,26,28,0,0,0,0,0,0
0,0,27,0,0,0,0,27,0,0,0,0,0,0,0
0,0,27,0,0,0,0,27,0,0,0,0,0,0,0
0,29,26,0,0,0,0,26,28,0,0,0,0,0,0
0,0,2,26,27,27,26,2,0,0,0,0,0,0,0
0,0,0,30,0,0,30,0,0,0,0,0,0,0,0
0,0,0,0,0,0,0,0,0,0,0,0,0,0,0
endlayer

layer
0,0,0,0,0,0,0,0,0,0,0,0,0,0,0
0,0,0,0,18,18,0,0,0,0,0,0,0,0,0
0,0,2,33,33,33,33,2,33,33,33,33,2,0,0
0,0,34,0,0,0,0,34,0,0,0,0,34,0,0
0,0,34,0,0,0,0,34,0,0,0,0,34,0,0
0,0,34,0,0,0,0,34,0,0,0,0,34,0,0
0,0,34,0,0,0,0,34,0,0,0,0,34,0,0
0,0,2,0,0,0,0,2,33,33,33,33,2,0,0
0,0,34,0,0,0,0,34,0,0,0,0,0,0,0
0,0,34,0,0,0,0,34,0,0,0,0,0,0,0
0,0,34,0,0,0,0,34,0,0,0,0,0,0,0
0,0,34,0,0,0,0,34,0,0,0,0,0,0,0
0,0,2,33,33,33,33,2,0,0,0,0,0,0,0
0,0,0,0,0,0,0,0,0,0,0,0,0,0,0
0,0,0,0,0,0,0,0,0,0,0,0,0,0,0
endlayer

layer
0,0,0,0,0,0,0,0,0,0,0,0,0,0,0
0,46,45,0,18,18,0,45,44,43,43,43,43,43,0
0,46,48,26,49,49,26,48,48,48,48,48,48,47,0
0,46,48,0,0,0,0,48,0,0,0,0,26,0,0
0,46,48,0,0,0,0,48,0,0,0,0,27,0,0
0,46,48,0,0,0,0,48,0,0,0,0,27,0,0
0,46,48,0,0,0,0,48,0,0,0,0,26,0,0
0,46,48,0,0,0,0,48,48,48,48,48,48,50,0
0,46,48,0,0,0,0,48,44,51,51,51,51,51,0
0,46,48,0,0,0,0,48,44,0,0,0,0,0,0
0,46,48,0,0,0,0,48,44,0,0,0,0,0,0
0,46,48,0,0,0,0,48,44,0,0,0,0,0,0
0,46,48,26,27,27,26,48,44,0,0,0,0,0,0
0,46,53,0,0,0,0,52,44,0,0,0,0,0,0
0,0,0,0,0,0,0,0,0,0,0,0,0,0,0
endlayer

layer
0,0,0,0,0,0,0,0,0,0,0,0,0,0,0
0,0,45,53,18,18,52,45,0,0,0,0,0,0,0
0,0,48,48,0,0,48,48,54,54,54,54,54,43,0
0,0,48,57,0,0,56,48,55,55,55,55,48,47,0
0,0,48,57,0,0,56,48,0,0,0,0,27,0,0
0,0,48,57,0,0,56,48,0,0,0,0,27,0,0
0,0,48,57,0,0,56,48,58,58,58,58,48,50,0
0,0,48,57,0,0,56,48,59,59,59,59,59,51,0
0,0,48,57,0,0,56,48,0,0,0,0,0,0,0
0,0,48,57,0,0,56,48,0,0,0,0,0,0,0
0,0,48,57,0,0,56,48,0,0,0,0,0,0,0
0,0,48,57,0,0,56,48,0,0,0,0,0,0,0
0,0,48,48,27,27,48,48,0,0,0,0,0,0,0
0,0,45,53,0,0,52,45,0,0,0,0,0,0,0
0,0,0,0,0,0,0,0,0,0,0,0,0,0,0
endlayer

layer
0,0,0,0,0,0,0,0,0,0,0,0,0,0,0
0,0,46,45,18,18,45,44,0,0,0,0,0,0,0
0,0,61,48,0,0,48,60,0,0,0,0,0,0,0
0,0,61,48,0,0,48,54,54,54,54,54,54,43,0
0,0,61,48,0,0,48,55,55,55,55,55,48,47,0
0,0,61,48,0,0,48,58,58,58,58,58,48,50,0
0,0,61,48,0,0,48,59,59,59,59,59,59,51,0
0,0,61,48,0,0,48,60,0,0,0,0,0,0,0
0,0,61,48,0,0,48,60,0,0,0,0,0,0,0
0,0,61,48,0,0,48,60,0,0,0,0,0,0,0
0,0,61,48,0,0,48,60,0,0,0,0,0,0,0
0,0,61,48,0,0,48,60,0,0,0,0,0,0,0
0,0,61,48,27,27,48,60,0,0,0,0,0,0,0
0,0,46,45,0,0,45,44,0,0,0,0,0,0,0
0,0,0,0,0,0,0,0,0,0,0,0,0,0,0
endlayer

layer
0,0,0,0,0,0,0,0,0,0,0,0,0,0,0
0,0,0,45,18,18,45,0,0,0,0,0,0,0,0
0,0,0,48,57,56,48,0,0,0,0,0,0,0,0
0,0,0,48,57,56,48,0,0,0,0,0,0,0,0
0,0,0,48,57,56,48,54,54,54,54,54,54,43,43
0,0,0,48,57,56,48,59,59,59,59,59,59,51,51
0,0,0,48,57,56,48,0,0,0,0,0,0,0,0
0,0,0,48,57,56,48,0,0,0,0,0,0,0,0
0,0,0,48,57,56,48,0,0,0,0,0,0,0,0
0,0,0,48,57,56,48,0,0,0,0,0,0,0,0
0,0,0,48,57,56,48,0,0,0,0,0,0,0,0
0,0,0,48,57,56,48,0,0,0,0,0,0,0,0
0,0,0,48,48,48,48,0,0,0,0,0,0,0,0
0,0,0,45,53,52,45,0,0,0,0,0,0,0,0
0,0,0,0,0,0,0,0,0,0,0,0,0,0,0
endlayer

layer
0,0,0,0,0,0,0,0,0,0,0,0,0,0,0
0,0,0,46,18,18,44,0,0,0,0,0,0,0,0
0,0,0,61,48,48,60,0,0,0,0,0,0,0,0
0,0,0,61,48,48,60,0,0,0,0,0,0,0,0
0,0,0,61,48,48,60,0,0,0,0,0,0,0,0
0,0,0,61,48,48,60,0,0,0,0,0,0,0,0
0,0,0,61,48,48,60,0,0,0,0,0,0,0,0
0,0,0,61,48,48,60,0,0,0,0,0,0,0,0
0,0,0,61,48,48,60,0,0,0,0,0,0,0,0
0,0,0,61,48,48,60,0,0,0,0,0,0,0,0
0,0,0,61,48,48,60,0,0,0,0,0,0,0,0
0,0,0,61,48,48,60,0,0,0,0,0,0,0,0
0,0,0,61,48,48,60,0,0,0,0,0,0,0,0
0,0,0,46,45,45,44,0,0,0,0,0,0,0,0
0,0,0,0,0,0,0,0,0,0,0,0,0,0,0
endlayer

layer
0,0,0,0,50,50,0,0,0,0,0,0,0,0,0
0,0,0,0,18,18,0,0,0,0,0,0,0,0,0
0,0,0,0,48,48,0,0,0,0,0,0,0,0,0
0,0,0,0,48,48,0,0,0,0,0,0,0,0,0
0,0,0,0,48,48,0,0,0,0,0,0,0,0,0
0,0,0,0,48,48,0,0,0,0,0,0,0,0,0
0,0,0,0,48,48,0,0,0,0,0,0,0,0,0
0,0,0,0,48,48,0,0,0,0,0,0,0,0,0
0,0,0,0,48,48,0,0,0,0,0,0,0,0,0
0,0,0,0,48,48,0,0,0,0,0,0,0,0,0
0,0,0,0,48,48,0,0,0,0,0,0,0,0,0
0,0,0,0,48,48,0,0,0,0,0,0,0,0,0
0,0,0,0,48,48,0,0,0,0,0,0,0,0,0
0,0,0,0,45,45,0,0,0,0,0,0,0,0,0
0,0,0,0,47,47,0,0,0,0,0,0,0,0,0
endlayer

layer
0,0,0,0,46,44,0,0,0,0,0,0,0,0,0
0,0,0,0,18,18,0,0,0,0,0,0,0,0,0
0,0,0,0,61,60,0,0,0,0,0,0,0,0,0
0,0,0,0,61,60,0,0,0,0,0,0,0,0,0
0,0,0,0,61,60,0,0,0,0,0,0,0,0,0
0,0,0,0,61,60,0,0,0,0,0,0,0,0,0
0,0,0,0,61,60,0,0,0,0,0,0,0,0,0
0,0,0,0,61,60,0,0,0,0,0,0,0,0,0
0,0,0,0,61,60,0,0,0,0,0,0,0,0,0
0,0,0,0,61,60,0,0,0,0,0,0,0,0,0
0,0,0,0,61,60,0,0,0,0,0,0,0,0,0
0,0,0,0,61,60,0,0,0,0,0,0,0,0,0
0,0,0,0,61,60,0,0,0,0,0,0,0,0,0
0,0,0,0,46,44,0,0,0,0,0,0,0,0,0
0,0,0,0,46,44,0,0,0,0,0,0,0,0,0
endlayer

layer
0,0,0,0,0,0,0,0,0,0,0,0,0,0,0
0,0,0,0,49,49,0,0,0,0,0,0,0,0,0
0,0,0,0,0,0,0,0,0,0,0,0,0,0,0
0,0,0,0,0,0,0,0,0,0,0,0,0,0,0
0,0,0,0,0,0,0,0,0,0,0,0,0,0,0
0,0,0,0,0,0,0,0,0,0,0,0,0,0,0
0,0,0,0,0,0,0,0,0,0,0,0,0,0,0
0,0,0,0,0,0,0,0,0,0,0,0,0,0,0
0,0,0,0,0,0,0,0,0,0,0,0,0,0,0
0,0,0,0,0,0,0,0,0,0,0,0,0,0,0
0,0,0,0,0,0,0,0,0,0,0,0,0,0,0
0,0,0,0,0,0,0,0,0,0,0,0,0,0,0
0,0,0,0,0,0,0,0,0,0,0,0,0,0,0
0,0,0,0,0,0,0,0,0,0,0,0,0,0,0
0,0,0,0,0,0,0,0,0,0,0,0,0,0,0
endlayer

